Workbook

Sheet Students
A1: Sample data. All 112 students are fictional. Change a student's Cohort (blue column K) and the Balance tab updates.
A2: Student ID | B2: Reading Score | C2: Reading Placement | D2: Math Score | E2: Math Placement | F2: Gender | G2: IEP | H2: 504 | I2: Race/Ethnicity | J2: English Learner | K2: Cohort | L2: #in cohort
A3: S-001 | B3: 542 | C3: Grade 5 | D3: 474 | E3: Grade 3 | F3: Girl | G3: No | H3: No | I3: Hispanic/Latino | J3: No | K3: 5A | L3: =IF(K3="","",COUNTIF($K$3:K3,K3)) -> 1
A4: S-002 | B4: 537 | C4: Grade 5 | D4: 473 | E4: Grade 3 | F4: Girl | G4: No | H4: No | I4: Hispanic/Latino | J4: No | K4: 5A | L4: =IF(K4="","",COUNTIF($K$3:K4,K4)) -> 2
A5: S-003 | B5: 536 | C5: Grade 5 | D5: 490 | E5: Grade 3 | F5: Boy | G5: No | H5: No | I5: Hispanic/Latino | J5: No | K5: 5A | L5: =IF(K5="","",COUNTIF($K$3:K5,K5)) -> 3
A6: S-004 | B6: 548 | C6: Grade 5 | D6: 535 | E6: Grade 4 | F6: Girl | G6: No | H6: No | I6: Hispanic/Latino | J6: Yes | K6: 5C | L6: =IF(K6="","",COUNTIF($K$3:K6,K6)) -> 1
A7: S-005 | B7: 454 | C7: Grade 2 | D7: 568 | E7: Grade 5 | F7: Boy | G7: No | H7: No | I7: Asian | J7: No | K7: 5C | L7: =IF(K7="","",COUNTIF($K$3:K7,K7)) -> 2
A8: S-006 | B8: 549 | C8: Grade 5 | D8: 516 | E8: Grade 4 | F8: Boy | G8: No | H8: No | I8: Hispanic/Latino | J8: No | K8: 5A | L8: =IF(K8="","",COUNTIF($K$3:K8,K8)) -> 4
A9: S-007 | B9: 513 | C9: Grade 4 | D9: 401 | E9: Grade 1 | F9: Boy | G9: No | H9: No | I9: White | J9: No | K9: 5D | L9: =IF(K9="","",COUNTIF($K$3:K9,K9)) -> 1
A10: S-008 | B10: 546 | C10: Grade 5 | D10: 573 | E10: Grade 5 | F10: Boy | G10: No | H10: No | I10: Hispanic/Latino | J10: No | K10: 5B | L10: =IF(K10="","",COUNTIF($K$3:K10,K10)) -> 1
A11: S-009 | B11: 477 | C11: Grade 3 | D11: 547 | E11: Grade 5 | F11: Boy | G11: No | H11: No | I11: Black | J11: Yes | K11: 5A | L11: =IF(K11="","",COUNTIF($K$3:K11,K11)) -> 5
A12: S-010 | B12: 575 | C12: Grade 5 | D12: 547 | E12: Grade 5 | F12: Girl | G12: No | H12: No | I12: Asian | J12: No | K12: 5B | L12: =IF(K12="","",COUNTIF($K$3:K12,K12)) -> 2
A13: S-011 | B13: 532 | C13: Grade 4 | D13: 558 | E13: Grade 5 | F13: Boy | G13: No | H13: Yes | I13: Hispanic/Latino | J13: Yes | K13: 5D | L13: =IF(K13="","",COUNTIF($K$3:K13,K13)) -> 2
A14: S-012 | B14: 496 | C14: Grade 3 | D14: 396 | E14: Grade 1 | F14: Boy | G14: No | H14: No | I14: Hispanic/Latino | J14: Yes | K14: 5B | L14: =IF(K14="","",COUNTIF($K$3:K14,K14)) -> 3
... A114: S-112 | B114: 470 | C114: Grade 3 | D114: 564 | E114: Grade 5 | F114: Girl | G114: Yes | H114: No | I114: Hispanic/Latino | J114: No | K114: 5B | L114: =IF(K114="","",COUNTIF($K$3:K114,K114)) -> 28

Sheet Balance
A1: Cohort balance (updates when a student's cohort changes)
A2: Spread = highest cohort minus lowest. Green means balanced (within 1 student, or within 10 points for average scores).
A4: Measure | B4: 5A | C4: 5B | D4: 5C | E4: 5D | F4: Spread
A5: Students | B5: =COUNTIF(Students!$K$3:$K$114,"5A") -> 28 | C5: =COUNTIF(Students!$K$3:$K$114,"5B") -> 28 | D5: =COUNTIF(Students!$K$3:$K$114,"5C") -> 28 | E5: =COUNTIF(Students!$K$3:$K$114,"5D") -> 28 | F5: =MAX(B5:E5)-MIN(B5:E5) -> 0
A6: Avg reading score | B6: =IFERROR(AVERAGEIF(Students!$K$3:$K$114,"5A",Students!$B$3:$B$114),0) -> 499.25 | C6: =IFERROR(AVERAGEIF(Students!$K$3:$K$114,"5B",Students!$B$3:$B$114),0) -> 499.32143 | D6: =IFERROR(AVERAGEIF(Students!$K$3:$K$114,"5C",Students!$B$3:$B$114),0) -> 499.10714 | E6: =IFERROR(AVERAGEIF(Students!$K$3:$K$114,"5D",Students!$B$3:$B$114),0) -> 499.21429 | F6: =MAX(B6:E6)-MIN(B6:E6) -> 0.21428571
A7: Avg math score | B7: =IFERROR(AVERAGEIF(Students!$K$3:$K$114,"5A",Students!$D$3:$D$114),0) -> 502.92857 | C7: =IFERROR(AVERAGEIF(Students!$K$3:$K$114,"5B",Students!$D$3:$D$114),0) -> 502.96429 | D7: =IFERROR(AVERAGEIF(Students!$K$3:$K$114,"5C",Students!$D$3:$D$114),0) -> 503.89286 | E7: =IFERROR(AVERAGEIF(Students!$K$3:$K$114,"5D",Students!$D$3:$D$114),0) -> 504.14286 | F7: =MAX(B7:E7)-MIN(B7:E7) -> 1.2142857
A8: Girls | B8: =COUNTIFS(Students!$K$3:$K$114,"5A",Students!$F$3:$F$114,"Girl") -> 14 | C8: =COUNTIFS(Students!$K$3:$K$114,"5B",Students!$F$3:$F$114,"Girl") -> 14 | D8: =COUNTIFS(Students!$K$3:$K$114,"5C",Students!$F$3:$F$114,"Girl") -> 15 | E8: =COUNTIFS(Students!$K$3:$K$114,"5D",Students!$F$3:$F$114,"Girl") -> 15 | F8: =MAX(B8:E8)-MIN(B8:E8) -> 1
A9: Boys | B9: =COUNTIFS(Students!$K$3:$K$114,"5A",Students!$F$3:$F$114,"Boy") -> 14 | C9: =COUNTIFS(Students!$K$3:$K$114,"5B",Students!$F$3:$F$114,"Boy") -> 14 | D9: =COUNTIFS(Students!$K$3:$K$114,"5C",Students!$F$3:$F$114,"Boy") -> 13 | E9: =COUNTIFS(Students!$K$3:$K$114,"5D",Students!$F$3:$F$114,"Boy") -> 13 | F9: =MAX(B9:E9)-MIN(B9:E9) -> 1
A10: IEP | B10: =COUNTIFS(Students!$K$3:$K$114,"5A",Students!$G$3:$G$114,"Yes") -> 3 | C10: =COUNTIFS(Students!$K$3:$K$114,"5B",Students!$G$3:$G$114,"Yes") -> 4 | D10: =COUNTIFS(Students!$K$3:$K$114,"5C",Students!$G$3:$G$114,"Yes") -> 3 | E10: =COUNTIFS(Students!$K$3:$K$114,"5D",Students!$G$3:$G$114,"Yes") -> 3 | F10: =MAX(B10:E10)-MIN(B10:E10) -> 1
A11: 504 | B11: =COUNTIFS(Students!$K$3:$K$114,"5A",Students!$H$3:$H$114,"Yes") -> 2 | C11: =COUNTIFS(Students!$K$3:$K$114,"5B",Students!$H$3:$H$114,"Yes") -> 2 | D11: =COUNTIFS(Students!$K$3:$K$114,"5C",Students!$H$3:$H$114,"Yes") -> 2 | E11: =COUNTIFS(Students!$K$3:$K$114,"5D",Students!$H$3:$H$114,"Yes") -> 2 | F11: =MAX(B11:E11)-MIN(B11:E11) -> 0
A12: Black | B12: =COUNTIFS(Students!$K$3:$K$114,"5A",Students!$I$3:$I$114,"Black") -> 6 | C12: =COUNTIFS(Students!$K$3:$K$114,"5B",Students!$I$3:$I$114,"Black") -> 6 | D12: =COUNTIFS(Students!$K$3:$K$114,"5C",Students!$I$3:$I$114,"Black") -> 6 | E12: =COUNTIFS(Students!$K$3:$K$114,"5D",Students!$I$3:$I$114,"Black") -> 6 | F12: =MAX(B12:E12)-MIN(B12:E12) -> 0
A13: Hispanic/Latino | B13: =COUNTIFS(Students!$K$3:$K$114,"5A",Students!$I$3:$I$114,"Hispanic/Latino") -> 13 | C13: =COUNTIFS(Students!$K$3:$K$114,"5B",Students!$I$3:$I$114,"Hispanic/Latino") -> 13 | D13: =COUNTIFS(Students!$K$3:$K$114,"5C",Students!$I$3:$I$114,"Hispanic/Latino") -> 13 | E13: =COUNTIFS(Students!$K$3:$K$114,"5D",Students!$I$3:$I$114,"Hispanic/Latino") -> 13 | F13: =MAX(B13:E13)-MIN(B13:E13) -> 0
A14: White | B14: =COUNTIFS(Students!$K$3:$K$114,"5A",Students!$I$3:$I$114,"White") -> 3 | C14: =COUNTIFS(Students!$K$3:$K$114,"5B",Students!$I$3:$I$114,"White") -> 3 | D14: =COUNTIFS(Students!$K$3:$K$114,"5C",Students!$I$3:$I$114,"White") -> 4 | E14: =COUNTIFS(Students!$K$3:$K$114,"5D",Students!$I$3:$I$114,"White") -> 4 | F14: =MAX(B14:E14)-MIN(B14:E14) -> 1
A15: Asian | B15: =COUNTIFS(Students!$K$3:$K$114,"5A",Students!$I$3:$I$114,"Asian") -> 6 | C15: =COUNTIFS(Students!$K$3:$K$114,"5B",Students!$I$3:$I$114,"Asian") -> 6 | D15: =COUNTIFS(Students!$K$3:$K$114,"5C",Students!$I$3:$I$114,"Asian") -> 5 | E15: =COUNTIFS(Students!$K$3:$K$114,"5D",Students!$I$3:$I$114,"Asian") -> 5 | F15: =MAX(B15:E15)-MIN(B15:E15) -> 1
A16: English learners | B16: =COUNTIFS(Students!$K$3:$K$114,"5A",Students!$J$3:$J$114,"Yes") -> 8 | C16: =COUNTIFS(Students!$K$3:$K$114,"5B",Students!$J$3:$J$114,"Yes") -> 7 | D16: =COUNTIFS(Students!$K$3:$K$114,"5C",Students!$J$3:$J$114,"Yes") -> 8 | E16: =COUNTIFS(Students!$K$3:$K$114,"5D",Students!$J$3:$J$114,"Yes") -> 8 | F16: =MAX(B16:E16)-MIN(B16:E16) -> 1
A17: English speakers | B17: =COUNTIFS(Students!$K$3:$K$114,"5A",Students!$J$3:$J$114,"No") -> 20 | C17: =COUNTIFS(Students!$K$3:$K$114,"5B",Students!$J$3:$J$114,"No") -> 21 | D17: =COUNTIFS(Students!$K$3:$K$114,"5C",Students!$J$3:$J$114,"No") -> 20 | E17: =COUNTIFS(Students!$K$3:$K$114,"5D",Students!$J$3:$J$114,"No") -> 20 | F17: =MAX(B17:E17)-MIN(B17:E17) -> 1

Sheet 5A
A1: Cohort 5A
A2: # | B2: Student ID | C2: Reading Score | D2: Reading Placement | E2: Math Score | F2: Math Placement
A3: 1 | B3: =IFERROR(INDEX(Students!$A$3:$A$114,MATCH(1,INDEX((Students!$K$3:$K$114="5A")*(Students!$L$3:$L$114=1),0),0)),"") -> S-001 | C3: =IFERROR(INDEX(Students!$B$3:$B$114,MATCH(1,INDEX((Students!$K$3:$K$114="5A")*(Students!$L$3:$L$114=1),0),0)),"") -> 542 | D3: =IFERROR(INDEX(Students!$C$3:$C$114,MATCH(1,INDEX((Students!$K$3:$K$114="5A")*(Students!$L$3:$L$114=1),0),0)),"") -> Grade 5 | E3: =IFERROR(INDEX(Students!$D$3:$D$114,MATCH(1,INDEX((Students!$K$3:$K$114="5A")*(Students!$L$3:$L$114=1),0),0)),"") -> 474 | F3: =IFERROR(INDEX(Students!$E$3:$E$114,MATCH(1,INDEX((Students!$K$3:$K$114="5A")*(Students!$L$3:$L$114=1),0),0)),"") -> Grade 3
A4: 2 | B4: =IFERROR(INDEX(Students!$A$3:$A$114,MATCH(1,INDEX((Students!$K$3:$K$114="5A")*(Students!$L$3:$L$114=2),0),0)),"") -> S-002 | C4: =IFERROR(INDEX(Students!$B$3:$B$114,MATCH(1,INDEX((Students!$K$3:$K$114="5A")*(Students!$L$3:$L$114=2),0),0)),"") -> 537 | D4: =IFERROR(INDEX(Students!$C$3:$C$114,MATCH(1,INDEX((Students!$K$3:$K$114="5A")*(Students!$L$3:$L$114=2),0),0)),"") -> Grade 5 | E4: =IFERROR(INDEX(Students!$D$3:$D$114,MATCH(1,INDEX((Students!$K$3:$K$114="5A")*(Students!$L$3:$L$114=2),0),0)),"") -> 473 | F4: =IFERROR(INDEX(Students!$E$3:$E$114,MATCH(1,INDEX((Students!$K$3:$K$114="5A")*(Students!$L$3:$L$114=2),0),0)),"") -> Grade 3
A5: 3 | B5: =IFERROR(INDEX(Students!$A$3:$A$114,MATCH(1,INDEX((Students!$K$3:$K$114="5A")*(Students!$L$3:$L$114=3),0),0)),"") -> S-003 | C5: =IFERROR(INDEX(Students!$B$3:$B$114,MATCH(1,INDEX((Students!$K$3:$K$114="5A")*(Students!$L$3:$L$114=3),0),0)),"") -> 536 | D5: =IFERROR(INDEX(Students!$C$3:$C$114,MATCH(1,INDEX((Students!$K$3:$K$114="5A")*(Students!$L$3:$L$114=3),0),0)),"") -> Grade 5 | E5: =IFERROR(INDEX(Students!$D$3:$D$114,MATCH(1,INDEX((Students!$K$3:$K$114="5A")*(Students!$L$3:$L$114=3),0),0)),"") -> 490 | F5: =IFERROR(INDEX(Students!$E$3:$E$114,MATCH(1,INDEX((Students!$K$3:$K$114="5A")*(Students!$L$3:$L$114=3),0),0)),"") -> Grade 3
A6: 4 | B6: =IFERROR(INDEX(Students!$A$3:$A$114,MATCH(1,INDEX((Students!$K$3:$K$114="5A")*(Students!$L$3:$L$114=4),0),0)),"") -> S-006 | C6: =IFERROR(INDEX(Students!$B$3:$B$114,MATCH(1,INDEX((Students!$K$3:$K$114="5A")*(Students!$L$3:$L$114=4),0),0)),"") -> 549 | D6: =IFERROR(INDEX(Students!$C$3:$C$114,MATCH(1,INDEX((Students!$K$3:$K$114="5A")*(Students!$L$3:$L$114=4),0),0)),"") -> Grade 5 | E6: =IFERROR(INDEX(Students!$D$3:$D$114,MATCH(1,INDEX((Students!$K$3:$K$114="5A")*(Students!$L$3:$L$114=4),0),0)),"") -> 516 | F6: =IFERROR(INDEX(Students!$E$3:$E$114,MATCH(1,INDEX((Students!$K$3:$K$114="5A")*(Students!$L$3:$L$114=4),0),0)),"") -> Grade 4
A7: 5 | B7: =IFERROR(INDEX(Students!$A$3:$A$114,MATCH(1,INDEX((Students!$K$3:$K$114="5A")*(Students!$L$3:$L$114=5),0),0)),"") -> S-009 | C7: =IFERROR(INDEX(Students!$B$3:$B$114,MATCH(1,INDEX((Students!$K$3:$K$114="5A")*(Students!$L$3:$L$114=5),0),0)),"") -> 477 | D7: =IFERROR(INDEX(Students!$C$3:$C$114,MATCH(1,INDEX((Students!$K$3:$K$114="5A")*(Students!$L$3:$L$114=5),0),0)),"") -> Grade 3 | E7: =IFERROR(INDEX(Students!$D$3:$D$114,MATCH(1,INDEX((Students!$K$3:$K$114="5A")*(Students!$L$3:$L$114=5),0),0)),"") -> 547 | F7: =IFERROR(INDEX(Students!$E$3:$E$114,MATCH(1,INDEX((Students!$K$3:$K$114="5A")*(Students!$L$3:$L$114=5),0),0)),"") -> Grade 5
A8: 6 | B8: =IFERROR(INDEX(Students!$A$3:$A$114,MATCH(1,INDEX((Students!$K$3:$K$114="5A")*(Students!$L$3:$L$114=6),0),0)),"") -> S-027 | C8: =IFERROR(INDEX(Students!$B$3:$B$114,MATCH(1,INDEX((Students!$K$3:$K$114="5A")*(Students!$L$3:$L$114=6),0),0)),"") -> 491 | D8: =IFERROR(INDEX(Students!$C$3:$C$114,MATCH(1,INDEX((Students!$K$3:$K$114="5A")*(Students!$L$3:$L$114=6),0),0)),"") -> Grade 3 | E8: =IFERROR(INDEX(Students!$D$3:$D$114,MATCH(1,INDEX((Students!$K$3:$K$114="5A")*(Students!$L$3:$L$114=6),0),0)),"") -> 563 | F8: =IFERROR(INDEX(Students!$E$3:$E$114,MATCH(1,INDEX((Students!$K$3:$K$114="5A")*(Students!$L$3:$L$114=6),0),0)),"") -> Grade 5
A9: 7 | B9: =IFERROR(INDEX(Students!$A$3:$A$114,MATCH(1,INDEX((Students!$K$3:$K$114="5A")*(Students!$L$3:$L$114=7),0),0)),"") -> S-028 | C9: =IFERROR(INDEX(Students!$B$3:$B$114,MATCH(1,INDEX((Students!$K$3:$K$114="5A")*(Students!$L$3:$L$114=7),0),0)),"") -> 465 | D9: =IFERROR(INDEX(Students!$C$3:$C$114,MATCH(1,INDEX((Students!$K$3:$K$114="5A")*(Students!$L$3:$L$114=7),0),0)),"") -> Grade 3 | E9: =IFERROR(INDEX(Students!$D$3:$D$114,MATCH(1,INDEX((Students!$K$3:$K$114="5A")*(Students!$L$3:$L$114=7),0),0)),"") -> 451 | F9: =IFERROR(INDEX(Students!$E$3:$E$114,MATCH(1,INDEX((Students!$K$3:$K$114="5A")*(Students!$L$3:$L$114=7),0),0)),"") -> Grade 2
A10: 8 | B10: =IFERROR(INDEX(Students!$A$3:$A$114,MATCH(1,INDEX((Students!$K$3:$K$114="5A")*(Students!$L$3:$L$114=8),0),0)),"") -> S-029 | C10: =IFERROR(INDEX(Students!$B$3:$B$114,MATCH(1,INDEX((Students!$K$3:$K$114="5A")*(Students!$L$3:$L$114=8),0),0)),"") -> 520 | D10: =IFERROR(INDEX(Students!$C$3:$C$114,MATCH(1,INDEX((Students!$K$3:$K$114="5A")*(Students!$L$3:$L$114=8),0),0)),"") -> Grade 4 | E10: =IFERROR(INDEX(Students!$D$3:$D$114,MATCH(1,INDEX((Students!$K$3:$K$114="5A")*(Students!$L$3:$L$114=8),0),0)),"") -> 477 | F10: =IFERROR(INDEX(Students!$E$3:$E$114,MATCH(1,INDEX((Students!$K$3:$K$114="5A")*(Students!$L$3:$L$114=8),0),0)),"") -> Grade 3
A11: 9 | B11: =IFERROR(INDEX(Students!$A$3:$A$114,MATCH(1,INDEX((Students!$K$3:$K$114="5A")*(Students!$L$3:$L$114=9),0),0)),"") -> S-030 | C11: =IFERROR(INDEX(Students!$B$3:$B$114,MATCH(1,INDEX((Students!$K$3:$K$114="5A")*(Students!$L$3:$L$114=9),0),0)),"") -> 456 | D11: =IFERROR(INDEX(Students!$C$3:$C$114,MATCH(1,INDEX((Students!$K$3:$K$114="5A")*(Students!$L$3:$L$114=9),0),0)),"") -> Grade 2 | E11: =IFERROR(INDEX(Students!$D$3:$D$114,MATCH(1,INDEX((Students!$K$3:$K$114="5A")*(Students!$L$3:$L$114=9),0),0)),"") -> 525 | F11: =IFERROR(INDEX(Students!$E$3:$E$114,MATCH(1,INDEX((Students!$K$3:$K$114="5A")*(Students!$L$3:$L$114=9),0),0)),"") -> Grade 4
A12: 10 | B12: =IFERROR(INDEX(Students!$A$3:$A$114,MATCH(1,INDEX((Students!$K$3:$K$114="5A")*(Students!$L$3:$L$114=10),0),0)),"") -> S-032 | C12: =IFERROR(INDEX(Students!$B$3:$B$114,MATCH(1,INDEX((Students!$K$3:$K$114="5A")*(Students!$L$3:$L$114=10),0),0)),"") -> 438 | D12: =IFERROR(INDEX(Students!$C$3:$C$114,MATCH(1,INDEX((Students!$K$3:$K$114="5A")*(Students!$L$3:$L$114=10),0),0)),"") -> Grade 2 | E12: =IFERROR(INDEX(Students!$D$3:$D$114,MATCH(1,INDEX((Students!$K$3:$K$114="5A")*(Students!$L$3:$L$114=10),0),0)),"") -> 494 | F12: =IFERROR(INDEX(Students!$E$3:$E$114,MATCH(1,INDEX((Students!$K$3:$K$114="5A")*(Students!$L$3:$L$114=10),0),0)),"") -> Grade 3
A13: 11 | B13: =IFERROR(INDEX(Students!$A$3:$A$114,MATCH(1,INDEX((Students!$K$3:$K$114="5A")*(Students!$L$3:$L$114=11),0),0)),"") -> S-037 | C13: =IFERROR(INDEX(Students!$B$3:$B$114,MATCH(1,INDEX((Students!$K$3:$K$114="5A")*(Students!$L$3:$L$114=11),0),0)),"") -> 567 | D13: =IFERROR(INDEX(Students!$C$3:$C$114,MATCH(1,INDEX((Students!$K$3:$K$114="5A")*(Students!$L$3:$L$114=11),0),0)),"") -> Grade 5 | E13: =IFERROR(INDEX(Students!$D$3:$D$114,MATCH(1,INDEX((Students!$K$3:$K$114="5A")*(Students!$L$3:$L$114=11),0),0)),"") -> 476 | F13: =IFERROR(INDEX(Students!$E$3:$E$114,MATCH(1,INDEX((Students!$K$3:$K$114="5A")*(Students!$L$3:$L$114=11),0),0)),"") -> Grade 3
A14: 12 | B14: =IFERROR(INDEX(Students!$A$3:$A$114,MATCH(1,INDEX((Students!$K$3:$K$114="5A")*(Students!$L$3:$L$114=12),0),0)),"") -> S-038 | C14: =IFERROR(INDEX(Students!$B$3:$B$114,MATCH(1,INDEX((Students!$K$3:$K$114="5A")*(Students!$L$3:$L$114=12),0),0)),"") -> 538 | D14: =IFERROR(INDEX(Students!$C$3:$C$114,MATCH(1,INDEX((Students!$K$3:$K$114="5A")*(Students!$L$3:$L$114=12),0),0)),"") -> Grade 4 | E14: =IFERROR(INDEX(Students!$D$3:$D$114,MATCH(1,INDEX((Students!$K$3:$K$114="5A")*(Students!$L$3:$L$114=12),0),0)),"") -> 411 | F14: =IFERROR(INDEX(Students!$E$3:$E$114,MATCH(1,INDEX((Students!$K$3:$K$114="5A")*(Students!$L$3:$L$114=12),0),0)),"") -> Grade 1
A15: 13 | B15: =IFERROR(INDEX(Students!$A$3:$A$114,MATCH(1,INDEX((Students!$K$3:$K$114="5A")*(Students!$L$3:$L$114=13),0),0)),"") -> S-039 | C15: =IFERROR(INDEX(Students!$B$3:$B$114,MATCH(1,INDEX((Students!$K$3:$K$114="5A")*(Students!$L$3:$L$114=13),0),0)),"") -> 404 | D15: =IFERROR(INDEX(Students!$C$3:$C$114,MATCH(1,INDEX((Students!$K$3:$K$114="5A")*(Students!$L$3:$L$114=13),0),0)),"") -> Grade 1 | E15: =IFERROR(INDEX(Students!$D$3:$D$114,MATCH(1,INDEX((Students!$K$3:$K$114="5A")*(Students!$L$3:$L$114=13),0),0)),"") -> 511 | F15: =IFERROR(INDEX(Students!$E$3:$E$114,MATCH(1,INDEX((Students!$K$3:$K$114="5A")*(Students!$L$3:$L$114=13),0),0)),"") -> Grade 4
A16: 14 | B16: =IFERROR(INDEX(Students!$A$3:$A$114,MATCH(1,INDEX((Students!$K$3:$K$114="5A")*(Students!$L$3:$L$114=14),0),0)),"") -> S-045 | C16: =IFERROR(INDEX(Students!$B$3:$B$114,MATCH(1,INDEX((Students!$K$3:$K$114="5A")*(Students!$L$3:$L$114=14),0),0)),"") -> 471 | D16: =IFERROR(INDEX(Students!$C$3:$C$114,MATCH(1,INDEX((Students!$K$3:$K$114="5A")*(Students!$L$3:$L$114=14),0),0)),"") -> Grade 3 | E16: =IFERROR(INDEX(Students!$D$3:$D$114,MATCH(1,INDEX((Students!$K$3:$K$114="5A")*(Students!$L$3:$L$114=14),0),0)),"") -> 515 | F16: =IFERROR(INDEX(Students!$E$3:$E$114,MATCH(1,INDEX((Students!$K$3:$K$114="5A")*(Students!$L$3:$L$114=14),0),0)),"") -> Grade 4
A17: 15 | B17: =IFERROR(INDEX(Students!$A$3:$A$114,MATCH(1,INDEX((Students!$K$3:$K$114="5A")*(Students!$L$3:$L$114=15),0),0)),"") -> S-048 | C17: =IFERROR(INDEX(Students!$B$3:$B$114,MATCH(1,INDEX((Students!$K$3:$K$114="5A")*(Students!$L$3:$L$114=15),0),0)),"") -> 514 | D17: =IFERROR(INDEX(Students!$C$3:$C$114,MATCH(1,INDEX((Students!$K$3:$K$114="5A")*(Students!$L$3:$L$114=15),0),0)),"") -> Grade 4 | E17: =IFERROR(INDEX(Students!$D$3:$D$114,MATCH(1,INDEX((Students!$K$3:$K$114="5A")*(Students!$L$3:$L$114=15),0),0)),"") -> 557 | F17: =IFERROR(INDEX(Students!$E$3:$E$114,MATCH(1,INDEX((Students!$K$3:$K$114="5A")*(Students!$L$3:$L$114=15),0),0)),"") -> Grade 5
A18: 16 | B18: =IFERROR(INDEX(Students!$A$3:$A$114,MATCH(1,INDEX((Students!$K$3:$K$114="5A")*(Students!$L$3:$L$114=16),0),0)),"") -> S-058 | C18: =IFERROR(INDEX(Students!$B$3:$B$114,MATCH(1,INDEX((Students!$K$3:$K$114="5A")*(Students!$L$3:$L$114=16),0),0)),"") -> 542 | D18: =IFERROR(INDEX(Students!$C$3:$C$114,MATCH(1,INDEX((Students!$K$3:$K$114="5A")*(Students!$L$3:$L$114=16),0),0)),"") -> Grade 5 | E18: =IFERROR(INDEX(Students!$D$3:$D$114,MATCH(1,INDEX((Students!$K$3:$K$114="5A")*(Students!$L$3:$L$114=16),0),0)),"") -> 453 | F18: =IFERROR(INDEX(Students!$E$3:$E$114,MATCH(1,INDEX((Students!$K$3:$K$114="5A")*(Students!$L$3:$L$114=16),0),0)),"") -> Grade 2
A19: 17 | B19: =IFERROR(INDEX(Students!$A$3:$A$114,MATCH(1,INDEX((Students!$K$3:$K$114="5A")*(Students!$L$3:$L$114=17),0),0)),"") -> S-060 | C19: =IFERROR(INDEX(Students!$B$3:$B$114,MATCH(1,INDEX((Students!$K$3:$K$114="5A")*(Students!$L$3:$L$114=17),0),0)),"") -> 522 | D19: =IFERROR(INDEX(Students!$C$3:$C$114,MATCH(1,INDEX((Students!$K$3:$K$114="5A")*(Students!$L$3:$L$114=17),0),0)),"") -> Grade 4 | E19: =IFERROR(INDEX(Students!$D$3:$D$114,MATCH(1,INDEX((Students!$K$3:$K$114="5A")*(Students!$L$3:$L$114=17),0),0)),"") -> 433 | F19: =IFERROR(INDEX(Students!$E$3:$E$114,MATCH(1,INDEX((Students!$K$3:$K$114="5A")*(Students!$L$3:$L$114=17),0),0)),"") -> Grade 1
A20: 18 | B20: =IFERROR(INDEX(Students!$A$3:$A$114,MATCH(1,INDEX((Students!$K$3:$K$114="5A")*(Students!$L$3:$L$114=18),0),0)),"") -> S-061 | C20: =IFERROR(INDEX(Students!$B$3:$B$114,MATCH(1,INDEX((Students!$K$3:$K$114="5A")*(Students!$L$3:$L$114=18),0),0)),"") -> 507 | D20: =IFERROR(INDEX(Students!$C$3:$C$114,MATCH(1,INDEX((Students!$K$3:$K$114="5A")*(Students!$L$3:$L$114=18),0),0)),"") -> Grade 4 | E20: =IFERROR(INDEX(Students!$D$3:$D$114,MATCH(1,INDEX((Students!$K$3:$K$114="5A")*(Students!$L$3:$L$114=18),0),0)),"") -> 490 | F20: =IFERROR(INDEX(Students!$E$3:$E$114,MATCH(1,INDEX((Students!$K$3:$K$114="5A")*(Students!$L$3:$L$114=18),0),0)),"") -> Grade 3
A21: 19 | B21: =IFERROR(INDEX(Students!$A$3:$A$114,MATCH(1,INDEX((Students!$K$3:$K$114="5A")*(Students!$L$3:$L$114=19),0),0)),"") -> S-062 | C21: =IFERROR(INDEX(Students!$B$3:$B$114,MATCH(1,INDEX((Students!$K$3:$K$114="5A")*(Students!$L$3:$L$114=19),0),0)),"") -> 503 | D21: =IFERROR(INDEX(Students!$C$3:$C$114,MATCH(1,INDEX((Students!$K$3:$K$114="5A")*(Students!$L$3:$L$114=19),0),0)),"") -> Grade 3 | E21: =IFERROR(INDEX(Students!$D$3:$D$114,MATCH(1,INDEX((Students!$K$3:$K$114="5A")*(Students!$L$3:$L$114=19),0),0)),"") -> 462 | F21: =IFERROR(INDEX(Students!$E$3:$E$114,MATCH(1,INDEX((Students!$K$3:$K$114="5A")*(Students!$L$3:$L$114=19),0),0)),"") -> Grade 2
A22: 20 | B22: =IFERROR(INDEX(Students!$A$3:$A$114,MATCH(1,INDEX((Students!$K$3:$K$114="5A")*(Students!$L$3:$L$114=20),0),0)),"") -> S-065 | C22: =IFERROR(INDEX(Students!$B$3:$B$114,MATCH(1,INDEX((Students!$K$3:$K$114="5A")*(Students!$L$3:$L$114=20),0),0)),"") -> 505 | D22: =IFERROR(INDEX(Students!$C$3:$C$114,MATCH(1,INDEX((Students!$K$3:$K$114="5A")*(Students!$L$3:$L$114=20),0),0)),"") -> Grade 4 | E22: =IFERROR(INDEX(Students!$D$3:$D$114,MATCH(1,INDEX((Students!$K$3:$K$114="5A")*(Students!$L$3:$L$114=20),0),0)),"") -> 492 | F22: =IFERROR(INDEX(Students!$E$3:$E$114,MATCH(1,INDEX((Students!$K$3:$K$114="5A")*(Students!$L$3:$L$114=20),0),0)),"") -> Grade 3
A23: 21 | B23: =IFERROR(INDEX(Students!$A$3:$A$114,MATCH(1,INDEX((Students!$K$3:$K$114="5A")*(Students!$L$3:$L$114=21),0),0)),"") -> S-067 | C23: =IFERROR(INDEX(Students!$B$3:$B$114,MATCH(1,INDEX((Students!$K$3:$K$114="5A")*(Students!$L$3:$L$114=21),0),0)),"") -> 481 | D23: =IFERROR(INDEX(Students!$C$3:$C$114,MATCH(1,INDEX((Students!$K$3:$K$114="5A")*(Students!$L$3:$L$114=21),0),0)),"") -> Grade 3 | E23: =IFERROR(INDEX(Students!$D$3:$D$114,MATCH(1,INDEX((Students!$K$3:$K$114="5A")*(Students!$L$3:$L$114=21),0),0)),"") -> 567 | F23: =IFERROR(INDEX(Students!$E$3:$E$114,MATCH(1,INDEX((Students!$K$3:$K$114="5A")*(Students!$L$3:$L$114=21),0),0)),"") -> Grade 5
A24: 22 | B24: =IFERROR(INDEX(Students!$A$3:$A$114,MATCH(1,INDEX((Students!$K$3:$K$114="5A")*(Students!$L$3:$L$114=22),0),0)),"") -> S-075 | C24: =IFERROR(INDEX(Students!$B$3:$B$114,MATCH(1,INDEX((Students!$K$3:$K$114="5A")*(Students!$L$3:$L$114=22),0),0)),"") -> 475 | D24: =IFERROR(INDEX(Students!$C$3:$C$114,MATCH(1,INDEX((Students!$K$3:$K$114="5A")*(Students!$L$3:$L$114=22),0),0)),"") -> Grade 3 | E24: =IFERROR(INDEX(Students!$D$3:$D$114,MATCH(1,INDEX((Students!$K$3:$K$114="5A")*(Students!$L$3:$L$114=22),0),0)),"") -> 532 | F24: =IFERROR(INDEX(Students!$E$3:$E$114,MATCH(1,INDEX((Students!$K$3:$K$114="5A")*(Students!$L$3:$L$114=22),0),0)),"") -> Grade 4
A25: 23 | B25: =IFERROR(INDEX(Students!$A$3:$A$114,MATCH(1,INDEX((Students!$K$3:$K$114="5A")*(Students!$L$3:$L$114=23),0),0)),"") -> S-078 | C25: =IFERROR(INDEX(Students!$B$3:$B$114,MATCH(1,INDEX((Students!$K$3:$K$114="5A")*(Students!$L$3:$L$114=23),0),0)),"") -> 541 | D25: =IFERROR(INDEX(Students!$C$3:$C$114,MATCH(1,INDEX((Students!$K$3:$K$114="5A")*(Students!$L$3:$L$114=23),0),0)),"") -> Grade 5 | E25: =IFERROR(INDEX(Students!$D$3:$D$114,MATCH(1,INDEX((Students!$K$3:$K$114="5A")*(Students!$L$3:$L$114=23),0),0)),"") -> 550 | F25: =IFERROR(INDEX(Students!$E$3:$E$114,MATCH(1,INDEX((Students!$K$3:$K$114="5A")*(Students!$L$3:$L$114=23),0),0)),"") -> Grade 5
A26: 24 | B26: =IFERROR(INDEX(Students!$A$3:$A$114,MATCH(1,INDEX((Students!$K$3:$K$114="5A")*(Students!$L$3:$L$114=24),0),0)),"") -> S-085 | C26: =IFERROR(INDEX(Students!$B$3:$B$114,MATCH(1,INDEX((Students!$K$3:$K$114="5A")*(Students!$L$3:$L$114=24),0),0)),"") -> 535 | D26: =IFERROR(INDEX(Students!$C$3:$C$114,MATCH(1,INDEX((Students!$K$3:$K$114="5A")*(Students!$L$3:$L$114=24),0),0)),"") -> Grade 4 | E26: =IFERROR(INDEX(Students!$D$3:$D$114,MATCH(1,INDEX((Students!$K$3:$K$114="5A")*(Students!$L$3:$L$114=24),0),0)),"") -> 517 | F26: =IFERROR(INDEX(Students!$E$3:$E$114,MATCH(1,INDEX((Students!$K$3:$K$114="5A")*(Students!$L$3:$L$114=24),0),0)),"") -> Grade 4
A27: 25 | B27: =IFERROR(INDEX(Students!$A$3:$A$114,MATCH(1,INDEX((Students!$K$3:$K$114="5A")*(Students!$L$3:$L$114=25),0),0)),"") -> S-098 | C27: =IFERROR(INDEX(Students!$B$3:$B$114,MATCH(1,INDEX((Students!$K$3:$K$114="5A")*(Students!$L$3:$L$114=25),0),0)),"") -> 456 | D27: =IFERROR(INDEX(Students!$C$3:$C$114,MATCH(1,INDEX((Students!$K$3:$K$114="5A")*(Students!$L$3:$L$114=25),0),0)),"") -> Grade 2 | E27: =IFERROR(INDEX(Students!$D$3:$D$114,MATCH(1,INDEX((Students!$K$3:$K$114="5A")*(Students!$L$3:$L$114=25),0),0)),"") -> 553 | F27: =IFERROR(INDEX(Students!$E$3:$E$114,MATCH(1,INDEX((Students!$K$3:$K$114="5A")*(Students!$L$3:$L$114=25),0),0)),"") -> Grade 5
A28: 26 | B28: =IFERROR(INDEX(Students!$A$3:$A$114,MATCH(1,INDEX((Students!$K$3:$K$114="5A")*(Students!$L$3:$L$114=26),0),0)),"") -> S-099 | C28: =IFERROR(INDEX(Students!$B$3:$B$114,MATCH(1,INDEX((Students!$K$3:$K$114="5A")*(Students!$L$3:$L$114=26),0),0)),"") -> 457 | D28: =IFERROR(INDEX(Students!$C$3:$C$114,MATCH(1,INDEX((Students!$K$3:$K$114="5A")*(Students!$L$3:$L$114=26),0),0)),"") -> Grade 2 | E28: =IFERROR(INDEX(Students!$D$3:$D$114,MATCH(1,INDEX((Students!$K$3:$K$114="5A")*(Students!$L$3:$L$114=26),0),0)),"") -> 538 | F28: =IFERROR(INDEX(Students!$E$3:$E$114,MATCH(1,INDEX((Students!$K$3:$K$114="5A")*(Students!$L$3:$L$114=26),0),0)),"") -> Grade 5
A29: 27 | B29: =IFERROR(INDEX(Students!$A$3:$A$114,MATCH(1,INDEX((Students!$K$3:$K$114="5A")*(Students!$L$3:$L$114=27),0),0)),"") -> S-105 | C29: =IFERROR(INDEX(Students!$B$3:$B$114,MATCH(1,INDEX((Students!$K$3:$K$114="5A")*(Students!$L$3:$L$114=27),0),0)),"") -> 414 | D29: =IFERROR(INDEX(Students!$C$3:$C$114,MATCH(1,INDEX((Students!$K$3:$K$114="5A")*(Students!$L$3:$L$114=27),0),0)),"") -> Grade 1 | E29: =IFERROR(INDEX(Students!$D$3:$D$114,MATCH(1,INDEX((Students!$K$3:$K$114="5A")*(Students!$L$3:$L$114=27),0),0)),"") -> 480 | F29: =IFERROR(INDEX(Students!$E$3:$E$114,MATCH(1,INDEX((Students!$K$3:$K$114="5A")*(Students!$L$3:$L$114=27),0),0)),"") -> Grade 3
A30: 28 | B30: =IFERROR(INDEX(Students!$A$3:$A$114,MATCH(1,INDEX((Students!$K$3:$K$114="5A")*(Students!$L$3:$L$114=28),0),0)),"") -> S-107 | C30: =IFERROR(INDEX(Students!$B$3:$B$114,MATCH(1,INDEX((Students!$K$3:$K$114="5A")*(Students!$L$3:$L$114=28),0),0)),"") -> 536 | D30: =IFERROR(INDEX(Students!$C$3:$C$114,MATCH(1,INDEX((Students!$K$3:$K$114="5A")*(Students!$L$3:$L$114=28),0),0)),"") -> Grade 5 | E30: =IFERROR(INDEX(Students!$D$3:$D$114,MATCH(1,INDEX((Students!$K$3:$K$114="5A")*(Students!$L$3:$L$114=28),0),0)),"") -> 535 | F30: =IFERROR(INDEX(Students!$E$3:$E$114,MATCH(1,INDEX((Students!$K$3:$K$114="5A")*(Students!$L$3:$L$114=28),0),0)),"") -> Grade 5
A31: 29 | B31: =IFERROR(INDEX(Students!$A$3:$A$114,MATCH(1,INDEX((Students!$K$3:$K$114="5A")*(Students!$L$3:$L$114=29),0),0)),"") | C31: =IFERROR(INDEX(Students!$B$3:$B$114,MATCH(1,INDEX((Students!$K$3:$K$114="5A")*(Students!$L$3:$L$114=29),0),0)),"") | D31: =IFERROR(INDEX(Students!$C$3:$C$114,MATCH(1,INDEX((Students!$K$3:$K$114="5A")*(Students!$L$3:$L$114=29),0),0)),"") | E31: =IFERROR(INDEX(Students!$D$3:$D$114,MATCH(1,INDEX((Students!$K$3:$K$114="5A")*(Students!$L$3:$L$114=29),0),0)),"") | F31: =IFERROR(INDEX(Students!$E$3:$E$114,MATCH(1,INDEX((Students!$K$3:$K$114="5A")*(Students!$L$3:$L$114=29),0),0)),"")
A32: 30 | B32: =IFERROR(INDEX(Students!$A$3:$A$114,MATCH(1,INDEX((Students!$K$3:$K$114="5A")*(Students!$L$3:$L$114=30),0),0)),"") | C32: =IFERROR(INDEX(Students!$B$3:$B$114,MATCH(1,INDEX((Students!$K$3:$K$114="5A")*(Students!$L$3:$L$114=30),0),0)),"") | D32: =IFERROR(INDEX(Students!$C$3:$C$114,MATCH(1,INDEX((Students!$K$3:$K$114="5A")*(Students!$L$3:$L$114=30),0),0)),"") | E32: =IFERROR(INDEX(Students!$D$3:$D$114,MATCH(1,INDEX((Students!$K$3:$K$114="5A")*(Students!$L$3:$L$114=30),0),0)),"") | F32: =IFERROR(INDEX(Students!$E$3:$E$114,MATCH(1,INDEX((Students!$K$3:$K$114="5A")*(Students!$L$3:$L$114=30),0),0)),"")
A33: 31 | B33: =IFERROR(INDEX(Students!$A$3:$A$114,MATCH(1,INDEX((Students!$K$3:$K$114="5A")*(Students!$L$3:$L$114=31),0),0)),"") | C33: =IFERROR(INDEX(Students!$B$3:$B$114,MATCH(1,INDEX((Students!$K$3:$K$114="5A")*(Students!$L$3:$L$114=31),0),0)),"") | D33: =IFERROR(INDEX(Students!$C$3:$C$114,MATCH(1,INDEX((Students!$K$3:$K$114="5A")*(Students!$L$3:$L$114=31),0),0)),"") | E33: =IFERROR(INDEX(Students!$D$3:$D$114,MATCH(1,INDEX((Students!$K$3:$K$114="5A")*(Students!$L$3:$L$114=31),0),0)),"") | F33: =IFERROR(INDEX(Students!$E$3:$E$114,MATCH(1,INDEX((Students!$K$3:$K$114="5A")*(Students!$L$3:$L$114=31),0),0)),"")
A34: 32 | B34: =IFERROR(INDEX(Students!$A$3:$A$114,MATCH(1,INDEX((Students!$K$3:$K$114="5A")*(Students!$L$3:$L$114=32),0),0)),"") | C34: =IFERROR(INDEX(Students!$B$3:$B$114,MATCH(1,INDEX((Students!$K$3:$K$114="5A")*(Students!$L$3:$L$114=32),0),0)),"") | D34: =IFERROR(INDEX(Students!$C$3:$C$114,MATCH(1,INDEX((Students!$K$3:$K$114="5A")*(Students!$L$3:$L$114=32),0),0)),"") | E34: =IFERROR(INDEX(Students!$D$3:$D$114,MATCH(1,INDEX((Students!$K$3:$K$114="5A")*(Students!$L$3:$L$114=32),0),0)),"") | F34: =IFERROR(INDEX(Students!$E$3:$E$114,MATCH(1,INDEX((Students!$K$3:$K$114="5A")*(Students!$L$3:$L$114=32),0),0)),"")
A35: 33 | B35: =IFERROR(INDEX(Students!$A$3:$A$114,MATCH(1,INDEX((Students!$K$3:$K$114="5A")*(Students!$L$3:$L$114=33),0),0)),"") | C35: =IFERROR(INDEX(Students!$B$3:$B$114,MATCH(1,INDEX((Students!$K$3:$K$114="5A")*(Students!$L$3:$L$114=33),0),0)),"") | D35: =IFERROR(INDEX(Students!$C$3:$C$114,MATCH(1,INDEX((Students!$K$3:$K$114="5A")*(Students!$L$3:$L$114=33),0),0)),"") | E35: =IFERROR(INDEX(Students!$D$3:$D$114,MATCH(1,INDEX((Students!$K$3:$K$114="5A")*(Students!$L$3:$L$114=33),0),0)),"") | F35: =IFERROR(INDEX(Students!$E$3:$E$114,MATCH(1,INDEX((Students!$K$3:$K$114="5A")*(Students!$L$3:$L$114=33),0),0)),"")
A36: 34 | B36: =IFERROR(INDEX(Students!$A$3:$A$114,MATCH(1,INDEX((Students!$K$3:$K$114="5A")*(Students!$L$3:$L$114=34),0),0)),"") | C36: =IFERROR(INDEX(Students!$B$3:$B$114,MATCH(1,INDEX((Students!$K$3:$K$114="5A")*(Students!$L$3:$L$114=34),0),0)),"") | D36: =IFERROR(INDEX(Students!$C$3:$C$114,MATCH(1,INDEX((Students!$K$3:$K$114="5A")*(Students!$L$3:$L$114=34),0),0)),"") | E36: =IFERROR(INDEX(Students!$D$3:$D$114,MATCH(1,INDEX((Students!$K$3:$K$114="5A")*(Students!$L$3:$L$114=34),0),0)),"") | F36: =IFERROR(INDEX(Students!$E$3:$E$114,MATCH(1,INDEX((Students!$K$3:$K$114="5A")*(Students!$L$3:$L$114=34),0),0)),"")
A37: 35 | B37: =IFERROR(INDEX(Students!$A$3:$A$114,MATCH(1,INDEX((Students!$K$3:$K$114="5A")*(Students!$L$3:$L$114=35),0),0)),"") | C37: =IFERROR(INDEX(Students!$B$3:$B$114,MATCH(1,INDEX((Students!$K$3:$K$114="5A")*(Students!$L$3:$L$114=35),0),0)),"") | D37: =IFERROR(INDEX(Students!$C$3:$C$114,MATCH(1,INDEX((Students!$K$3:$K$114="5A")*(Students!$L$3:$L$114=35),0),0)),"") | E37: =IFERROR(INDEX(Students!$D$3:$D$114,MATCH(1,INDEX((Students!$K$3:$K$114="5A")*(Students!$L$3:$L$114=35),0),0)),"") | F37: =IFERROR(INDEX(Students!$E$3:$E$114,MATCH(1,INDEX((Students!$K$3:$K$114="5A")*(Students!$L$3:$L$114=35),0),0)),"")

Sheet 5B
A1: Cohort 5B
A2: # | B2: Student ID | C2: Reading Score | D2: Reading Placement | E2: Math Score | F2: Math Placement
A3: 1 | B3: =IFERROR(INDEX(Students!$A$3:$A$114,MATCH(1,INDEX((Students!$K$3:$K$114="5B")*(Students!$L$3:$L$114=1),0),0)),"") -> S-008 | C3: =IFERROR(INDEX(Students!$B$3:$B$114,MATCH(1,INDEX((Students!$K$3:$K$114="5B")*(Students!$L$3:$L$114=1),0),0)),"") -> 546 | D3: =IFERROR(INDEX(Students!$C$3:$C$114,MATCH(1,INDEX((Students!$K$3:$K$114="5B")*(Students!$L$3:$L$114=1),0),0)),"") -> Grade 5 | E3: =IFERROR(INDEX(Students!$D$3:$D$114,MATCH(1,INDEX((Students!$K$3:$K$114="5B")*(Students!$L$3:$L$114=1),0),0)),"") -> 573 | F3: =IFERROR(INDEX(Students!$E$3:$E$114,MATCH(1,INDEX((Students!$K$3:$K$114="5B")*(Students!$L$3:$L$114=1),0),0)),"") -> Grade 5
A4: 2 | B4: =IFERROR(INDEX(Students!$A$3:$A$114,MATCH(1,INDEX((Students!$K$3:$K$114="5B")*(Students!$L$3:$L$114=2),0),0)),"") -> S-010 | C4: =IFERROR(INDEX(Students!$B$3:$B$114,MATCH(1,INDEX((Students!$K$3:$K$114="5B")*(Students!$L$3:$L$114=2),0),0)),"") -> 575 | D4: =IFERROR(INDEX(Students!$C$3:$C$114,MATCH(1,INDEX((Students!$K$3:$K$114="5B")*(Students!$L$3:$L$114=2),0),0)),"") -> Grade 5 | E4: =IFERROR(INDEX(Students!$D$3:$D$114,MATCH(1,INDEX((Students!$K$3:$K$114="5B")*(Students!$L$3:$L$114=2),0),0)),"") -> 547 | F4: =IFERROR(INDEX(Students!$E$3:$E$114,MATCH(1,INDEX((Students!$K$3:$K$114="5B")*(Students!$L$3:$L$114=2),0),0)),"") -> Grade 5
A5: 3 | B5: =IFERROR(INDEX(Students!$A$3:$A$114,MATCH(1,INDEX((Students!$K$3:$K$114="5B")*(Students!$L$3:$L$114=3),0),0)),"") -> S-012 | C5: =IFERROR(INDEX(Students!$B$3:$B$114,MATCH(1,INDEX((Students!$K$3:$K$114="5B")*(Students!$L$3:$L$114=3),0),0)),"") -> 496 | D5: =IFERROR(INDEX(Students!$C$3:$C$114,MATCH(1,INDEX((Students!$K$3:$K$114="5B")*(Students!$L$3:$L$114=3),0),0)),"") -> Grade 3 | E5: =IFERROR(INDEX(Students!$D$3:$D$114,MATCH(1,INDEX((Students!$K$3:$K$114="5B")*(Students!$L$3:$L$114=3),0),0)),"") -> 396 | F5: =IFERROR(INDEX(Students!$E$3:$E$114,MATCH(1,INDEX((Students!$K$3:$K$114="5B")*(Students!$L$3:$L$114=3),0),0)),"") -> Grade 1
A6: 4 | B6: =IFERROR(INDEX(Students!$A$3:$A$114,MATCH(1,INDEX((Students!$K$3:$K$114="5B")*(Students!$L$3:$L$114=4),0),0)),"") -> S-019 | C6: =IFERROR(INDEX(Students!$B$3:$B$114,MATCH(1,INDEX((Students!$K$3:$K$114="5B")*(Students!$L$3:$L$114=4),0),0)),"") -> 528 | D6: =IFERROR(INDEX(Students!$C$3:$C$114,MATCH(1,INDEX((Students!$K$3:$K$114="5B")*(Students!$L$3:$L$114=4),0),0)),"") -> Grade 4 | E6: =IFERROR(INDEX(Students!$D$3:$D$114,MATCH(1,INDEX((Students!$K$3:$K$114="5B")*(Students!$L$3:$L$114=4),0),0)),"") -> 512 | F6: =IFERROR(INDEX(Students!$E$3:$E$114,MATCH(1,INDEX((Students!$K$3:$K$114="5B")*(Students!$L$3:$L$114=4),0),0)),"") -> Grade 4
A7: 5 | B7: =IFERROR(INDEX(Students!$A$3:$A$114,MATCH(1,INDEX((Students!$K$3:$K$114="5B")*(Students!$L$3:$L$114=5),0),0)),"") -> S-020 | C7: =IFERROR(INDEX(Students!$B$3:$B$114,MATCH(1,INDEX((Students!$K$3:$K$114="5B")*(Students!$L$3:$L$114=5),0),0)),"") -> 469 | D7: =IFERROR(INDEX(Students!$C$3:$C$114,MATCH(1,INDEX((Students!$K$3:$K$114="5B")*(Students!$L$3:$L$114=5),0),0)),"") -> Grade 3 | E7: =IFERROR(INDEX(Students!$D$3:$D$114,MATCH(1,INDEX((Students!$K$3:$K$114="5B")*(Students!$L$3:$L$114=5),0),0)),"") -> 434 | F7: =IFERROR(INDEX(Students!$E$3:$E$114,MATCH(1,INDEX((Students!$K$3:$K$114="5B")*(Students!$L$3:$L$114=5),0),0)),"") -> Grade 1
A8: 6 | B8: =IFERROR(INDEX(Students!$A$3:$A$114,MATCH(1,INDEX((Students!$K$3:$K$114="5B")*(Students!$L$3:$L$114=6),0),0)),"") -> S-025 | C8: =IFERROR(INDEX(Students!$B$3:$B$114,MATCH(1,INDEX((Students!$K$3:$K$114="5B")*(Students!$L$3:$L$114=6),0),0)),"") -> 445 | D8: =IFERROR(INDEX(Students!$C$3:$C$114,MATCH(1,INDEX((Students!$K$3:$K$114="5B")*(Students!$L$3:$L$114=6),0),0)),"") -> Grade 2 | E8: =IFERROR(INDEX(Students!$D$3:$D$114,MATCH(1,INDEX((Students!$K$3:$K$114="5B")*(Students!$L$3:$L$114=6),0),0)),"") -> 410 | F8: =IFERROR(INDEX(Students!$E$3:$E$114,MATCH(1,INDEX((Students!$K$3:$K$114="5B")*(Students!$L$3:$L$114=6),0),0)),"") -> Grade 1
A9: 7 | B9: =IFERROR(INDEX(Students!$A$3:$A$114,MATCH(1,INDEX((Students!$K$3:$K$114="5B")*(Students!$L$3:$L$114=7),0),0)),"") -> S-036 | C9: =IFERROR(INDEX(Students!$B$3:$B$114,MATCH(1,INDEX((Students!$K$3:$K$114="5B")*(Students!$L$3:$L$114=7),0),0)),"") -> 519 | D9: =IFERROR(INDEX(Students!$C$3:$C$114,MATCH(1,INDEX((Students!$K$3:$K$114="5B")*(Students!$L$3:$L$114=7),0),0)),"") -> Grade 4 | E9: =IFERROR(INDEX(Students!$D$3:$D$114,MATCH(1,INDEX((Students!$K$3:$K$114="5B")*(Students!$L$3:$L$114=7),0),0)),"") -> 520 | F9: =IFERROR(INDEX(Students!$E$3:$E$114,MATCH(1,INDEX((Students!$K$3:$K$114="5B")*(Students!$L$3:$L$114=7),0),0)),"") -> Grade 4
A10: 8 | B10: =IFERROR(INDEX(Students!$A$3:$A$114,MATCH(1,INDEX((Students!$K$3:$K$114="5B")*(Students!$L$3:$L$114=8),0),0)),"") -> S-040 | C10: =IFERROR(INDEX(Students!$B$3:$B$114,MATCH(1,INDEX((Students!$K$3:$K$114="5B")*(Students!$L$3:$L$114=8),0),0)),"") -> 512 | D10: =IFERROR(INDEX(Students!$C$3:$C$114,MATCH(1,INDEX((Students!$K$3:$K$114="5B")*(Students!$L$3:$L$114=8),0),0)),"") -> Grade 4 | E10: =IFERROR(INDEX(Students!$D$3:$D$114,MATCH(1,INDEX((Students!$K$3:$K$114="5B")*(Students!$L$3:$L$114=8),0),0)),"") -> 451 | F10: =IFERROR(INDEX(Students!$E$3:$E$114,MATCH(1,INDEX((Students!$K$3:$K$114="5B")*(Students!$L$3:$L$114=8),0),0)),"") -> Grade 2
A11: 9 | B11: =IFERROR(INDEX(Students!$A$3:$A$114,MATCH(1,INDEX((Students!$K$3:$K$114="5B")*(Students!$L$3:$L$114=9),0),0)),"") -> S-043 | C11: =IFERROR(INDEX(Students!$B$3:$B$114,MATCH(1,INDEX((Students!$K$3:$K$114="5B")*(Students!$L$3:$L$114=9),0),0)),"") -> 539 | D11: =IFERROR(INDEX(Students!$C$3:$C$114,MATCH(1,INDEX((Students!$K$3:$K$114="5B")*(Students!$L$3:$L$114=9),0),0)),"") -> Grade 5 | E11: =IFERROR(INDEX(Students!$D$3:$D$114,MATCH(1,INDEX((Students!$K$3:$K$114="5B")*(Students!$L$3:$L$114=9),0),0)),"") -> 526 | F11: =IFERROR(INDEX(Students!$E$3:$E$114,MATCH(1,INDEX((Students!$K$3:$K$114="5B")*(Students!$L$3:$L$114=9),0),0)),"") -> Grade 4
A12: 10 | B12: =IFERROR(INDEX(Students!$A$3:$A$114,MATCH(1,INDEX((Students!$K$3:$K$114="5B")*(Students!$L$3:$L$114=10),0),0)),"") -> S-046 | C12: =IFERROR(INDEX(Students!$B$3:$B$114,MATCH(1,INDEX((Students!$K$3:$K$114="5B")*(Students!$L$3:$L$114=10),0),0)),"") -> 440 | D12: =IFERROR(INDEX(Students!$C$3:$C$114,MATCH(1,INDEX((Students!$K$3:$K$114="5B")*(Students!$L$3:$L$114=10),0),0)),"") -> Grade 2 | E12: =IFERROR(INDEX(Students!$D$3:$D$114,MATCH(1,INDEX((Students!$K$3:$K$114="5B")*(Students!$L$3:$L$114=10),0),0)),"") -> 395 | F12: =IFERROR(INDEX(Students!$E$3:$E$114,MATCH(1,INDEX((Students!$K$3:$K$114="5B")*(Students!$L$3:$L$114=10),0),0)),"") -> Grade 1
A13: 11 | B13: =IFERROR(INDEX(Students!$A$3:$A$114,MATCH(1,INDEX((Students!$K$3:$K$114="5B")*(Students!$L$3:$L$114=11),0),0)),"") -> S-054 | C13: =IFERROR(INDEX(Students!$B$3:$B$114,MATCH(1,INDEX((Students!$K$3:$K$114="5B")*(Students!$L$3:$L$114=11),0),0)),"") -> 524 | D13: =IFERROR(INDEX(Students!$C$3:$C$114,MATCH(1,INDEX((Students!$K$3:$K$114="5B")*(Students!$L$3:$L$114=11),0),0)),"") -> Grade 4 | E13: =IFERROR(INDEX(Students!$D$3:$D$114,MATCH(1,INDEX((Students!$K$3:$K$114="5B")*(Students!$L$3:$L$114=11),0),0)),"") -> 475 | F13: =IFERROR(INDEX(Students!$E$3:$E$114,MATCH(1,INDEX((Students!$K$3:$K$114="5B")*(Students!$L$3:$L$114=11),0),0)),"") -> Grade 3
A14: 12 | B14: =IFERROR(INDEX(Students!$A$3:$A$114,MATCH(1,INDEX((Students!$K$3:$K$114="5B")*(Students!$L$3:$L$114=12),0),0)),"") -> S-056 | C14: =IFERROR(INDEX(Students!$B$3:$B$114,MATCH(1,INDEX((Students!$K$3:$K$114="5B")*(Students!$L$3:$L$114=12),0),0)),"") -> 541 | D14: =IFERROR(INDEX(Students!$C$3:$C$114,MATCH(1,INDEX((Students!$K$3:$K$114="5B")*(Students!$L$3:$L$114=12),0),0)),"") -> Grade 5 | E14: =IFERROR(INDEX(Students!$D$3:$D$114,MATCH(1,INDEX((Students!$K$3:$K$114="5B")*(Students!$L$3:$L$114=12),0),0)),"") -> 501 | F14: =IFERROR(INDEX(Students!$E$3:$E$114,MATCH(1,INDEX((Students!$K$3:$K$114="5B")*(Students!$L$3:$L$114=12),0),0)),"") -> Grade 3
A15: 13 | B15: =IFERROR(INDEX(Students!$A$3:$A$114,MATCH(1,INDEX((Students!$K$3:$K$114="5B")*(Students!$L$3:$L$114=13),0),0)),"") -> S-063 | C15: =IFERROR(INDEX(Students!$B$3:$B$114,MATCH(1,INDEX((Students!$K$3:$K$114="5B")*(Students!$L$3:$L$114=13),0),0)),"") -> 550 | D15: =IFERROR(INDEX(Students!$C$3:$C$114,MATCH(1,INDEX((Students!$K$3:$K$114="5B")*(Students!$L$3:$L$114=13),0),0)),"") -> Grade 5 | E15: =IFERROR(INDEX(Students!$D$3:$D$114,MATCH(1,INDEX((Students!$K$3:$K$114="5B")*(Students!$L$3:$L$114=13),0),0)),"") -> 543 | F15: =IFERROR(INDEX(Students!$E$3:$E$114,MATCH(1,INDEX((Students!$K$3:$K$114="5B")*(Students!$L$3:$L$114=13),0),0)),"") -> Grade 5
A16: 14 | B16: =IFERROR(INDEX(Students!$A$3:$A$114,MATCH(1,INDEX((Students!$K$3:$K$114="5B")*(Students!$L$3:$L$114=14),0),0)),"") -> S-071 | C16: =IFERROR(INDEX(Students!$B$3:$B$114,MATCH(1,INDEX((Students!$K$3:$K$114="5B")*(Students!$L$3:$L$114=14),0),0)),"") -> 433 | D16: =IFERROR(INDEX(Students!$C$3:$C$114,MATCH(1,INDEX((Students!$K$3:$K$114="5B")*(Students!$L$3:$L$114=14),0),0)),"") -> Grade 2 | E16: =IFERROR(INDEX(Students!$D$3:$D$114,MATCH(1,INDEX((Students!$K$3:$K$114="5B")*(Students!$L$3:$L$114=14),0),0)),"") -> 540 | F16: =IFERROR(INDEX(Students!$E$3:$E$114,MATCH(1,INDEX((Students!$K$3:$K$114="5B")*(Students!$L$3:$L$114=14),0),0)),"") -> Grade 5
A17: 15 | B17: =IFERROR(INDEX(Students!$A$3:$A$114,MATCH(1,INDEX((Students!$K$3:$K$114="5B")*(Students!$L$3:$L$114=15),0),0)),"") -> S-076 | C17: =IFERROR(INDEX(Students!$B$3:$B$114,MATCH(1,INDEX((Students!$K$3:$K$114="5B")*(Students!$L$3:$L$114=15),0),0)),"") -> 519 | D17: =IFERROR(INDEX(Students!$C$3:$C$114,MATCH(1,INDEX((Students!$K$3:$K$114="5B")*(Students!$L$3:$L$114=15),0),0)),"") -> Grade 4 | E17: =IFERROR(INDEX(Students!$D$3:$D$114,MATCH(1,INDEX((Students!$K$3:$K$114="5B")*(Students!$L$3:$L$114=15),0),0)),"") -> 551 | F17: =IFERROR(INDEX(Students!$E$3:$E$114,MATCH(1,INDEX((Students!$K$3:$K$114="5B")*(Students!$L$3:$L$114=15),0),0)),"") -> Grade 5
A18: 16 | B18: =IFERROR(INDEX(Students!$A$3:$A$114,MATCH(1,INDEX((Students!$K$3:$K$114="5B")*(Students!$L$3:$L$114=16),0),0)),"") -> S-077 | C18: =IFERROR(INDEX(Students!$B$3:$B$114,MATCH(1,INDEX((Students!$K$3:$K$114="5B")*(Students!$L$3:$L$114=16),0),0)),"") -> 495 | D18: =IFERROR(INDEX(Students!$C$3:$C$114,MATCH(1,INDEX((Students!$K$3:$K$114="5B")*(Students!$L$3:$L$114=16),0),0)),"") -> Grade 3 | E18: =IFERROR(INDEX(Students!$D$3:$D$114,MATCH(1,INDEX((Students!$K$3:$K$114="5B")*(Students!$L$3:$L$114=16),0),0)),"") -> 558 | F18: =IFERROR(INDEX(Students!$E$3:$E$114,MATCH(1,INDEX((Students!$K$3:$K$114="5B")*(Students!$L$3:$L$114=16),0),0)),"") -> Grade 5
A19: 17 | B19: =IFERROR(INDEX(Students!$A$3:$A$114,MATCH(1,INDEX((Students!$K$3:$K$114="5B")*(Students!$L$3:$L$114=17),0),0)),"") -> S-080 | C19: =IFERROR(INDEX(Students!$B$3:$B$114,MATCH(1,INDEX((Students!$K$3:$K$114="5B")*(Students!$L$3:$L$114=17),0),0)),"") -> 410 | D19: =IFERROR(INDEX(Students!$C$3:$C$114,MATCH(1,INDEX((Students!$K$3:$K$114="5B")*(Students!$L$3:$L$114=17),0),0)),"") -> Grade 1 | E19: =IFERROR(INDEX(Students!$D$3:$D$114,MATCH(1,INDEX((Students!$K$3:$K$114="5B")*(Students!$L$3:$L$114=17),0),0)),"") -> 518 | F19: =IFERROR(INDEX(Students!$E$3:$E$114,MATCH(1,INDEX((Students!$K$3:$K$114="5B")*(Students!$L$3:$L$114=17),0),0)),"") -> Grade 4
A20: 18 | B20: =IFERROR(INDEX(Students!$A$3:$A$114,MATCH(1,INDEX((Students!$K$3:$K$114="5B")*(Students!$L$3:$L$114=18),0),0)),"") -> S-081 | C20: =IFERROR(INDEX(Students!$B$3:$B$114,MATCH(1,INDEX((Students!$K$3:$K$114="5B")*(Students!$L$3:$L$114=18),0),0)),"") -> 538 | D20: =IFERROR(INDEX(Students!$C$3:$C$114,MATCH(1,INDEX((Students!$K$3:$K$114="5B")*(Students!$L$3:$L$114=18),0),0)),"") -> Grade 5 | E20: =IFERROR(INDEX(Students!$D$3:$D$114,MATCH(1,INDEX((Students!$K$3:$K$114="5B")*(Students!$L$3:$L$114=18),0),0)),"") -> 549 | F20: =IFERROR(INDEX(Students!$E$3:$E$114,MATCH(1,INDEX((Students!$K$3:$K$114="5B")*(Students!$L$3:$L$114=18),0),0)),"") -> Grade 5
A21: 19 | B21: =IFERROR(INDEX(Students!$A$3:$A$114,MATCH(1,INDEX((Students!$K$3:$K$114="5B")*(Students!$L$3:$L$114=19),0),0)),"") -> S-087 | C21: =IFERROR(INDEX(Students!$B$3:$B$114,MATCH(1,INDEX((Students!$K$3:$K$114="5B")*(Students!$L$3:$L$114=19),0),0)),"") -> 417 | D21: =IFERROR(INDEX(Students!$C$3:$C$114,MATCH(1,INDEX((Students!$K$3:$K$114="5B")*(Students!$L$3:$L$114=19),0),0)),"") -> Grade 1 | E21: =IFERROR(INDEX(Students!$D$3:$D$114,MATCH(1,INDEX((Students!$K$3:$K$114="5B")*(Students!$L$3:$L$114=19),0),0)),"") -> 537 | F21: =IFERROR(INDEX(Students!$E$3:$E$114,MATCH(1,INDEX((Students!$K$3:$K$114="5B")*(Students!$L$3:$L$114=19),0),0)),"") -> Grade 4
A22: 20 | B22: =IFERROR(INDEX(Students!$A$3:$A$114,MATCH(1,INDEX((Students!$K$3:$K$114="5B")*(Students!$L$3:$L$114=20),0),0)),"") -> S-095 | C22: =IFERROR(INDEX(Students!$B$3:$B$114,MATCH(1,INDEX((Students!$K$3:$K$114="5B")*(Students!$L$3:$L$114=20),0),0)),"") -> 507 | D22: =IFERROR(INDEX(Students!$C$3:$C$114,MATCH(1,INDEX((Students!$K$3:$K$114="5B")*(Students!$L$3:$L$114=20),0),0)),"") -> Grade 4 | E22: =IFERROR(INDEX(Students!$D$3:$D$114,MATCH(1,INDEX((Students!$K$3:$K$114="5B")*(Students!$L$3:$L$114=20),0),0)),"") -> 440 | F22: =IFERROR(INDEX(Students!$E$3:$E$114,MATCH(1,INDEX((Students!$K$3:$K$114="5B")*(Students!$L$3:$L$114=20),0),0)),"") -> Grade 2
A23: 21 | B23: =IFERROR(INDEX(Students!$A$3:$A$114,MATCH(1,INDEX((Students!$K$3:$K$114="5B")*(Students!$L$3:$L$114=21),0),0)),"") -> S-096 | C23: =IFERROR(INDEX(Students!$B$3:$B$114,MATCH(1,INDEX((Students!$K$3:$K$114="5B")*(Students!$L$3:$L$114=21),0),0)),"") -> 473 | D23: =IFERROR(INDEX(Students!$C$3:$C$114,MATCH(1,INDEX((Students!$K$3:$K$114="5B")*(Students!$L$3:$L$114=21),0),0)),"") -> Grade 3 | E23: =IFERROR(INDEX(Students!$D$3:$D$114,MATCH(1,INDEX((Students!$K$3:$K$114="5B")*(Students!$L$3:$L$114=21),0),0)),"") -> 427 | F23: =IFERROR(INDEX(Students!$E$3:$E$114,MATCH(1,INDEX((Students!$K$3:$K$114="5B")*(Students!$L$3:$L$114=21),0),0)),"") -> Grade 1
A24: 22 | B24: =IFERROR(INDEX(Students!$A$3:$A$114,MATCH(1,INDEX((Students!$K$3:$K$114="5B")*(Students!$L$3:$L$114=22),0),0)),"") -> S-097 | C24: =IFERROR(INDEX(Students!$B$3:$B$114,MATCH(1,INDEX((Students!$K$3:$K$114="5B")*(Students!$L$3:$L$114=22),0),0)),"") -> 537 | D24: =IFERROR(INDEX(Students!$C$3:$C$114,MATCH(1,INDEX((Students!$K$3:$K$114="5B")*(Students!$L$3:$L$114=22),0),0)),"") -> Grade 5 | E24: =IFERROR(INDEX(Students!$D$3:$D$114,MATCH(1,INDEX((Students!$K$3:$K$114="5B")*(Students!$L$3:$L$114=22),0),0)),"") -> 570 | F24: =IFERROR(INDEX(Students!$E$3:$E$114,MATCH(1,INDEX((Students!$K$3:$K$114="5B")*(Students!$L$3:$L$114=22),0),0)),"") -> Grade 5
A25: 23 | B25: =IFERROR(INDEX(Students!$A$3:$A$114,MATCH(1,INDEX((Students!$K$3:$K$114="5B")*(Students!$L$3:$L$114=23),0),0)),"") -> S-100 | C25: =IFERROR(INDEX(Students!$B$3:$B$114,MATCH(1,INDEX((Students!$K$3:$K$114="5B")*(Students!$L$3:$L$114=23),0),0)),"") -> 526 | D25: =IFERROR(INDEX(Students!$C$3:$C$114,MATCH(1,INDEX((Students!$K$3:$K$114="5B")*(Students!$L$3:$L$114=23),0),0)),"") -> Grade 4 | E25: =IFERROR(INDEX(Students!$D$3:$D$114,MATCH(1,INDEX((Students!$K$3:$K$114="5B")*(Students!$L$3:$L$114=23),0),0)),"") -> 465 | F25: =IFERROR(INDEX(Students!$E$3:$E$114,MATCH(1,INDEX((Students!$K$3:$K$114="5B")*(Students!$L$3:$L$114=23),0),0)),"") -> Grade 3
A26: 24 | B26: =IFERROR(INDEX(Students!$A$3:$A$114,MATCH(1,INDEX((Students!$K$3:$K$114="5B")*(Students!$L$3:$L$114=24),0),0)),"") -> S-101 | C26: =IFERROR(INDEX(Students!$B$3:$B$114,MATCH(1,INDEX((Students!$K$3:$K$114="5B")*(Students!$L$3:$L$114=24),0),0)),"") -> 489 | D26: =IFERROR(INDEX(Students!$C$3:$C$114,MATCH(1,INDEX((Students!$K$3:$K$114="5B")*(Students!$L$3:$L$114=24),0),0)),"") -> Grade 3 | E26: =IFERROR(INDEX(Students!$D$3:$D$114,MATCH(1,INDEX((Students!$K$3:$K$114="5B")*(Students!$L$3:$L$114=24),0),0)),"") -> 550 | F26: =IFERROR(INDEX(Students!$E$3:$E$114,MATCH(1,INDEX((Students!$K$3:$K$114="5B")*(Students!$L$3:$L$114=24),0),0)),"") -> Grade 5
A27: 25 | B27: =IFERROR(INDEX(Students!$A$3:$A$114,MATCH(1,INDEX((Students!$K$3:$K$114="5B")*(Students!$L$3:$L$114=25),0),0)),"") -> S-103 | C27: =IFERROR(INDEX(Students!$B$3:$B$114,MATCH(1,INDEX((Students!$K$3:$K$114="5B")*(Students!$L$3:$L$114=25),0),0)),"") -> 469 | D27: =IFERROR(INDEX(Students!$C$3:$C$114,MATCH(1,INDEX((Students!$K$3:$K$114="5B")*(Students!$L$3:$L$114=25),0),0)),"") -> Grade 2 | E27: =IFERROR(INDEX(Students!$D$3:$D$114,MATCH(1,INDEX((Students!$K$3:$K$114="5B")*(Students!$L$3:$L$114=25),0),0)),"") -> 558 | F27: =IFERROR(INDEX(Students!$E$3:$E$114,MATCH(1,INDEX((Students!$K$3:$K$114="5B")*(Students!$L$3:$L$114=25),0),0)),"") -> Grade 5
A28: 26 | B28: =IFERROR(INDEX(Students!$A$3:$A$114,MATCH(1,INDEX((Students!$K$3:$K$114="5B")*(Students!$L$3:$L$114=26),0),0)),"") -> S-104 | C28: =IFERROR(INDEX(Students!$B$3:$B$114,MATCH(1,INDEX((Students!$K$3:$K$114="5B")*(Students!$L$3:$L$114=26),0),0)),"") -> 501 | D28: =IFERROR(INDEX(Students!$C$3:$C$114,MATCH(1,INDEX((Students!$K$3:$K$114="5B")*(Students!$L$3:$L$114=26),0),0)),"") -> Grade 4 | E28: =IFERROR(INDEX(Students!$D$3:$D$114,MATCH(1,INDEX((Students!$K$3:$K$114="5B")*(Students!$L$3:$L$114=26),0),0)),"") -> 452 | F28: =IFERROR(INDEX(Students!$E$3:$E$114,MATCH(1,INDEX((Students!$K$3:$K$114="5B")*(Students!$L$3:$L$114=26),0),0)),"") -> Grade 2
A29: 27 | B29: =IFERROR(INDEX(Students!$A$3:$A$114,MATCH(1,INDEX((Students!$K$3:$K$114="5B")*(Students!$L$3:$L$114=27),0),0)),"") -> S-108 | C29: =IFERROR(INDEX(Students!$B$3:$B$114,MATCH(1,INDEX((Students!$K$3:$K$114="5B")*(Students!$L$3:$L$114=27),0),0)),"") -> 513 | D29: =IFERROR(INDEX(Students!$C$3:$C$114,MATCH(1,INDEX((Students!$K$3:$K$114="5B")*(Students!$L$3:$L$114=27),0),0)),"") -> Grade 4 | E29: =IFERROR(INDEX(Students!$D$3:$D$114,MATCH(1,INDEX((Students!$K$3:$K$114="5B")*(Students!$L$3:$L$114=27),0),0)),"") -> 521 | F29: =IFERROR(INDEX(Students!$E$3:$E$114,MATCH(1,INDEX((Students!$K$3:$K$114="5B")*(Students!$L$3:$L$114=27),0),0)),"") -> Grade 4
A30: 28 | B30: =IFERROR(INDEX(Students!$A$3:$A$114,MATCH(1,INDEX((Students!$K$3:$K$114="5B")*(Students!$L$3:$L$114=28),0),0)),"") -> S-112 | C30: =IFERROR(INDEX(Students!$B$3:$B$114,MATCH(1,INDEX((Students!$K$3:$K$114="5B")*(Students!$L$3:$L$114=28),0),0)),"") -> 470 | D30: =IFERROR(INDEX(Students!$C$3:$C$114,MATCH(1,INDEX((Students!$K$3:$K$114="5B")*(Students!$L$3:$L$114=28),0),0)),"") -> Grade 3 | E30: =IFERROR(INDEX(Students!$D$3:$D$114,MATCH(1,INDEX((Students!$K$3:$K$114="5B")*(Students!$L$3:$L$114=28),0),0)),"") -> 564 | F30: =IFERROR(INDEX(Students!$E$3:$E$114,MATCH(1,INDEX((Students!$K$3:$K$114="5B")*(Students!$L$3:$L$114=28),0),0)),"") -> Grade 5
A31: 29 | B31: =IFERROR(INDEX(Students!$A$3:$A$114,MATCH(1,INDEX((Students!$K$3:$K$114="5B")*(Students!$L$3:$L$114=29),0),0)),"") | C31: =IFERROR(INDEX(Students!$B$3:$B$114,MATCH(1,INDEX((Students!$K$3:$K$114="5B")*(Students!$L$3:$L$114=29),0),0)),"") | D31: =IFERROR(INDEX(Students!$C$3:$C$114,MATCH(1,INDEX((Students!$K$3:$K$114="5B")*(Students!$L$3:$L$114=29),0),0)),"") | E31: =IFERROR(INDEX(Students!$D$3:$D$114,MATCH(1,INDEX((Students!$K$3:$K$114="5B")*(Students!$L$3:$L$114=29),0),0)),"") | F31: =IFERROR(INDEX(Students!$E$3:$E$114,MATCH(1,INDEX((Students!$K$3:$K$114="5B")*(Students!$L$3:$L$114=29),0),0)),"")
A32: 30 | B32: =IFERROR(INDEX(Students!$A$3:$A$114,MATCH(1,INDEX((Students!$K$3:$K$114="5B")*(Students!$L$3:$L$114=30),0),0)),"") | C32: =IFERROR(INDEX(Students!$B$3:$B$114,MATCH(1,INDEX((Students!$K$3:$K$114="5B")*(Students!$L$3:$L$114=30),0),0)),"") | D32: =IFERROR(INDEX(Students!$C$3:$C$114,MATCH(1,INDEX((Students!$K$3:$K$114="5B")*(Students!$L$3:$L$114=30),0),0)),"") | E32: =IFERROR(INDEX(Students!$D$3:$D$114,MATCH(1,INDEX((Students!$K$3:$K$114="5B")*(Students!$L$3:$L$114=30),0),0)),"") | F32: =IFERROR(INDEX(Students!$E$3:$E$114,MATCH(1,INDEX((Students!$K$3:$K$114="5B")*(Students!$L$3:$L$114=30),0),0)),"")
A33: 31 | B33: =IFERROR(INDEX(Students!$A$3:$A$114,MATCH(1,INDEX((Students!$K$3:$K$114="5B")*(Students!$L$3:$L$114=31),0),0)),"") | C33: =IFERROR(INDEX(Students!$B$3:$B$114,MATCH(1,INDEX((Students!$K$3:$K$114="5B")*(Students!$L$3:$L$114=31),0),0)),"") | D33: =IFERROR(INDEX(Students!$C$3:$C$114,MATCH(1,INDEX((Students!$K$3:$K$114="5B")*(Students!$L$3:$L$114=31),0),0)),"") | E33: =IFERROR(INDEX(Students!$D$3:$D$114,MATCH(1,INDEX((Students!$K$3:$K$114="5B")*(Students!$L$3:$L$114=31),0),0)),"") | F33: =IFERROR(INDEX(Students!$E$3:$E$114,MATCH(1,INDEX((Students!$K$3:$K$114="5B")*(Students!$L$3:$L$114=31),0),0)),"")
A34: 32 | B34: =IFERROR(INDEX(Students!$A$3:$A$114,MATCH(1,INDEX((Students!$K$3:$K$114="5B")*(Students!$L$3:$L$114=32),0),0)),"") | C34: =IFERROR(INDEX(Students!$B$3:$B$114,MATCH(1,INDEX((Students!$K$3:$K$114="5B")*(Students!$L$3:$L$114=32),0),0)),"") | D34: =IFERROR(INDEX(Students!$C$3:$C$114,MATCH(1,INDEX((Students!$K$3:$K$114="5B")*(Students!$L$3:$L$114=32),0),0)),"") | E34: =IFERROR(INDEX(Students!$D$3:$D$114,MATCH(1,INDEX((Students!$K$3:$K$114="5B")*(Students!$L$3:$L$114=32),0),0)),"") | F34: =IFERROR(INDEX(Students!$E$3:$E$114,MATCH(1,INDEX((Students!$K$3:$K$114="5B")*(Students!$L$3:$L$114=32),0),0)),"")
A35: 33 | B35: =IFERROR(INDEX(Students!$A$3:$A$114,MATCH(1,INDEX((Students!$K$3:$K$114="5B")*(Students!$L$3:$L$114=33),0),0)),"") | C35: =IFERROR(INDEX(Students!$B$3:$B$114,MATCH(1,INDEX((Students!$K$3:$K$114="5B")*(Students!$L$3:$L$114=33),0),0)),"") | D35: =IFERROR(INDEX(Students!$C$3:$C$114,MATCH(1,INDEX((Students!$K$3:$K$114="5B")*(Students!$L$3:$L$114=33),0),0)),"") | E35: =IFERROR(INDEX(Students!$D$3:$D$114,MATCH(1,INDEX((Students!$K$3:$K$114="5B")*(Students!$L$3:$L$114=33),0),0)),"") | F35: =IFERROR(INDEX(Students!$E$3:$E$114,MATCH(1,INDEX((Students!$K$3:$K$114="5B")*(Students!$L$3:$L$114=33),0),0)),"")
A36: 34 | B36: =IFERROR(INDEX(Students!$A$3:$A$114,MATCH(1,INDEX((Students!$K$3:$K$114="5B")*(Students!$L$3:$L$114=34),0),0)),"") | C36: =IFERROR(INDEX(Students!$B$3:$B$114,MATCH(1,INDEX((Students!$K$3:$K$114="5B")*(Students!$L$3:$L$114=34),0),0)),"") | D36: =IFERROR(INDEX(Students!$C$3:$C$114,MATCH(1,INDEX((Students!$K$3:$K$114="5B")*(Students!$L$3:$L$114=34),0),0)),"") | E36: =IFERROR(INDEX(Students!$D$3:$D$114,MATCH(1,INDEX((Students!$K$3:$K$114="5B")*(Students!$L$3:$L$114=34),0),0)),"") | F36: =IFERROR(INDEX(Students!$E$3:$E$114,MATCH(1,INDEX((Students!$K$3:$K$114="5B")*(Students!$L$3:$L$114=34),0),0)),"")
A37: 35 | B37: =IFERROR(INDEX(Students!$A$3:$A$114,MATCH(1,INDEX((Students!$K$3:$K$114="5B")*(Students!$L$3:$L$114=35),0),0)),"") | C37: =IFERROR(INDEX(Students!$B$3:$B$114,MATCH(1,INDEX((Students!$K$3:$K$114="5B")*(Students!$L$3:$L$114=35),0),0)),"") | D37: =IFERROR(INDEX(Students!$C$3:$C$114,MATCH(1,INDEX((Students!$K$3:$K$114="5B")*(Students!$L$3:$L$114=35),0),0)),"") | E37: =IFERROR(INDEX(Students!$D$3:$D$114,MATCH(1,INDEX((Students!$K$3:$K$114="5B")*(Students!$L$3:$L$114=35),0),0)),"") | F37: =IFERROR(INDEX(Students!$E$3:$E$114,MATCH(1,INDEX((Students!$K$3:$K$114="5B")*(Students!$L$3:$L$114=35),0),0)),"")

Sheet 5C
A1: Cohort 5C
A2: # | B2: Student ID | C2: Reading Score | D2: Reading Placement | E2: Math Score | F2: Math Placement
A3: 1 | B3: =IFERROR(INDEX(Students!$A$3:$A$114,MATCH(1,INDEX((Students!$K$3:$K$114="5C")*(Students!$L$3:$L$114=1),0),0)),"") -> S-004 | C3: =IFERROR(INDEX(Students!$B$3:$B$114,MATCH(1,INDEX((Students!$K$3:$K$114="5C")*(Students!$L$3:$L$114=1),0),0)),"") -> 548 | D3: =IFERROR(INDEX(Students!$C$3:$C$114,MATCH(1,INDEX((Students!$K$3:$K$114="5C")*(Students!$L$3:$L$114=1),0),0)),"") -> Grade 5 | E3: =IFERROR(INDEX(Students!$D$3:$D$114,MATCH(1,INDEX((Students!$K$3:$K$114="5C")*(Students!$L$3:$L$114=1),0),0)),"") -> 535 | F3: =IFERROR(INDEX(Students!$E$3:$E$114,MATCH(1,INDEX((Students!$K$3:$K$114="5C")*(Students!$L$3:$L$114=1),0),0)),"") -> Grade 4
A4: 2 | B4: =IFERROR(INDEX(Students!$A$3:$A$114,MATCH(1,INDEX((Students!$K$3:$K$114="5C")*(Students!$L$3:$L$114=2),0),0)),"") -> S-005 | C4: =IFERROR(INDEX(Students!$B$3:$B$114,MATCH(1,INDEX((Students!$K$3:$K$114="5C")*(Students!$L$3:$L$114=2),0),0)),"") -> 454 | D4: =IFERROR(INDEX(Students!$C$3:$C$114,MATCH(1,INDEX((Students!$K$3:$K$114="5C")*(Students!$L$3:$L$114=2),0),0)),"") -> Grade 2 | E4: =IFERROR(INDEX(Students!$D$3:$D$114,MATCH(1,INDEX((Students!$K$3:$K$114="5C")*(Students!$L$3:$L$114=2),0),0)),"") -> 568 | F4: =IFERROR(INDEX(Students!$E$3:$E$114,MATCH(1,INDEX((Students!$K$3:$K$114="5C")*(Students!$L$3:$L$114=2),0),0)),"") -> Grade 5
A5: 3 | B5: =IFERROR(INDEX(Students!$A$3:$A$114,MATCH(1,INDEX((Students!$K$3:$K$114="5C")*(Students!$L$3:$L$114=3),0),0)),"") -> S-013 | C5: =IFERROR(INDEX(Students!$B$3:$B$114,MATCH(1,INDEX((Students!$K$3:$K$114="5C")*(Students!$L$3:$L$114=3),0),0)),"") -> 572 | D5: =IFERROR(INDEX(Students!$C$3:$C$114,MATCH(1,INDEX((Students!$K$3:$K$114="5C")*(Students!$L$3:$L$114=3),0),0)),"") -> Grade 5 | E5: =IFERROR(INDEX(Students!$D$3:$D$114,MATCH(1,INDEX((Students!$K$3:$K$114="5C")*(Students!$L$3:$L$114=3),0),0)),"") -> 546 | F5: =IFERROR(INDEX(Students!$E$3:$E$114,MATCH(1,INDEX((Students!$K$3:$K$114="5C")*(Students!$L$3:$L$114=3),0),0)),"") -> Grade 5
A6: 4 | B6: =IFERROR(INDEX(Students!$A$3:$A$114,MATCH(1,INDEX((Students!$K$3:$K$114="5C")*(Students!$L$3:$L$114=4),0),0)),"") -> S-014 | C6: =IFERROR(INDEX(Students!$B$3:$B$114,MATCH(1,INDEX((Students!$K$3:$K$114="5C")*(Students!$L$3:$L$114=4),0),0)),"") -> 442 | D6: =IFERROR(INDEX(Students!$C$3:$C$114,MATCH(1,INDEX((Students!$K$3:$K$114="5C")*(Students!$L$3:$L$114=4),0),0)),"") -> Grade 2 | E6: =IFERROR(INDEX(Students!$D$3:$D$114,MATCH(1,INDEX((Students!$K$3:$K$114="5C")*(Students!$L$3:$L$114=4),0),0)),"") -> 414 | F6: =IFERROR(INDEX(Students!$E$3:$E$114,MATCH(1,INDEX((Students!$K$3:$K$114="5C")*(Students!$L$3:$L$114=4),0),0)),"") -> Grade 1
A7: 5 | B7: =IFERROR(INDEX(Students!$A$3:$A$114,MATCH(1,INDEX((Students!$K$3:$K$114="5C")*(Students!$L$3:$L$114=5),0),0)),"") -> S-016 | C7: =IFERROR(INDEX(Students!$B$3:$B$114,MATCH(1,INDEX((Students!$K$3:$K$114="5C")*(Students!$L$3:$L$114=5),0),0)),"") -> 522 | D7: =IFERROR(INDEX(Students!$C$3:$C$114,MATCH(1,INDEX((Students!$K$3:$K$114="5C")*(Students!$L$3:$L$114=5),0),0)),"") -> Grade 4 | E7: =IFERROR(INDEX(Students!$D$3:$D$114,MATCH(1,INDEX((Students!$K$3:$K$114="5C")*(Students!$L$3:$L$114=5),0),0)),"") -> 483 | F7: =IFERROR(INDEX(Students!$E$3:$E$114,MATCH(1,INDEX((Students!$K$3:$K$114="5C")*(Students!$L$3:$L$114=5),0),0)),"") -> Grade 3
A8: 6 | B8: =IFERROR(INDEX(Students!$A$3:$A$114,MATCH(1,INDEX((Students!$K$3:$K$114="5C")*(Students!$L$3:$L$114=6),0),0)),"") -> S-018 | C8: =IFERROR(INDEX(Students!$B$3:$B$114,MATCH(1,INDEX((Students!$K$3:$K$114="5C")*(Students!$L$3:$L$114=6),0),0)),"") -> 467 | D8: =IFERROR(INDEX(Students!$C$3:$C$114,MATCH(1,INDEX((Students!$K$3:$K$114="5C")*(Students!$L$3:$L$114=6),0),0)),"") -> Grade 3 | E8: =IFERROR(INDEX(Students!$D$3:$D$114,MATCH(1,INDEX((Students!$K$3:$K$114="5C")*(Students!$L$3:$L$114=6),0),0)),"") -> 574 | F8: =IFERROR(INDEX(Students!$E$3:$E$114,MATCH(1,INDEX((Students!$K$3:$K$114="5C")*(Students!$L$3:$L$114=6),0),0)),"") -> Grade 5
A9: 7 | B9: =IFERROR(INDEX(Students!$A$3:$A$114,MATCH(1,INDEX((Students!$K$3:$K$114="5C")*(Students!$L$3:$L$114=7),0),0)),"") -> S-024 | C9: =IFERROR(INDEX(Students!$B$3:$B$114,MATCH(1,INDEX((Students!$K$3:$K$114="5C")*(Students!$L$3:$L$114=7),0),0)),"") -> 411 | D9: =IFERROR(INDEX(Students!$C$3:$C$114,MATCH(1,INDEX((Students!$K$3:$K$114="5C")*(Students!$L$3:$L$114=7),0),0)),"") -> Grade 1 | E9: =IFERROR(INDEX(Students!$D$3:$D$114,MATCH(1,INDEX((Students!$K$3:$K$114="5C")*(Students!$L$3:$L$114=7),0),0)),"") -> 524 | F9: =IFERROR(INDEX(Students!$E$3:$E$114,MATCH(1,INDEX((Students!$K$3:$K$114="5C")*(Students!$L$3:$L$114=7),0),0)),"") -> Grade 4
A10: 8 | B10: =IFERROR(INDEX(Students!$A$3:$A$114,MATCH(1,INDEX((Students!$K$3:$K$114="5C")*(Students!$L$3:$L$114=8),0),0)),"") -> S-031 | C10: =IFERROR(INDEX(Students!$B$3:$B$114,MATCH(1,INDEX((Students!$K$3:$K$114="5C")*(Students!$L$3:$L$114=8),0),0)),"") -> 457 | D10: =IFERROR(INDEX(Students!$C$3:$C$114,MATCH(1,INDEX((Students!$K$3:$K$114="5C")*(Students!$L$3:$L$114=8),0),0)),"") -> Grade 2 | E10: =IFERROR(INDEX(Students!$D$3:$D$114,MATCH(1,INDEX((Students!$K$3:$K$114="5C")*(Students!$L$3:$L$114=8),0),0)),"") -> 551 | F10: =IFERROR(INDEX(Students!$E$3:$E$114,MATCH(1,INDEX((Students!$K$3:$K$114="5C")*(Students!$L$3:$L$114=8),0),0)),"") -> Grade 5
A11: 9 | B11: =IFERROR(INDEX(Students!$A$3:$A$114,MATCH(1,INDEX((Students!$K$3:$K$114="5C")*(Students!$L$3:$L$114=9),0),0)),"") -> S-033 | C11: =IFERROR(INDEX(Students!$B$3:$B$114,MATCH(1,INDEX((Students!$K$3:$K$114="5C")*(Students!$L$3:$L$114=9),0),0)),"") -> 468 | D11: =IFERROR(INDEX(Students!$C$3:$C$114,MATCH(1,INDEX((Students!$K$3:$K$114="5C")*(Students!$L$3:$L$114=9),0),0)),"") -> Grade 2 | E11: =IFERROR(INDEX(Students!$D$3:$D$114,MATCH(1,INDEX((Students!$K$3:$K$114="5C")*(Students!$L$3:$L$114=9),0),0)),"") -> 526 | F11: =IFERROR(INDEX(Students!$E$3:$E$114,MATCH(1,INDEX((Students!$K$3:$K$114="5C")*(Students!$L$3:$L$114=9),0),0)),"") -> Grade 4
