Workbook

Sheet Roster
A1: Sample roster tracker. All families and dates are fictional. Edit the blue columns; Status and Follow-up # are formulas.
A2: Family ID | B2: Testing Week | C2: Preferred Language | D2: Confirmed Date | E2: Confirmation Email Sent | F2: Contact Method | G2: Notes | H2: Status | I2: Follow-up #
A3: F-001 | B3: Week 3 | C3: English | D3: 46223 | E3: Yes | F3: Email | G3: Confirmed by email | H3: =IF(D3<>"","Confirmed","Follow up") -> Confirmed | I3: =IF(H3="Follow up",COUNTIF($H$3:H3,"Follow up"),"")
A4: F-002 | B4: Week 2 | C4: Spanish | D4: 46217 | E4: Yes | F4: Email | G4: Prefers morning slot | H4: =IF(D4<>"","Confirmed","Follow up") -> Confirmed | I4: =IF(H4="Follow up",COUNTIF($H$3:H4,"Follow up"),"")
A5: F-003 | B5: Week 1 | C5: English | D5: 46212 | E5: Yes | F5: Email | G5: Sibling testing same day | H5: =IF(D5<>"","Confirmed","Follow up") -> Confirmed | I5: =IF(H5="Follow up",COUNTIF($H$3:H5,"Follow up"),"")
A6: F-004 | B6: Week 3 | C6: English | D6: 46223 | E6: Yes | F6: Phone | H6: =IF(D6<>"","Confirmed","Follow up") -> Confirmed | I6: =IF(H6="Follow up",COUNTIF($H$3:H6,"Follow up"),"")
A7: F-005 | B7: Week 1 | C7: English | E7: Yes | F7: Phone | G7: Left voicemail | H7: =IF(D7<>"","Confirmed","Follow up") -> Follow up | I7: =IF(H7="Follow up",COUNTIF($H$3:H7,"Follow up"),"") -> 1
A8: F-006 | B8: Week 1 | C8: English | E8: No | F8: Phone | G8: Email bounced, calling | H8: =IF(D8<>"","Confirmed","Follow up") -> Follow up | I8: =IF(H8="Follow up",COUNTIF($H$3:H8,"Follow up"),"") -> 2
A9: F-007 | B9: Week 3 | C9: English | D9: 46226 | E9: Yes | F9: Phone | G9: Prefers morning slot | H9: =IF(D9<>"","Confirmed","Follow up") -> Confirmed | I9: =IF(H9="Follow up",COUNTIF($H$3:H9,"Follow up"),"")
A10: F-008 | B10: Week 1 | C10: Spanish | D10: 46210 | E10: Yes | F10: Email | H10: =IF(D10<>"","Confirmed","Follow up") -> Confirmed | I10: =IF(H10="Follow up",COUNTIF($H$3:H10,"Follow up"),"")
A11: F-009 | B11: Week 3 | C11: Spanish | D11: 46223 | E11: Yes | F11: Phone | H11: =IF(D11<>"","Confirmed","Follow up") -> Confirmed | I11: =IF(H11="Follow up",COUNTIF($H$3:H11,"Follow up"),"")
A12: F-010 | B12: Week 2 | C12: English | D12: 46217 | E12: Yes | F12: Email | H12: =IF(D12<>"","Confirmed","Follow up") -> Confirmed | I12: =IF(H12="Follow up",COUNTIF($H$3:H12,"Follow up"),"")
A13: F-011 | B13: Week 2 | C13: English | D13: 46217 | E13: Yes | F13: Email | G13: Confirmed by email | H13: =IF(D13<>"","Confirmed","Follow up") -> Confirmed | I13: =IF(H13="Follow up",COUNTIF($H$3:H13,"Follow up"),"")
A14: F-012 | B14: Week 3 | C14: Spanish | D14: 46225 | E14: Yes | F14: Email | G14: Sibling testing same day | H14: =IF(D14<>"","Confirmed","Follow up") -> Confirmed | I14: =IF(H14="Follow up",COUNTIF($H$3:H14,"Follow up"),"")
A15: F-013 | B15: Week 1 | C15: Portuguese | D15: 46209 | E15: Yes | F15: Phone | G15: Prefers morning slot | H15: =IF(D15<>"","Confirmed","Follow up") -> Confirmed | I15: =IF(H15="Follow up",COUNTIF($H$3:H15,"Follow up"),"")
A16: F-014 | B16: Week 2 | C16: Spanish | D16: 46219 | E16: Yes | F16: Phone | H16: =IF(D16<>"","Confirmed","Follow up") -> Confirmed | I16: =IF(H16="Follow up",COUNTIF($H$3:H16,"Follow up"),"")
A17: F-015 | B17: Week 3 | C17: English | D17: 46224 | E17: Yes | F17: Phone | H17: =IF(D17<>"","Confirmed","Follow up") -> Confirmed | I17: =IF(H17="Follow up",COUNTIF($H$3:H17,"Follow up"),"")
A18: F-016 | B18: Week 2 | C18: English | D18: 46217 | E18: Yes | F18: Phone | H18: =IF(D18<>"","Confirmed","Follow up") -> Confirmed | I18: =IF(H18="Follow up",COUNTIF($H$3:H18,"Follow up"),"")
A19: F-017 | B19: Week 1 | C19: English | D19: 46210 | E19: Yes | F19: Email | H19: =IF(D19<>"","Confirmed","Follow up") -> Confirmed | I19: =IF(H19="Follow up",COUNTIF($H$3:H19,"Follow up"),"")
A20: F-018 | B20: Week 3 | C20: English | D20: 46223 | E20: Yes | F20: Phone | H20: =IF(D20<>"","Confirmed","Follow up") -> Confirmed | I20: =IF(H20="Follow up",COUNTIF($H$3:H20,"Follow up"),"")
A21: F-019 | B21: Week 2 | C21: Spanish | D21: 46219 | E21: Yes | F21: Email | H21: =IF(D21<>"","Confirmed","Follow up") -> Confirmed | I21: =IF(H21="Follow up",COUNTIF($H$3:H21,"Follow up"),"")
A22: F-020 | B22: Week 1 | C22: Spanish | D22: 46210 | E22: Yes | F22: Email | H22: =IF(D22<>"","Confirmed","Follow up") -> Confirmed | I22: =IF(H22="Follow up",COUNTIF($H$3:H22,"Follow up"),"")
A23: F-021 | B23: Week 1 | C23: Spanish | D23: 46212 | E23: Yes | F23: Phone | H23: =IF(D23<>"","Confirmed","Follow up") -> Confirmed | I23: =IF(H23="Follow up",COUNTIF($H$3:H23,"Follow up"),"")
A24: F-022 | B24: Week 1 | C24: English | D24: 46212 | E24: Yes | F24: Email | G24: Confirmed by email | H24: =IF(D24<>"","Confirmed","Follow up") -> Confirmed | I24: =IF(H24="Follow up",COUNTIF($H$3:H24,"Follow up"),"")
A25: F-023 | B25: Week 3 | C25: Spanish | D25: 46225 | E25: Yes | F25: Email | H25: =IF(D25<>"","Confirmed","Follow up") -> Confirmed | I25: =IF(H25="Follow up",COUNTIF($H$3:H25,"Follow up"),"")
A26: F-024 | B26: Week 3 | C26: English | D26: 46224 | E26: Yes | F26: Phone | G26: Confirmed by phone | H26: =IF(D26<>"","Confirmed","Follow up") -> Confirmed | I26: =IF(H26="Follow up",COUNTIF($H$3:H26,"Follow up"),"")
A27: F-025 | B27: Week 3 | C27: English | D27: 46224 | E27: Yes | F27: Email | H27: =IF(D27<>"","Confirmed","Follow up") -> Confirmed | I27: =IF(H27="Follow up",COUNTIF($H$3:H27,"Follow up"),"")
A28: F-026 | B28: Week 2 | C28: English | D28: 46216 | E28: Yes | F28: Email | H28: =IF(D28<>"","Confirmed","Follow up") -> Confirmed | I28: =IF(H28="Follow up",COUNTIF($H$3:H28,"Follow up"),"")
A29: F-027 | B29: Week 2 | C29: English | D29: 46216 | E29: Yes | F29: Phone | G29: Confirmed by email | H29: =IF(D29<>"","Confirmed","Follow up") -> Confirmed | I29: =IF(H29="Follow up",COUNTIF($H$3:H29,"Follow up"),"")
A30: F-028 | B30: Week 2 | C30: Portuguese | E30: Yes | F30: Phone | G30: Email bounced, calling | H30: =IF(D30<>"","Confirmed","Follow up") -> Follow up | I30: =IF(H30="Follow up",COUNTIF($H$3:H30,"Follow up"),"") -> 3
A31: F-029 | B31: Week 3 | C31: English | D31: 46225 | E31: Yes | F31: Email | H31: =IF(D31<>"","Confirmed","Follow up") -> Confirmed | I31: =IF(H31="Follow up",COUNTIF($H$3:H31,"Follow up"),"")
A32: F-030 | B32: Week 3 | C32: Arabic | D32: 46225 | E32: Yes | F32: Email | G32: Confirmed by phone | H32: =IF(D32<>"","Confirmed","Follow up") -> Confirmed | I32: =IF(H32="Follow up",COUNTIF($H$3:H32,"Follow up"),"")
A33: F-031 | B33: Week 1 | C33: English | D33: 46212 | E33: Yes | F33: Email | H33: =IF(D33<>"","Confirmed","Follow up") -> Confirmed | I33: =IF(H33="Follow up",COUNTIF($H$3:H33,"Follow up"),"")
A34: F-032 | B34: Week 2 | C34: English | D34: 46219 | E34: Yes | F34: Email | G34: Confirmed by email | H34: =IF(D34<>"","Confirmed","Follow up") -> Confirmed | I34: =IF(H34="Follow up",COUNTIF($H$3:H34,"Follow up"),"")
A35: F-033 | B35: Week 1 | C35: Spanish | D35: 46212 | E35: Yes | F35: Phone | G35: Sibling testing same day | H35: =IF(D35<>"","Confirmed","Follow up") -> Confirmed | I35: =IF(H35="Follow up",COUNTIF($H$3:H35,"Follow up"),"")
A36: F-034 | B36: Week 2 | C36: Spanish | D36: 46219 | E36: Yes | F36: Email | G36: Prefers morning slot | H36: =IF(D36<>"","Confirmed","Follow up") -> Confirmed | I36: =IF(H36="Follow up",COUNTIF($H$3:H36,"Follow up"),"")
A37: F-035 | B37: Week 2 | C37: Spanish | D37: 46216 | E37: Yes | F37: Phone | G37: Prefers morning slot | H37: =IF(D37<>"","Confirmed","Follow up") -> Confirmed | I37: =IF(H37="Follow up",COUNTIF($H$3:H37,"Follow up"),"")
A38: F-036 | B38: Week 1 | C38: English | E38: No | F38: Phone | G38: Text sent | H38: =IF(D38<>"","Confirmed","Follow up") -> Follow up | I38: =IF(H38="Follow up",COUNTIF($H$3:H38,"Follow up"),"") -> 4
A39: F-037 | B39: Week 2 | C39: English | E39: No | F39: Phone | G39: Left voicemail | H39: =IF(D39<>"","Confirmed","Follow up") -> Follow up | I39: =IF(H39="Follow up",COUNTIF($H$3:H39,"Follow up"),"") -> 5
A40: F-038 | B40: Week 2 | C40: English | D40: 46218 | E40: Yes | F40: Phone | G40: Confirmed by phone | H40: =IF(D40<>"","Confirmed","Follow up") -> Confirmed | I40: =IF(H40="Follow up",COUNTIF($H$3:H40,"Follow up"),"")
...

Sheet Summary
A1: Program summary (updates automatically from Roster)
A3: Families on roster | B3: =COUNTA(Roster!A3:A149) -> 147
A4: Dates confirmed | B4: =COUNTIF(Roster!H3:H149,"Confirmed") -> 131
A5: Need follow-up | B5: =COUNTIF(Roster!H3:H149,"Follow up") -> 16
A6: Confirmation rate | B6: =IF(B3=0,0,B4/B3) -> 0.89115646
A8: By testing week
A9: Week | B9: Families | C9: Confirmed | D9: Follow up | E9: Rate
A10: Week 1 | B10: =COUNTIF(Roster!$B$3:$B$149,A10) -> 51 | C10: =COUNTIFS(Roster!$B$3:$B$149,A10,Roster!$H$3:$H$149,"Confirmed") -> 46 | D10: =COUNTIFS(Roster!$B$3:$B$149,A10,Roster!$H$3:$H$149,"Follow up") -> 5 | E10: =IF(B10=0,0,C10/B10) -> 0.90196078
A11: Week 2 | B11: =COUNTIF(Roster!$B$3:$B$149,A11) -> 53 | C11: =COUNTIFS(Roster!$B$3:$B$149,A11,Roster!$H$3:$H$149,"Confirmed") -> 45 | D11: =COUNTIFS(Roster!$B$3:$B$149,A11,Roster!$H$3:$H$149,"Follow up") -> 8 | E11: =IF(B11=0,0,C11/B11) -> 0.8490566
A12: Week 3 | B12: =COUNTIF(Roster!$B$3:$B$149,A12) -> 43 | C12: =COUNTIFS(Roster!$B$3:$B$149,A12,Roster!$H$3:$H$149,"Confirmed") -> 40 | D12: =COUNTIFS(Roster!$B$3:$B$149,A12,Roster!$H$3:$H$149,"Follow up") -> 3 | E12: =IF(B12=0,0,C12/B12) -> 0.93023256
A15: By preferred language
A16: Language | B16: Families | C16: Confirmed | D16: Follow up | E16: Rate
A17: English | B17: =COUNTIF(Roster!$C$3:$C$149,A17) -> 79 | C17: =COUNTIFS(Roster!$C$3:$C$149,A17,Roster!$H$3:$H$149,"Confirmed") -> 67 | D17: =COUNTIFS(Roster!$C$3:$C$149,A17,Roster!$H$3:$H$149,"Follow up") -> 12 | E17: =IF(B17=0,0,C17/B17) -> 0.84810127
A18: Spanish | B18: =COUNTIF(Roster!$C$3:$C$149,A18) -> 48 | C18: =COUNTIFS(Roster!$C$3:$C$149,A18,Roster!$H$3:$H$149,"Confirmed") -> 46 | D18: =COUNTIFS(Roster!$C$3:$C$149,A18,Roster!$H$3:$H$149,"Follow up") -> 2 | E18: =IF(B18=0,0,C18/B18) -> 0.95833333
A19: Arabic | B19: =COUNTIF(Roster!$C$3:$C$149,A19) -> 12 | C19: =COUNTIFS(Roster!$C$3:$C$149,A19,Roster!$H$3:$H$149,"Confirmed") -> 12 | D19: =COUNTIFS(Roster!$C$3:$C$149,A19,Roster!$H$3:$H$149,"Follow up") -> 0 | E19: =IF(B19=0,0,C19/B19) -> 1
A20: Portuguese | B20: =COUNTIF(Roster!$C$3:$C$149,A20) -> 8 | C20: =COUNTIFS(Roster!$C$3:$C$149,A20,Roster!$H$3:$H$149,"Confirmed") -> 6 | D20: =COUNTIFS(Roster!$C$3:$C$149,A20,Roster!$H$3:$H$149,"Follow up") -> 2 | E20: =IF(B20=0,0,C20/B20) -> 0.75
A22: Sample data only. Language split is invented for the demo except the 79 English-preferred total.

Sheet Follow-up List
A1: Families to call next (pulled automatically from Roster)
A3: # | B3: Family ID | C3: Testing Week | D3: Preferred Language | E3: Email Sent | F3: Notes
A4: 1 | B4: =IFERROR(INDEX(Roster!$A$3:$A$149,MATCH($A4,Roster!$I$3:$I$149,0)),"") -> F-005 | C4: =IFERROR(INDEX(Roster!$B$3:$B$149,MATCH($A4,Roster!$I$3:$I$149,0)),"") -> Week 1 | D4: =IFERROR(INDEX(Roster!$C$3:$C$149,MATCH($A4,Roster!$I$3:$I$149,0)),"") -> English | E4: =IFERROR(INDEX(Roster!$E$3:$E$149,MATCH($A4,Roster!$I$3:$I$149,0)),"") -> Yes | F4: =IFERROR(INDEX(Roster!$G$3:$G$149,MATCH($A4,Roster!$I$3:$I$149,0)),"") -> Left voicemail
A5: 2 | B5: =IFERROR(INDEX(Roster!$A$3:$A$149,MATCH($A5,Roster!$I$3:$I$149,0)),"") -> F-006 | C5: =IFERROR(INDEX(Roster!$B$3:$B$149,MATCH($A5,Roster!$I$3:$I$149,0)),"") -> Week 1 | D5: =IFERROR(INDEX(Roster!$C$3:$C$149,MATCH($A5,Roster!$I$3:$I$149,0)),"") -> English | E5: =IFERROR(INDEX(Roster!$E$3:$E$149,MATCH($A5,Roster!$I$3:$I$149,0)),"") -> No | F5: =IFERROR(INDEX(Roster!$G$3:$G$149,MATCH($A5,Roster!$I$3:$I$149,0)),"") -> Email bounced, calling
A6: 3 | B6: =IFERROR(INDEX(Roster!$A$3:$A$149,MATCH($A6,Roster!$I$3:$I$149,0)),"") -> F-028 | C6: =IFERROR(INDEX(Roster!$B$3:$B$149,MATCH($A6,Roster!$I$3:$I$149,0)),"") -> Week 2 | D6: =IFERROR(INDEX(Roster!$C$3:$C$149,MATCH($A6,Roster!$I$3:$I$149,0)),"") -> Portuguese | E6: =IFERROR(INDEX(Roster!$E$3:$E$149,MATCH($A6,Roster!$I$3:$I$149,0)),"") -> Yes | F6: =IFERROR(INDEX(Roster!$G$3:$G$149,MATCH($A6,Roster!$I$3:$I$149,0)),"") -> Email bounced, calling
A7: 4 | B7: =IFERROR(INDEX(Roster!$A$3:$A$149,MATCH($A7,Roster!$I$3:$I$149,0)),"") -> F-036 | C7: =IFERROR(INDEX(Roster!$B$3:$B$149,MATCH($A7,Roster!$I$3:$I$149,0)),"") -> Week 1 | D7: =IFERROR(INDEX(Roster!$C$3:$C$149,MATCH($A7,Roster!$I$3:$I$149,0)),"") -> English | E7: =IFERROR(INDEX(Roster!$E$3:$E$149,MATCH($A7,Roster!$I$3:$I$149,0)),"") -> No | F7: =IFERROR(INDEX(Roster!$G$3:$G$149,MATCH($A7,Roster!$I$3:$I$149,0)),"") -> Text sent
A8: 5 | B8: =IFERROR(INDEX(Roster!$A$3:$A$149,MATCH($A8,Roster!$I$3:$I$149,0)),"") -> F-037 | C8: =IFERROR(INDEX(Roster!$B$3:$B$149,MATCH($A8,Roster!$I$3:$I$149,0)),"") -> Week 2 | D8: =IFERROR(INDEX(Roster!$C$3:$C$149,MATCH($A8,Roster!$I$3:$I$149,0)),"") -> English | E8: =IFERROR(INDEX(Roster!$E$3:$E$149,MATCH($A8,Roster!$I$3:$I$149,0)),"") -> No | F8: =IFERROR(INDEX(Roster!$G$3:$G$149,MATCH($A8,Roster!$I$3:$I$149,0)),"") -> Left voicemail
A9: 6 | B9: =IFERROR(INDEX(Roster!$A$3:$A$149,MATCH($A9,Roster!$I$3:$I$149,0)),"") -> F-043 | C9: =IFERROR(INDEX(Roster!$B$3:$B$149,MATCH($A9,Roster!$I$3:$I$149,0)),"") -> Week 3 | D9: =IFERROR(INDEX(Roster!$C$3:$C$149,MATCH($A9,Roster!$I$3:$I$149,0)),"") -> English | E9: =IFERROR(INDEX(Roster!$E$3:$E$149,MATCH($A9,Roster!$I$3:$I$149,0)),"") -> No | F9: =IFERROR(INDEX(Roster!$G$3:$G$149,MATCH($A9,Roster!$I$3:$I$149,0)),"") -> No reply after 2 emails
A10: 7 | B10: =IFERROR(INDEX(Roster!$A$3:$A$149,MATCH($A10,Roster!$I$3:$I$149,0)),"") -> F-053 | C10: =IFERROR(INDEX(Roster!$B$3:$B$149,MATCH($A10,Roster!$I$3:$I$149,0)),"") -> Week 2 | D10: =IFERROR(INDEX(Roster!$C$3:$C$149,MATCH($A10,Roster!$I$3:$I$149,0)),"") -> English | E10: =IFERROR(INDEX(Roster!$E$3:$E$149,MATCH($A10,Roster!$I$3:$I$149,0)),"") -> No | F10: =IFERROR(INDEX(Roster!$G$3:$G$149,MATCH($A10,Roster!$I$3:$I$149,0)),"") -> Text sent
A11: 8 | B11: =IFERROR(INDEX(Roster!$A$3:$A$149,MATCH($A11,Roster!$I$3:$I$149,0)),"") -> F-072 | C11: =IFERROR(INDEX(Roster!$B$3:$B$149,MATCH($A11,Roster!$I$3:$I$149,0)),"") -> Week 3 | D11: =IFERROR(INDEX(Roster!$C$3:$C$149,MATCH($A11,Roster!$I$3:$I$149,0)),"") -> English | E11: =IFERROR(INDEX(Roster!$E$3:$E$149,MATCH($A11,Roster!$I$3:$I$149,0)),"") -> Yes | F11: =IFERROR(INDEX(Roster!$G$3:$G$149,MATCH($A11,Roster!$I$3:$I$149,0)),"") -> Email bounced, calling
A12: 9 | B12: =IFERROR(INDEX(Roster!$A$3:$A$149,MATCH($A12,Roster!$I$3:$I$149,0)),"") -> F-081 | C12: =IFERROR(INDEX(Roster!$B$3:$B$149,MATCH($A12,Roster!$I$3:$I$149,0)),"") -> Week 1 | D12: =IFERROR(INDEX(Roster!$C$3:$C$149,MATCH($A12,Roster!$I$3:$I$149,0)),"") -> Spanish | E12: =IFERROR(INDEX(Roster!$E$3:$E$149,MATCH($A12,Roster!$I$3:$I$149,0)),"") -> Yes | F12: =IFERROR(INDEX(Roster!$G$3:$G$149,MATCH($A12,Roster!$I$3:$I$149,0)),"") -> Left voicemail
A13: 10 | B13: =IFERROR(INDEX(Roster!$A$3:$A$149,MATCH($A13,Roster!$I$3:$I$149,0)),"") -> F-094 | C13: =IFERROR(INDEX(Roster!$B$3:$B$149,MATCH($A13,Roster!$I$3:$I$149,0)),"") -> Week 2 | D13: =IFERROR(INDEX(Roster!$C$3:$C$149,MATCH($A13,Roster!$I$3:$I$149,0)),"") -> English | E13: =IFERROR(INDEX(Roster!$E$3:$E$149,MATCH($A13,Roster!$I$3:$I$149,0)),"") -> Yes | F13: =IFERROR(INDEX(Roster!$G$3:$G$149,MATCH($A13,Roster!$I$3:$I$149,0)),"") -> Email bounced, calling
A14: 11 | B14: =IFERROR(INDEX(Roster!$A$3:$A$149,MATCH($A14,Roster!$I$3:$I$149,0)),"") -> F-097 | C14: =IFERROR(INDEX(Roster!$B$3:$B$149,MATCH($A14,Roster!$I$3:$I$149,0)),"") -> Week 3 | D14: =IFERROR(INDEX(Roster!$C$3:$C$149,MATCH($A14,Roster!$I$3:$I$149,0)),"") -> Spanish | E14: =IFERROR(INDEX(Roster!$E$3:$E$149,MATCH($A14,Roster!$I$3:$I$149,0)),"") -> Yes | F14: =IFERROR(INDEX(Roster!$G$3:$G$149,MATCH($A14,Roster!$I$3:$I$149,0)),"") -> No reply after 2 emails
A15: 12 | B15: =IFERROR(INDEX(Roster!$A$3:$A$149,MATCH($A15,Roster!$I$3:$I$149,0)),"") -> F-107 | C15: =IFERROR(INDEX(Roster!$B$3:$B$149,MATCH($A15,Roster!$I$3:$I$149,0)),"") -> Week 2 | D15: =IFERROR(INDEX(Roster!$C$3:$C$149,MATCH($A15,Roster!$I$3:$I$149,0)),"") -> Portuguese | E15: =IFERROR(INDEX(Roster!$E$3:$E$149,MATCH($A15,Roster!$I$3:$I$149,0)),"") -> No | F15: =IFERROR(INDEX(Roster!$G$3:$G$149,MATCH($A15,Roster!$I$3:$I$149,0)),"") -> Call back after 3pm
... A33: 30 | B33: =IFERROR(INDEX(Roster!$A$3:$A$149,MATCH($A33,Roster!$I$3:$I$149,0)),"") | C33: =IFERROR(INDEX(Roster!$B$3:$B$149,MATCH($A33,Roster!$I$3:$I$149,0)),"") | D33: =IFERROR(INDEX(Roster!$C$3:$C$149,MATCH($A33,Roster!$I$3:$I$149,0)),"") | E33: =IFERROR(INDEX(Roster!$E$3:$E$149,MATCH($A33,Roster!$I$3:$I$149,0)),"") | F33: =IFERROR(INDEX(Roster!$G$3:$G$149,MATCH($A33,Roster!$I$3:$I$149,0)),"")
