Workbook

Sheet Roster
A1: Sample data. All students are fictional (IDs only, no names). Blue cells are typed in; black cells are formulas.
A2: Student ID | B2: Grade | C2: Testing Week | D2: Week 1 # | E2: Week 2 #
A3: S-001 | B3: 8 | C3: Week 1 | D3: =IF(C3="Week 1",COUNTIF($C$3:C3,"Week 1"),"") -> 1 | E3: =IF(C3="Week 2",COUNTIF($C$3:C3,"Week 2"),"")
A4: S-002 | B4: 5 | C4: Week 1 | D4: =IF(C4="Week 1",COUNTIF($C$3:C4,"Week 1"),"") -> 2 | E4: =IF(C4="Week 2",COUNTIF($C$3:C4,"Week 2"),"")
A5: S-003 | B5: 8 | C5: Week 1 | D5: =IF(C5="Week 1",COUNTIF($C$3:C5,"Week 1"),"") -> 3 | E5: =IF(C5="Week 2",COUNTIF($C$3:C5,"Week 2"),"")
A6: S-004 | B6: 5 | C6: Week 2 | D6: =IF(C6="Week 1",COUNTIF($C$3:C6,"Week 1"),"") | E6: =IF(C6="Week 2",COUNTIF($C$3:C6,"Week 2"),"") -> 1
A7: S-005 | B7: 5 | C7: Week 2 | D7: =IF(C7="Week 1",COUNTIF($C$3:C7,"Week 1"),"") | E7: =IF(C7="Week 2",COUNTIF($C$3:C7,"Week 2"),"") -> 2
A8: S-006 | B8: 5 | C8: Week 1 | D8: =IF(C8="Week 1",COUNTIF($C$3:C8,"Week 1"),"") -> 4 | E8: =IF(C8="Week 2",COUNTIF($C$3:C8,"Week 2"),"")
A9: S-007 | B9: 5 | C9: Week 2 | D9: =IF(C9="Week 1",COUNTIF($C$3:C9,"Week 1"),"") | E9: =IF(C9="Week 2",COUNTIF($C$3:C9,"Week 2"),"") -> 3
A10: S-008 | B10: 8 | C10: Week 2 | D10: =IF(C10="Week 1",COUNTIF($C$3:C10,"Week 1"),"") | E10: =IF(C10="Week 2",COUNTIF($C$3:C10,"Week 2"),"") -> 4
A11: S-009 | B11: 5 | C11: Week 1 | D11: =IF(C11="Week 1",COUNTIF($C$3:C11,"Week 1"),"") -> 5 | E11: =IF(C11="Week 2",COUNTIF($C$3:C11,"Week 2"),"")
A12: S-010 | B12: 5 | C12: Week 2 | D12: =IF(C12="Week 1",COUNTIF($C$3:C12,"Week 1"),"") | E12: =IF(C12="Week 2",COUNTIF($C$3:C12,"Week 2"),"") -> 5
A13: S-011 | B13: 5 | C13: Week 1 | D13: =IF(C13="Week 1",COUNTIF($C$3:C13,"Week 1"),"") -> 6 | E13: =IF(C13="Week 2",COUNTIF($C$3:C13,"Week 2"),"")
A14: S-012 | B14: 8 | C14: Week 2 | D14: =IF(C14="Week 1",COUNTIF($C$3:C14,"Week 1"),"") | E14: =IF(C14="Week 2",COUNTIF($C$3:C14,"Week 2"),"") -> 6
... A148: S-146 | B148: 8 | C148: Week 2 | D148: =IF(C148="Week 1",COUNTIF($C$3:C148,"Week 1"),"") | E148: =IF(C148="Week 2",COUNTIF($C$3:C148,"Week 2"),"") -> 71

Sheet Summary
A1: Diagnostic summary (updates from the Week tabs)
A3: Week | B3: Students | C3: ELA completed | D3: ELA % | E3: Math completed | F3: Math % | G3: Avg ELA score | H3: Avg Math score
A4: Week 1 | B4: ='Week 1'!D1 -> 75 | C4: =COUNTIF('Week 1'!D3:D90,"Completed") -> 65 | D4: =IF(B4=0,0,C4/B4) -> 0.86666667 | E4: =COUNTIF('Week 1'!H3:H90,"Completed") -> 66 | F4: =IF(B4=0,0,E4/B4) -> 0.88 | G4: =IFERROR(AVERAGE('Week 1'!E3:E90),0) -> 546.12308 | H4: =IFERROR(AVERAGE('Week 1'!I3:I90),0) -> 539.28788
A5: Week 2 | B5: ='Week 2'!D1 -> 71 | C5: =COUNTIF('Week 2'!D3:D90,"Completed") -> 62 | D5: =IF(B5=0,0,C5/B5) -> 0.87323944 | E5: =COUNTIF('Week 2'!H3:H90,"Completed") -> 61 | F5: =IF(B5=0,0,E5/B5) -> 0.85915493 | G5: =IFERROR(AVERAGE('Week 2'!E3:E90),0) -> 557.74194 | H5: =IFERROR(AVERAGE('Week 2'!I3:I90),0) -> 561.40984
A6: Total | B6: =SUM(B4:B5) -> 146 | C6: =SUM(C4:C5) -> 127 | D6: =IF(B6=0,0,C6/B6) -> 0.86986301 | E6: =SUM(E4:E5) -> 127 | F6: =IF(B6=0,0,E6/B6) -> 0.86986301 | G6: =IFERROR(AVERAGE('Week 1'!E3:E90,'Week 2'!E3:E90),0) -> 551.79528 | H6: =IFERROR(AVERAGE('Week 1'!I3:I90,'Week 2'!I3:I90),0) -> 549.91339
A9: Placement vs. grade | B9: ELA students | C9: ELA % | D9: Math students | E9: Math %
A10: On/above grade | B10: =COUNTIF('Week 1'!G3:G90,A10)+COUNTIF('Week 2'!G3:G90,A10) -> 38 | C10: =IF(SUM($B$10:$B$13)=0,0,B10/SUM($B$10:$B$13)) -> 0.2992126 | D10: =COUNTIF('Week 1'!K3:K90,A10)+COUNTIF('Week 2'!K3:K90,A10) -> 36 | E10: =IF(SUM($D$10:$D$13)=0,0,D10/SUM($D$10:$D$13)) -> 0.28346457
A11: 1 grade below | B11: =COUNTIF('Week 1'!G3:G90,A11)+COUNTIF('Week 2'!G3:G90,A11) -> 33 | C11: =IF(SUM($B$10:$B$13)=0,0,B11/SUM($B$10:$B$13)) -> 0.25984252 | D11: =COUNTIF('Week 1'!K3:K90,A11)+COUNTIF('Week 2'!K3:K90,A11) -> 40 | E11: =IF(SUM($D$10:$D$13)=0,0,D11/SUM($D$10:$D$13)) -> 0.31496063
A12: 2 grades below | B12: =COUNTIF('Week 1'!G3:G90,A12)+COUNTIF('Week 2'!G3:G90,A12) -> 30 | C12: =IF(SUM($B$10:$B$13)=0,0,B12/SUM($B$10:$B$13)) -> 0.23622047 | D12: =COUNTIF('Week 1'!K3:K90,A12)+COUNTIF('Week 2'!K3:K90,A12) -> 29 | E12: =IF(SUM($D$10:$D$13)=0,0,D12/SUM($D$10:$D$13)) -> 0.22834646
A13: 3+ grades below | B13: =COUNTIF('Week 1'!G3:G90,A13)+COUNTIF('Week 2'!G3:G90,A13) -> 26 | C13: =IF(SUM($B$10:$B$13)=0,0,B13/SUM($B$10:$B$13)) -> 0.20472441 | D13: =COUNTIF('Week 1'!K3:K90,A13)+COUNTIF('Week 2'!K3:K90,A13) -> 22 | E13: =IF(SUM($D$10:$D$13)=0,0,D13/SUM($D$10:$D$13)) -> 0.17322835
A16: Group (Week 1) | B16: Students | C16: Group (Week 2) | D16: Students
A17: Group A | B17: =COUNTIF('Week 1'!C3:C90,A17) -> 25 | C17: Group A | D17: =COUNTIF('Week 2'!C3:C90,C17) -> 24
A18: Group B | B18: =COUNTIF('Week 1'!C3:C90,A18) -> 25 | C18: Group B | D18: =COUNTIF('Week 2'!C3:C90,C18) -> 24
A19: Group C | B19: =COUNTIF('Week 1'!C3:C90,A19) -> 25 | C19: Group C | D19: =COUNTIF('Week 2'!C3:C90,C19) -> 23
A21: Placement is the overall i-Ready placement level entered from the diagnostic report. Scores and placements here are invented for the demo.

Sheet Week 1
A1: Week 1 | C1: Students: | D1: =COUNTIF(A3:A87,"S-*") -> 75 | E1: Per group: | F1: =ROUNDUP(D1/3,0) -> 25
A2: Student ID | B2: Grade | C2: Group | D2: ELA Status | E2: ELA Score | F2: ELA Placement | G2: ELA vs. Grade | H2: Math Status | I2: Math Score | J2: Math Placement | K2: Math vs. Grade | L2: Mon | M2: Tue | N2: Wed | O2: Notes
A3: =IFERROR(INDEX(Roster!$A$3:$A$148,MATCH(1,Roster!$D$3:$D$148,0)),"") -> S-001 | B3: =IFERROR(INDEX(Roster!$B$3:$B$148,MATCH(1,Roster!$D$3:$D$148,0)),"") -> 8 | C3: =IF(A3="","",IF(ROW()-3<$F$1,"Group A",IF(ROW()-3<2*$F$1,"Group B","Group C"))) -> Group A | D3: Completed | E3: 667 | F3: Grade 8 | G3: =IF(F3="","",IF(B3-IF(F3="Grade K",0,VALUE(SUBSTITUTE(F3,"Grade ","")))<=0,"On/above grade",IF(B3-IF(F3="Grade K",0,VALUE(SUBSTITUTE(F3,"Grade ","")))=1,"1 grade below",IF(B3-IF(F3="Grade K",0,VALUE(SUBSTITUTE(F3,"Grade ","")))=2,"2 grades below","3+ grades below")))) -> On/above grade | H3: Completed | I3: 582 | J3: Grade 6 | K3: =IF(J3="","",IF(B3-IF(J3="Grade K",0,VALUE(SUBSTITUTE(J3,"Grade ","")))<=0,"On/above grade",IF(B3-IF(J3="Grade K",0,VALUE(SUBSTITUTE(J3,"Grade ","")))=1,"1 grade below",IF(B3-IF(J3="Grade K",0,VALUE(SUBSTITUTE(J3,"Grade ","")))=2,"2 grades below","3+ grades below")))) -> 2 grades below | L3: Completed All | M3: Present | N3: Present
A4: =IFERROR(INDEX(Roster!$A$3:$A$148,MATCH(2,Roster!$D$3:$D$148,0)),"") -> S-002 | B4: =IFERROR(INDEX(Roster!$B$3:$B$148,MATCH(2,Roster!$D$3:$D$148,0)),"") -> 5 | C4: =IF(A4="","",IF(ROW()-3<$F$1,"Group A",IF(ROW()-3<2*$F$1,"Group B","Group C"))) -> Group A | D4: Completed | E4: 566 | F4: Grade 5 | G4: =IF(F4="","",IF(B4-IF(F4="Grade K",0,VALUE(SUBSTITUTE(F4,"Grade ","")))<=0,"On/above grade",IF(B4-IF(F4="Grade K",0,VALUE(SUBSTITUTE(F4,"Grade ","")))=1,"1 grade below",IF(B4-IF(F4="Grade K",0,VALUE(SUBSTITUTE(F4,"Grade ","")))=2,"2 grades below","3+ grades below")))) -> On/above grade | H4: Completed | I4: 432 | J4: Grade 2 | K4: =IF(J4="","",IF(B4-IF(J4="Grade K",0,VALUE(SUBSTITUTE(J4,"Grade ","")))<=0,"On/above grade",IF(B4-IF(J4="Grade K",0,VALUE(SUBSTITUTE(J4,"Grade ","")))=1,"1 grade below",IF(B4-IF(J4="Grade K",0,VALUE(SUBSTITUTE(J4,"Grade ","")))=2,"2 grades below","3+ grades below")))) -> 3+ grades below | L4: Completed All | M4: Absent | N4: Present
A5: =IFERROR(INDEX(Roster!$A$3:$A$148,MATCH(3,Roster!$D$3:$D$148,0)),"") -> S-003 | B5: =IFERROR(INDEX(Roster!$B$3:$B$148,MATCH(3,Roster!$D$3:$D$148,0)),"") -> 8 | C5: =IF(A5="","",IF(ROW()-3<$F$1,"Group A",IF(ROW()-3<2*$F$1,"Group B","Group C"))) -> Group A | D5: Completed | E5: 622 | F5: Grade 7 | G5: =IF(F5="","",IF(B5-IF(F5="Grade K",0,VALUE(SUBSTITUTE(F5,"Grade ","")))<=0,"On/above grade",IF(B5-IF(F5="Grade K",0,VALUE(SUBSTITUTE(F5,"Grade ","")))=1,"1 grade below",IF(B5-IF(F5="Grade K",0,VALUE(SUBSTITUTE(F5,"Grade ","")))=2,"2 grades below","3+ grades below")))) -> 1 grade below | H5: Absent | K5: =IF(J5="","",IF(B5-IF(J5="Grade K",0,VALUE(SUBSTITUTE(J5,"Grade ","")))<=0,"On/above grade",IF(B5-IF(J5="Grade K",0,VALUE(SUBSTITUTE(J5,"Grade ","")))=1,"1 grade below",IF(B5-IF(J5="Grade K",0,VALUE(SUBSTITUTE(J5,"Grade ","")))=2,"2 grades below","3+ grades below")))) | L5: Completed All | M5: Present | N5: Present
A6: =IFERROR(INDEX(Roster!$A$3:$A$148,MATCH(4,Roster!$D$3:$D$148,0)),"") -> S-006 | B6: =IFERROR(INDEX(Roster!$B$3:$B$148,MATCH(4,Roster!$D$3:$D$148,0)),"") -> 5 | C6: =IF(A6="","",IF(ROW()-3<$F$1,"Group A",IF(ROW()-3<2*$F$1,"Group B","Group C"))) -> Group A | D6: Completed | E6: 504 | F6: Grade 3 | G6: =IF(F6="","",IF(B6-IF(F6="Grade K",0,VALUE(SUBSTITUTE(F6,"Grade ","")))<=0,"On/above grade",IF(B6-IF(F6="Grade K",0,VALUE(SUBSTITUTE(F6,"Grade ","")))=1,"1 grade below",IF(B6-IF(F6="Grade K",0,VALUE(SUBSTITUTE(F6,"Grade ","")))=2,"2 grades below","3+ grades below")))) -> 2 grades below | H6: Completed | I6: 537 | J6: Grade 5 | K6: =IF(J6="","",IF(B6-IF(J6="Grade K",0,VALUE(SUBSTITUTE(J6,"Grade ","")))<=0,"On/above grade",IF(B6-IF(J6="Grade K",0,VALUE(SUBSTITUTE(J6,"Grade ","")))=1,"1 grade below",IF(B6-IF(J6="Grade K",0,VALUE(SUBSTITUTE(J6,"Grade ","")))=2,"2 grades below","3+ grades below")))) -> On/above grade | L6: Present | M6: Completed All | N6: Completed All
A7: =IFERROR(INDEX(Roster!$A$3:$A$148,MATCH(5,Roster!$D$3:$D$148,0)),"") -> S-009 | B7: =IFERROR(INDEX(Roster!$B$3:$B$148,MATCH(5,Roster!$D$3:$D$148,0)),"") -> 5 | C7: =IF(A7="","",IF(ROW()-3<$F$1,"Group A",IF(ROW()-3<2*$F$1,"Group B","Group C"))) -> Group A | D7: Completed | E7: 536 | F7: Grade 4 | G7: =IF(F7="","",IF(B7-IF(F7="Grade K",0,VALUE(SUBSTITUTE(F7,"Grade ","")))<=0,"On/above grade",IF(B7-IF(F7="Grade K",0,VALUE(SUBSTITUTE(F7,"Grade ","")))=1,"1 grade below",IF(B7-IF(F7="Grade K",0,VALUE(SUBSTITUTE(F7,"Grade ","")))=2,"2 grades below","3+ grades below")))) -> 1 grade below | H7: Completed | I7: 564 | J7: Grade 5 | K7: =IF(J7="","",IF(B7-IF(J7="Grade K",0,VALUE(SUBSTITUTE(J7,"Grade ","")))<=0,"On/above grade",IF(B7-IF(J7="Grade K",0,VALUE(SUBSTITUTE(J7,"Grade ","")))=1,"1 grade below",IF(B7-IF(J7="Grade K",0,VALUE(SUBSTITUTE(J7,"Grade ","")))=2,"2 grades below","3+ grades below")))) -> On/above grade | L7: Present | M7: Completed All | N7: Present
A8: =IFERROR(INDEX(Roster!$A$3:$A$148,MATCH(6,Roster!$D$3:$D$148,0)),"") -> S-011 | B8: =IFERROR(INDEX(Roster!$B$3:$B$148,MATCH(6,Roster!$D$3:$D$148,0)),"") -> 5 | C8: =IF(A8="","",IF(ROW()-3<$F$1,"Group A",IF(ROW()-3<2*$F$1,"Group B","Group C"))) -> Group A | D8: Completed | E8: 505 | F8: Grade 3 | G8: =IF(F8="","",IF(B8-IF(F8="Grade K",0,VALUE(SUBSTITUTE(F8,"Grade ","")))<=0,"On/above grade",IF(B8-IF(F8="Grade K",0,VALUE(SUBSTITUTE(F8,"Grade ","")))=1,"1 grade below",IF(B8-IF(F8="Grade K",0,VALUE(SUBSTITUTE(F8,"Grade ","")))=2,"2 grades below","3+ grades below")))) -> 2 grades below | H8: Completed | I8: 569 | J8: Grade 5 | K8: =IF(J8="","",IF(B8-IF(J8="Grade K",0,VALUE(SUBSTITUTE(J8,"Grade ","")))<=0,"On/above grade",IF(B8-IF(J8="Grade K",0,VALUE(SUBSTITUTE(J8,"Grade ","")))=1,"1 grade below",IF(B8-IF(J8="Grade K",0,VALUE(SUBSTITUTE(J8,"Grade ","")))=2,"2 grades below","3+ grades below")))) -> On/above grade | L8: Completed All | M8: Completed All | N8: Absent
A9: =IFERROR(INDEX(Roster!$A$3:$A$148,MATCH(7,Roster!$D$3:$D$148,0)),"") -> S-013 | B9: =IFERROR(INDEX(Roster!$B$3:$B$148,MATCH(7,Roster!$D$3:$D$148,0)),"") -> 5 | C9: =IF(A9="","",IF(ROW()-3<$F$1,"Group A",IF(ROW()-3<2*$F$1,"Group B","Group C"))) -> Group A | D9: Completed | E9: 565 | F9: Grade 5 | G9: =IF(F9="","",IF(B9-IF(F9="Grade K",0,VALUE(SUBSTITUTE(F9,"Grade ","")))<=0,"On/above grade",IF(B9-IF(F9="Grade K",0,VALUE(SUBSTITUTE(F9,"Grade ","")))=1,"1 grade below",IF(B9-IF(F9="Grade K",0,VALUE(SUBSTITUTE(F9,"Grade ","")))=2,"2 grades below","3+ grades below")))) -> On/above grade | H9: Completed | I9: 495 | J9: Grade 3 | K9: =IF(J9="","",IF(B9-IF(J9="Grade K",0,VALUE(SUBSTITUTE(J9,"Grade ","")))<=0,"On/above grade",IF(B9-IF(J9="Grade K",0,VALUE(SUBSTITUTE(J9,"Grade ","")))=1,"1 grade below",IF(B9-IF(J9="Grade K",0,VALUE(SUBSTITUTE(J9,"Grade ","")))=2,"2 grades below","3+ grades below")))) -> 2 grades below | L9: Present | M9: Present | N9: Present
A10: =IFERROR(INDEX(Roster!$A$3:$A$148,MATCH(8,Roster!$D$3:$D$148,0)),"") -> S-017 | B10: =IFERROR(INDEX(Roster!$B$3:$B$148,MATCH(8,Roster!$D$3:$D$148,0)),"") -> 5 | C10: =IF(A10="","",IF(ROW()-3<$F$1,"Group A",IF(ROW()-3<2*$F$1,"Group B","Group C"))) -> Group A | D10: Completed | E10: 533 | F10: Grade 4 | G10: =IF(F10="","",IF(B10-IF(F10="Grade K",0,VALUE(SUBSTITUTE(F10,"Grade ","")))<=0,"On/above grade",IF(B10-IF(F10="Grade K",0,VALUE(SUBSTITUTE(F10,"Grade ","")))=1,"1 grade below",IF(B10-IF(F10="Grade K",0,VALUE(SUBSTITUTE(F10,"Grade ","")))=2,"2 grades below","3+ grades below")))) -> 1 grade below | H10: Completed | I10: 405 | J10: Grade 1 | K10: =IF(J10="","",IF(B10-IF(J10="Grade K",0,VALUE(SUBSTITUTE(J10,"Grade ","")))<=0,"On/above grade",IF(B10-IF(J10="Grade K",0,VALUE(SUBSTITUTE(J10,"Grade ","")))=1,"1 grade below",IF(B10-IF(J10="Grade K",0,VALUE(SUBSTITUTE(J10,"Grade ","")))=2,"2 grades below","3+ grades below")))) -> 3+ grades below | L10: Present | M10: Completed All | N10: Absent
A11: =IFERROR(INDEX(Roster!$A$3:$A$148,MATCH(9,Roster!$D$3:$D$148,0)),"") -> S-021 | B11: =IFERROR(INDEX(Roster!$B$3:$B$148,MATCH(9,Roster!$D$3:$D$148,0)),"") -> 5 | C11: =IF(A11="","",IF(ROW()-3<$F$1,"Group A",IF(ROW()-3<2*$F$1,"Group B","Group C"))) -> Group A | D11: Completed | E11: 419 | F11: Grade 1 | G11: =IF(F11="","",IF(B11-IF(F11="Grade K",0,VALUE(SUBSTITUTE(F11,"Grade ","")))<=0,"On/above grade",IF(B11-IF(F11="Grade K",0,VALUE(SUBSTITUTE(F11,"Grade ","")))=1,"1 grade below",IF(B11-IF(F11="Grade K",0,VALUE(SUBSTITUTE(F11,"Grade ","")))=2,"2 grades below","3+ grades below")))) -> 3+ grades below | H11: Completed | I11: 540 | J11: Grade 4 | K11: =IF(J11="","",IF(B11-IF(J11="Grade K",0,VALUE(SUBSTITUTE(J11,"Grade ","")))<=0,"On/above grade",IF(B11-IF(J11="Grade K",0,VALUE(SUBSTITUTE(J11,"Grade ","")))=1,"1 grade below",IF(B11-IF(J11="Grade K",0,VALUE(SUBSTITUTE(J11,"Grade ","")))=2,"2 grades below","3+ grades below")))) -> 1 grade below | L11: Completed All | M11: Present | N11: Present
A12: =IFERROR(INDEX(Roster!$A$3:$A$148,MATCH(10,Roster!$D$3:$D$148,0)),"") -> S-022 | B12: =IFERROR(INDEX(Roster!$B$3:$B$148,MATCH(10,Roster!$D$3:$D$148,0)),"") -> 5 | C12: =IF(A12="","",IF(ROW()-3<$F$1,"Group A",IF(ROW()-3<2*$F$1,"Group B","Group C"))) -> Group A | D12: Completed | E12: 521 | F12: Grade 4 | G12: =IF(F12="","",IF(B12-IF(F12="Grade K",0,VALUE(SUBSTITUTE(F12,"Grade ","")))<=0,"On/above grade",IF(B12-IF(F12="Grade K",0,VALUE(SUBSTITUTE(F12,"Grade ","")))=1,"1 grade below",IF(B12-IF(F12="Grade K",0,VALUE(SUBSTITUTE(F12,"Grade ","")))=2,"2 grades below","3+ grades below")))) -> 1 grade below | H12: Completed | I12: 478 | J12: Grade 3 | K12: =IF(J12="","",IF(B12-IF(J12="Grade K",0,VALUE(SUBSTITUTE(J12,"Grade ","")))<=0,"On/above grade",IF(B12-IF(J12="Grade K",0,VALUE(SUBSTITUTE(J12,"Grade ","")))=1,"1 grade below",IF(B12-IF(J12="Grade K",0,VALUE(SUBSTITUTE(J12,"Grade ","")))=2,"2 grades below","3+ grades below")))) -> 2 grades below | L12: Present | M12: Completed All | N12: Completed All
A13: =IFERROR(INDEX(Roster!$A$3:$A$148,MATCH(11,Roster!$D$3:$D$148,0)),"") -> S-024 | B13: =IFERROR(INDEX(Roster!$B$3:$B$148,MATCH(11,Roster!$D$3:$D$148,0)),"") -> 5 | C13: =IF(A13="","",IF(ROW()-3<$F$1,"Group A",IF(ROW()-3<2*$F$1,"Group B","Group C"))) -> Group A | D13: Absent | G13: =IF(F13="","",IF(B13-IF(F13="Grade K",0,VALUE(SUBSTITUTE(F13,"Grade ","")))<=0,"On/above grade",IF(B13-IF(F13="Grade K",0,VALUE(SUBSTITUTE(F13,"Grade ","")))=1,"1 grade below",IF(B13-IF(F13="Grade K",0,VALUE(SUBSTITUTE(F13,"Grade ","")))=2,"2 grades below","3+ grades below")))) | H13: Completed | I13: 559 | J13: Grade 5 | K13: =IF(J13="","",IF(B13-IF(J13="Grade K",0,VALUE(SUBSTITUTE(J13,"Grade ","")))<=0,"On/above grade",IF(B13-IF(J13="Grade K",0,VALUE(SUBSTITUTE(J13,"Grade ","")))=1,"1 grade below",IF(B13-IF(J13="Grade K",0,VALUE(SUBSTITUTE(J13,"Grade ","")))=2,"2 grades below","3+ grades below")))) -> On/above grade | L13: Absent | M13: Absent | N13: Present
A14: =IFERROR(INDEX(Roster!$A$3:$A$148,MATCH(12,Roster!$D$3:$D$148,0)),"") -> S-026 | B14: =IFERROR(INDEX(Roster!$B$3:$B$148,MATCH(12,Roster!$D$3:$D$148,0)),"") -> 8 | C14: =IF(A14="","",IF(ROW()-3<$F$1,"Group A",IF(ROW()-3<2*$F$1,"Group B","Group C"))) -> Group A | D14: Completed | E14: 606 | F14: Grade 7 | G14: =IF(F14="","",IF(B14-IF(F14="Grade K",0,VALUE(SUBSTITUTE(F14,"Grade ","")))<=0,"On/above grade",IF(B14-IF(F14="Grade K",0,VALUE(SUBSTITUTE(F14,"Grade ","")))=1,"1 grade below",IF(B14-IF(F14="Grade K",0,VALUE(SUBSTITUTE(F14,"Grade ","")))=2,"2 grades below","3+ grades below")))) -> 1 grade below | H14: Completed | I14: 668 | J14: Grade 8 | K14: =IF(J14="","",IF(B14-IF(J14="Grade K",0,VALUE(SUBSTITUTE(J14,"Grade ","")))<=0,"On/above grade",IF(B14-IF(J14="Grade K",0,VALUE(SUBSTITUTE(J14,"Grade ","")))=1,"1 grade below",IF(B14-IF(J14="Grade K",0,VALUE(SUBSTITUTE(J14,"Grade ","")))=2,"2 grades below","3+ grades below")))) -> On/above grade | L14: Present | M14: Present | N14: Present
A15: =IFERROR(INDEX(Roster!$A$3:$A$148,MATCH(13,Roster!$D$3:$D$148,0)),"") -> S-027 | B15: =IFERROR(INDEX(Roster!$B$3:$B$148,MATCH(13,Roster!$D$3:$D$148,0)),"") -> 5 | C15: =IF(A15="","",IF(ROW()-3<$F$1,"Group A",IF(ROW()-3<2*$F$1,"Group B","Group C"))) -> Group A | D15: Absent | G15: =IF(F15="","",IF(B15-IF(F15="Grade K",0,VALUE(SUBSTITUTE(F15,"Grade ","")))<=0,"On/above grade",IF(B15-IF(F15="Grade K",0,VALUE(SUBSTITUTE(F15,"Grade ","")))=1,"1 grade below",IF(B15-IF(F15="Grade K",0,VALUE(SUBSTITUTE(F15,"Grade ","")))=2,"2 grades below","3+ grades below")))) | H15: Completed | I15: 457 | J15: Grade 2 | K15: =IF(J15="","",IF(B15-IF(J15="Grade K",0,VALUE(SUBSTITUTE(J15,"Grade ","")))<=0,"On/above grade",IF(B15-IF(J15="Grade K",0,VALUE(SUBSTITUTE(J15,"Grade ","")))=1,"1 grade below",IF(B15-IF(J15="Grade K",0,VALUE(SUBSTITUTE(J15,"Grade ","")))=2,"2 grades below","3+ grades below")))) -> 3+ grades below | L15: Completed All | M15: Present | N15: Present
A16: =IFERROR(INDEX(Roster!$A$3:$A$148,MATCH(14,Roster!$D$3:$D$148,0)),"") -> S-028 | B16: =IFERROR(INDEX(Roster!$B$3:$B$148,MATCH(14,Roster!$D$3:$D$148,0)),"") -> 8 | C16: =IF(A16="","",IF(ROW()-3<$F$1,"Group A",IF(ROW()-3<2*$F$1,"Group B","Group C"))) -> Group A | D16: Completed | E16: 649 | F16: Grade 8 | G16: =IF(F16="","",IF(B16-IF(F16="Grade K",0,VALUE(SUBSTITUTE(F16,"Grade ","")))<=0,"On/above grade",IF(B16-IF(F16="Grade K",0,VALUE(SUBSTITUTE(F16,"Grade ","")))=1,"1 grade below",IF(B16-IF(F16="Grade K",0,VALUE(SUBSTITUTE(F16,"Grade ","")))=2,"2 grades below","3+ grades below")))) -> On/above grade | H16: Absent | K16: =IF(J16="","",IF(B16-IF(J16="Grade K",0,VALUE(SUBSTITUTE(J16,"Grade ","")))<=0,"On/above grade",IF(B16-IF(J16="Grade K",0,VALUE(SUBSTITUTE(J16,"Grade ","")))=1,"1 grade below",IF(B16-IF(J16="Grade K",0,VALUE(SUBSTITUTE(J16,"Grade ","")))=2,"2 grades below","3+ grades below")))) | L16: Absent | M16: Present | N16: Completed All
A17: =IFERROR(INDEX(Roster!$A$3:$A$148,MATCH(15,Roster!$D$3:$D$148,0)),"") -> S-031 | B17: =IFERROR(INDEX(Roster!$B$3:$B$148,MATCH(15,Roster!$D$3:$D$148,0)),"") -> 5 | C17: =IF(A17="","",IF(ROW()-3<$F$1,"Group A",IF(ROW()-3<2*$F$1,"Group B","Group C"))) -> Group A | D17: Completed | E17: 467 | F17: Grade 2 | G17: =IF(F17="","",IF(B17-IF(F17="Grade K",0,VALUE(SUBSTITUTE(F17,"Grade ","")))<=0,"On/above grade",IF(B17-IF(F17="Grade K",0,VALUE(SUBSTITUTE(F17,"Grade ","")))=1,"1 grade below",IF(B17-IF(F17="Grade K",0,VALUE(SUBSTITUTE(F17,"Grade ","")))=2,"2 grades below","3+ grades below")))) -> 3+ grades below | H17: Absent | K17: =IF(J17="","",IF(B17-IF(J17="Grade K",0,VALUE(SUBSTITUTE(J17,"Grade ","")))<=0,"On/above grade",IF(B17-IF(J17="Grade K",0,VALUE(SUBSTITUTE(J17,"Grade ","")))=1,"1 grade below",IF(B17-IF(J17="Grade K",0,VALUE(SUBSTITUTE(J17,"Grade ","")))=2,"2 grades below","3+ grades below")))) | L17: Present | M17: Present | N17: Present
A18: =IFERROR(INDEX(Roster!$A$3:$A$148,MATCH(16,Roster!$D$3:$D$148,0)),"") -> S-034 | B18: =IFERROR(INDEX(Roster!$B$3:$B$148,MATCH(16,Roster!$D$3:$D$148,0)),"") -> 5 | C18: =IF(A18="","",IF(ROW()-3<$F$1,"Group A",IF(ROW()-3<2*$F$1,"Group B","Group C"))) -> Group A | D18: Completed | E18: 505 | F18: Grade 3 | G18: =IF(F18="","",IF(B18-IF(F18="Grade K",0,VALUE(SUBSTITUTE(F18,"Grade ","")))<=0,"On/above grade",IF(B18-IF(F18="Grade K",0,VALUE(SUBSTITUTE(F18,"Grade ","")))=1,"1 grade below",IF(B18-IF(F18="Grade K",0,VALUE(SUBSTITUTE(F18,"Grade ","")))=2,"2 grades below","3+ grades below")))) -> 2 grades below | H18: Completed | I18: 535 | J18: Grade 4 | K18: =IF(J18="","",IF(B18-IF(J18="Grade K",0,VALUE(SUBSTITUTE(J18,"Grade ","")))<=0,"On/above grade",IF(B18-IF(J18="Grade K",0,VALUE(SUBSTITUTE(J18,"Grade ","")))=1,"1 grade below",IF(B18-IF(J18="Grade K",0,VALUE(SUBSTITUTE(J18,"Grade ","")))=2,"2 grades below","3+ grades below")))) -> 1 grade below | L18: Present | M18: Completed All | N18: Absent
A19: =IFERROR(INDEX(Roster!$A$3:$A$148,MATCH(17,Roster!$D$3:$D$148,0)),"") -> S-035 | B19: =IFERROR(INDEX(Roster!$B$3:$B$148,MATCH(17,Roster!$D$3:$D$148,0)),"") -> 5 | C19: =IF(A19="","",IF(ROW()-3<$F$1,"Group A",IF(ROW()-3<2*$F$1,"Group B","Group C"))) -> Group A | D19: Started | G19: =IF(F19="","",IF(B19-IF(F19="Grade K",0,VALUE(SUBSTITUTE(F19,"Grade ","")))<=0,"On/above grade",IF(B19-IF(F19="Grade K",0,VALUE(SUBSTITUTE(F19,"Grade ","")))=1,"1 grade below",IF(B19-IF(F19="Grade K",0,VALUE(SUBSTITUTE(F19,"Grade ","")))=2,"2 grades below","3+ grades below")))) | H19: Completed | I19: 509 | J19: Grade 4 | K19: =IF(J19="","",IF(B19-IF(J19="Grade K",0,VALUE(SUBSTITUTE(J19,"Grade ","")))<=0,"On/above grade",IF(B19-IF(J19="Grade K",0,VALUE(SUBSTITUTE(J19,"Grade ","")))=1,"1 grade below",IF(B19-IF(J19="Grade K",0,VALUE(SUBSTITUTE(J19,"Grade ","")))=2,"2 grades below","3+ grades below")))) -> 1 grade below | L19: Absent | M19: Present | N19: Present
A20: =IFERROR(INDEX(Roster!$A$3:$A$148,MATCH(18,Roster!$D$3:$D$148,0)),"") -> S-039 | B20: =IFERROR(INDEX(Roster!$B$3:$B$148,MATCH(18,Roster!$D$3:$D$148,0)),"") -> 8 | C20: =IF(A20="","",IF(ROW()-3<$F$1,"Group A",IF(ROW()-3<2*$F$1,"Group B","Group C"))) -> Group A | D20: Completed | E20: 637 | F20: Grade 7 | G20: =IF(F20="","",IF(B20-IF(F20="Grade K",0,VALUE(SUBSTITUTE(F20,"Grade ","")))<=0,"On/above grade",IF(B20-IF(F20="Grade K",0,VALUE(SUBSTITUTE(F20,"Grade ","")))=1,"1 grade below",IF(B20-IF(F20="Grade K",0,VALUE(SUBSTITUTE(F20,"Grade ","")))=2,"2 grades below","3+ grades below")))) -> 1 grade below | H20: Completed | I20: 639 | J20: Grade 7 | K20: =IF(J20="","",IF(B20-IF(J20="Grade K",0,VALUE(SUBSTITUTE(J20,"Grade ","")))<=0,"On/above grade",IF(B20-IF(J20="Grade K",0,VALUE(SUBSTITUTE(J20,"Grade ","")))=1,"1 grade below",IF(B20-IF(J20="Grade K",0,VALUE(SUBSTITUTE(J20,"Grade ","")))=2,"2 grades below","3+ grades below")))) -> 1 grade below | L20: Absent | M20: Present | N20: Present
A21: =IFERROR(INDEX(Roster!$A$3:$A$148,MATCH(19,Roster!$D$3:$D$148,0)),"") -> S-042 | B21: =IFERROR(INDEX(Roster!$B$3:$B$148,MATCH(19,Roster!$D$3:$D$148,0)),"") -> 5 | C21: =IF(A21="","",IF(ROW()-3<$F$1,"Group A",IF(ROW()-3<2*$F$1,"Group B","Group C"))) -> Group A | D21: Completed | E21: 531 | F21: Grade 4 | G21: =IF(F21="","",IF(B21-IF(F21="Grade K",0,VALUE(SUBSTITUTE(F21,"Grade ","")))<=0,"On/above grade",IF(B21-IF(F21="Grade K",0,VALUE(SUBSTITUTE(F21,"Grade ","")))=1,"1 grade below",IF(B21-IF(F21="Grade K",0,VALUE(SUBSTITUTE(F21,"Grade ","")))=2,"2 grades below","3+ grades below")))) -> 1 grade below | H21: Completed | I21: 569 | J21: Grade 5 | K21: =IF(J21="","",IF(B21-IF(J21="Grade K",0,VALUE(SUBSTITUTE(J21,"Grade ","")))<=0,"On/above grade",IF(B21-IF(J21="Grade K",0,VALUE(SUBSTITUTE(J21,"Grade ","")))=1,"1 grade below",IF(B21-IF(J21="Grade K",0,VALUE(SUBSTITUTE(J21,"Grade ","")))=2,"2 grades below","3+ grades below")))) -> On/above grade | L21: Present | M21: Absent | N21: Completed All
A22: =IFERROR(INDEX(Roster!$A$3:$A$148,MATCH(20,Roster!$D$3:$D$148,0)),"") -> S-043 | B22: =IFERROR(INDEX(Roster!$B$3:$B$148,MATCH(20,Roster!$D$3:$D$148,0)),"") -> 5 | C22: =IF(A22="","",IF(ROW()-3<$F$1,"Group A",IF(ROW()-3<2*$F$1,"Group B","Group C"))) -> Group A | D22: Completed | E22: 566 | F22: Grade 5 | G22: =IF(F22="","",IF(B22-IF(F22="Grade K",0,VALUE(SUBSTITUTE(F22,"Grade ","")))<=0,"On/above grade",IF(B22-IF(F22="Grade K",0,VALUE(SUBSTITUTE(F22,"Grade ","")))=1,"1 grade below",IF(B22-IF(F22="Grade K",0,VALUE(SUBSTITUTE(F22,"Grade ","")))=2,"2 grades below","3+ grades below")))) -> On/above grade | H22: Completed | I22: 530 | J22: Grade 4 | K22: =IF(J22="","",IF(B22-IF(J22="Grade K",0,VALUE(SUBSTITUTE(J22,"Grade ","")))<=0,"On/above grade",IF(B22-IF(J22="Grade K",0,VALUE(SUBSTITUTE(J22,"Grade ","")))=1,"1 grade below",IF(B22-IF(J22="Grade K",0,VALUE(SUBSTITUTE(J22,"Grade ","")))=2,"2 grades below","3+ grades below")))) -> 1 grade below | L22: Present | M22: Present | N22: Present
A23: =IFERROR(INDEX(Roster!$A$3:$A$148,MATCH(21,Roster!$D$3:$D$148,0)),"") -> S-044 | B23: =IFERROR(INDEX(Roster!$B$3:$B$148,MATCH(21,Roster!$D$3:$D$148,0)),"") -> 5 | C23: =IF(A23="","",IF(ROW()-3<$F$1,"Group A",IF(ROW()-3<2*$F$1,"Group B","Group C"))) -> Group A | D23: Completed | E23: 536 | F23: Grade 5 | G23: =IF(F23="","",IF(B23-IF(F23="Grade K",0,VALUE(SUBSTITUTE(F23,"Grade ","")))<=0,"On/above grade",IF(B23-IF(F23="Grade K",0,VALUE(SUBSTITUTE(F23,"Grade ","")))=1,"1 grade below",IF(B23-IF(F23="Grade K",0,VALUE(SUBSTITUTE(F23,"Grade ","")))=2,"2 grades below","3+ grades below")))) -> On/above grade | H23: Completed | I23: 535 | J23: Grade 5 | K23: =IF(J23="","",IF(B23-IF(J23="Grade K",0,VALUE(SUBSTITUTE(J23,"Grade ","")))<=0,"On/above grade",IF(B23-IF(J23="Grade K",0,VALUE(SUBSTITUTE(J23,"Grade ","")))=1,"1 grade below",IF(B23-IF(J23="Grade K",0,VALUE(SUBSTITUTE(J23,"Grade ","")))=2,"2 grades below","3+ grades below")))) -> On/above grade | L23: Completed All | M23: Present | N23: Present
A24: =IFERROR(INDEX(Roster!$A$3:$A$148,MATCH(22,Roster!$D$3:$D$148,0)),"") -> S-046 | B24: =IFERROR(INDEX(Roster!$B$3:$B$148,MATCH(22,Roster!$D$3:$D$148,0)),"") -> 5 | C24: =IF(A24="","",IF(ROW()-3<$F$1,"Group A",IF(ROW()-3<2*$F$1,"Group B","Group C"))) -> Group A | D24: Completed | E24: 572 | F24: Grade 5 | G24: =IF(F24="","",IF(B24-IF(F24="Grade K",0,VALUE(SUBSTITUTE(F24,"Grade ","")))<=0,"On/above grade",IF(B24-IF(F24="Grade K",0,VALUE(SUBSTITUTE(F24,"Grade ","")))=1,"1 grade below",IF(B24-IF(F24="Grade K",0,VALUE(SUBSTITUTE(F24,"Grade ","")))=2,"2 grades below","3+ grades below")))) -> On/above grade | H24: Completed | I24: 516 | J24: Grade 4 | K24: =IF(J24="","",IF(B24-IF(J24="Grade K",0,VALUE(SUBSTITUTE(J24,"Grade ","")))<=0,"On/above grade",IF(B24-IF(J24="Grade K",0,VALUE(SUBSTITUTE(J24,"Grade ","")))=1,"1 grade below",IF(B24-IF(J24="Grade K",0,VALUE(SUBSTITUTE(J24,"Grade ","")))=2,"2 grades below","3+ grades below")))) -> 1 grade below | L24: Completed All | M24: Completed All | N24: Completed All
A25: =IFERROR(INDEX(Roster!$A$3:$A$148,MATCH(23,Roster!$D$3:$D$148,0)),"") -> S-047 | B25: =IFERROR(INDEX(Roster!$B$3:$B$148,MATCH(23,Roster!$D$3:$D$148,0)),"") -> 5 | C25: =IF(A25="","",IF(ROW()-3<$F$1,"Group A",IF(ROW()-3<2*$F$1,"Group B","Group C"))) -> Group A | D25: Completed | E25: 498 | F25: Grade 3 | G25: =IF(F25="","",IF(B25-IF(F25="Grade K",0,VALUE(SUBSTITUTE(F25,"Grade ","")))<=0,"On/above grade",IF(B25-IF(F25="Grade K",0,VALUE(SUBSTITUTE(F25,"Grade ","")))=1,"1 grade below",IF(B25-IF(F25="Grade K",0,VALUE(SUBSTITUTE(F25,"Grade ","")))=2,"2 grades below","3+ grades below")))) -> 2 grades below | H25: Completed | I25: 540 | J25: Grade 4 | K25: =IF(J25="","",IF(B25-IF(J25="Grade K",0,VALUE(SUBSTITUTE(J25,"Grade ","")))<=0,"On/above grade",IF(B25-IF(J25="Grade K",0,VALUE(SUBSTITUTE(J25,"Grade ","")))=1,"1 grade below",IF(B25-IF(J25="Grade K",0,VALUE(SUBSTITUTE(J25,"Grade ","")))=2,"2 grades below","3+ grades below")))) -> 1 grade below | L25: Present | M25: Present | N25: Present
A26: =IFERROR(INDEX(Roster!$A$3:$A$148,MATCH(24,Roster!$D$3:$D$148,0)),"") -> S-051 | B26: =IFERROR(INDEX(Roster!$B$3:$B$148,MATCH(24,Roster!$D$3:$D$148,0)),"") -> 5 | C26: =IF(A26="","",IF(ROW()-3<$F$1,"Group A",IF(ROW()-3<2*$F$1,"Group B","Group C"))) -> Group A | D26: Completed | E26: 473 | F26: Grade 3 | G26: =IF(F26="","",IF(B26-IF(F26="Grade K",0,VALUE(SUBSTITUTE(F26,"Grade ","")))<=0,"On/above grade",IF(B26-IF(F26="Grade K",0,VALUE(SUBSTITUTE(F26,"Grade ","")))=1,"1 grade below",IF(B26-IF(F26="Grade K",0,VALUE(SUBSTITUTE(F26,"Grade ","")))=2,"2 grades below","3+ grades below")))) -> 2 grades below | H26: Completed | I26: 487 | J26: Grade 3 | K26: =IF(J26="","",IF(B26-IF(J26="Grade K",0,VALUE(SUBSTITUTE(J26,"Grade ","")))<=0,"On/above grade",IF(B26-IF(J26="Grade K",0,VALUE(SUBSTITUTE(J26,"Grade ","")))=1,"1 grade below",IF(B26-IF(J26="Grade K",0,VALUE(SUBSTITUTE(J26,"Grade ","")))=2,"2 grades below","3+ grades below")))) -> 2 grades below | L26: Absent | M26: Present | N26: Present
A27: =IFERROR(INDEX(Roster!$A$3:$A$148,MATCH(25,Roster!$D$3:$D$148,0)),"") -> S-054 | B27: =IFERROR(INDEX(Roster!$B$3:$B$148,MATCH(25,Roster!$D$3:$D$148,0)),"") -> 5 | C27: =IF(A27="","",IF(ROW()-3<$F$1,"Group A",IF(ROW()-3<2*$F$1,"Group B","Group C"))) -> Group A | D27: Absent | G27: =IF(F27="","",IF(B27-IF(F27="Grade K",0,VALUE(SUBSTITUTE(F27,"Grade ","")))<=0,"On/above grade",IF(B27-IF(F27="Grade K",0,VALUE(SUBSTITUTE(F27,"Grade ","")))=1,"1 grade below",IF(B27-IF(F27="Grade K",0,VALUE(SUBSTITUTE(F27,"Grade ","")))=2,"2 grades below","3+ grades below")))) | H27: Completed | I27: 401 | J27: Grade 1 | K27: =IF(J27="","",IF(B27-IF(J27="Grade K",0,VALUE(SUBSTITUTE(J27,"Grade ","")))<=0,"On/above grade",IF(B27-IF(J27="Grade K",0,VALUE(SUBSTITUTE(J27,"Grade ","")))=1,"1 grade below",IF(B27-IF(J27="Grade K",0,VALUE(SUBSTITUTE(J27,"Grade ","")))=2,"2 grades below","3+ grades below")))) -> 3+ grades below | L27: Present | M27: Present | N27: Completed All
A28: =IFERROR(INDEX(Roster!$A$3:$A$148,MATCH(26,Roster!$D$3:$D$148,0)),"") -> S-055 | B28: =IFERROR(INDEX(Roster!$B$3:$B$148,MATCH(26,Roster!$D$3:$D$148,0)),"") -> 5 | C28: =IF(A28="","",IF(ROW()-3<$F$1,"Group A",IF(ROW()-3<2*$F$1,"Group B","Group C"))) -> Group B | D28: Completed | E28: 561 | F28: Grade 5 | G28: =IF(F28="","",IF(B28-IF(F28="Grade K",0,VALUE(SUBSTITUTE(F28,"Grade ","")))<=0,"On/above grade",IF(B28-IF(F28="Grade K",0,VALUE(SUBSTITUTE(F28,"Grade ","")))=1,"1 grade below",IF(B28-IF(F28="Grade K",0,VALUE(SUBSTITUTE(F28,"Grade ","")))=2,"2 grades below","3+ grades below")))) -> On/above grade | H28: Completed | I28: 477 | J28: Grade 3 | K28: =IF(J28="","",IF(B28-IF(J28="Grade K",0,VALUE(SUBSTITUTE(J28,"Grade ","")))<=0,"On/above grade",IF(B28-IF(J28="Grade K",0,VALUE(SUBSTITUTE(J28,"Grade ","")))=1,"1 grade below",IF(B28-IF(J28="Grade K",0,VALUE(SUBSTITUTE(J28,"Grade ","")))=2,"2 grades below","3+ grades below")))) -> 2 grades below | L28: Present | M28: Completed All | N28: Present
A29: =IFERROR(INDEX(Roster!$A$3:$A$148,MATCH(27,Roster!$D$3:$D$148,0)),"") -> S-056 | B29: =IFERROR(INDEX(Roster!$B$3:$B$148,MATCH(27,Roster!$D$3:$D$148,0)),"") -> 8 | C29: =IF(A29="","",IF(ROW()-3<$F$1,"Group A",IF(ROW()-3<2*$F$1,"Group B","Group C"))) -> Group B | D29: Completed | E29: 593 | F29: Grade 6 | G29: =IF(F29="","",IF(B29-IF(F29="Grade K",0,VALUE(SUBSTITUTE(F29,"Grade ","")))<=0,"On/above grade",IF(B29-IF(F29="Grade K",0,VALUE(SUBSTITUTE(F29,"Grade ","")))=1,"1 grade below",IF(B29-IF(F29="Grade K",0,VALUE(SUBSTITUTE(F29,"Grade ","")))=2,"2 grades below","3+ grades below")))) -> 2 grades below | H29: Completed | I29: 626 | J29: Grade 7 | K29: =IF(J29="","",IF(B29-IF(J29="Grade K",0,VALUE(SUBSTITUTE(J29,"Grade ","")))<=0,"On/above grade",IF(B29-IF(J29="Grade K",0,VALUE(SUBSTITUTE(J29,"Grade ","")))=1,"1 grade below",IF(B29-IF(J29="Grade K",0,VALUE(SUBSTITUTE(J29,"Grade ","")))=2,"2 grades below","3+ grades below")))) -> 1 grade below | L29: Present | M29: Completed All | N29: Present
A30: =IFERROR(INDEX(Roster!$A$3:$A$148,MATCH(28,Roster!$D$3:$D$148,0)),"") -> S-057 | B30: =IFERROR(INDEX(Roster!$B$3:$B$148,MATCH(28,Roster!$D$3:$D$148,0)),"") -> 8 | C30: =IF(A30="","",IF(ROW()-3<$F$1,"Group A",IF(ROW()-3<2*$F$1,"Group B","Group C"))) -> Group B | D30: Completed | E30: 642 | F30: Grade 8 | G30: =IF(F30="","",IF(B30-IF(F30="Grade K",0,VALUE(SUBSTITUTE(F30,"Grade ","")))<=0,"On/above grade",IF(B30-IF(F30="Grade K",0,VALUE(SUBSTITUTE(F30,"Grade ","")))=1,"1 grade below",IF(B30-IF(F30="Grade K",0,VALUE(SUBSTITUTE(F30,"Grade ","")))=2,"2 grades below","3+ grades below")))) -> On/above grade | H30: Completed | I30: 606 | J30: Grade 6 | K30: =IF(J30="","",IF(B30-IF(J30="Grade K",0,VALUE(SUBSTITUTE(J30,"Grade ","")))<=0,"On/above grade",IF(B30-IF(J30="Grade K",0,VALUE(SUBSTITUTE(J30,"Grade ","")))=1,"1 grade below",IF(B30-IF(J30="Grade K",0,VALUE(SUBSTITUTE(J30,"Grade ","")))=2,"2 grades below","3+ grades below")))) -> 2 grades below | L30: Present | M30: Present | N30: Present
A31: =IFERROR(INDEX(Roster!$A$3:$A$148,MATCH(29,Roster!$D$3:$D$148,0)),"") -> S-062 | B31: =IFERROR(INDEX(Roster!$B$3:$B$148,MATCH(29,Roster!$D$3:$D$148,0)),"") -> 8 | C31: =IF(A31="","",IF(ROW()-3<$F$1,"Group A",IF(ROW()-3<2*$F$1,"Group B","Group C"))) -> Group B | D31: Completed | E31: 658 | F31: Grade 8 | G31: =IF(F31="","",IF(B31-IF(F31="Grade K",0,VALUE(SUBSTITUTE(F31,"Grade ","")))<=0,"On/above grade",IF(B31-IF(F31="Grade K",0,VALUE(SUBSTITUTE(F31,"Grade ","")))=1,"1 grade below",IF(B31-IF(F31="Grade K",0,VALUE(SUBSTITUTE(F31,"Grade ","")))=2,"2 grades below","3+ grades below")))) -> On/above grade | H31: Absent | K31: =IF(J31="","",IF(B31-IF(J31="Grade K",0,VALUE(SUBSTITUTE(J31,"Grade ","")))<=0,"On/above grade",IF(B31-IF(J31="Grade K",0,VALUE(SUBSTITUTE(J31,"Grade ","")))=1,"1 grade below",IF(B31-IF(J31="Grade K",0,VALUE(SUBSTITUTE(J31,"Grade ","")))=2,"2 grades below","3+ grades below")))) | L31: Present | M31: Present | N31: Absent
A32: =IFERROR(INDEX(Roster!$A$3:$A$148,MATCH(30,Roster!$D$3:$D$148,0)),"") -> S-064 | B32: =IFERROR(INDEX(Roster!$B$3:$B$148,MATCH(30,Roster!$D$3:$D$148,0)),"") -> 8 | C32: =IF(A32="","",IF(ROW()-3<$F$1,"Group A",IF(ROW()-3<2*$F$1,"Group B","Group C"))) -> Group B | D32: Completed | E32: 590 | F32: Grade 6 | G32: =IF(F32="","",IF(B32-IF(F32="Grade K",0,VALUE(SUBSTITUTE(F32,"Grade ","")))<=0,"On/above grade",IF(B32-IF(F32="Grade K",0,VALUE(SUBSTITUTE(F32,"Grade ","")))=1,"1 grade below",IF(B32-IF(F32="Grade K",0,VALUE(SUBSTITUTE(F32,"Grade ","")))=2,"2 grades below","3+ grades below")))) -> 2 grades below | H32: Completed | I32: 627 | J32: Grade 7 | K32: =IF(J32="","",IF(B32-IF(J32="Grade K",0,VALUE(SUBSTITUTE(J32,"Grade ","")))<=0,"On/above grade",IF(B32-IF(J32="Grade K",0,VALUE(SUBSTITUTE(J32,"Grade ","")))=1,"1 grade below",IF(B32-IF(J32="Grade K",0,VALUE(SUBSTITUTE(J32,"Grade ","")))=2,"2 grades below","3+ grades below")))) -> 1 grade below | L32: Present | M32: Completed All | N32: Present
A33: =IFERROR(INDEX(Roster!$A$3:$A$148,MATCH(31,Roster!$D$3:$D$148,0)),"") -> S-065 | B33: =IFERROR(INDEX(Roster!$B$3:$B$148,MATCH(31,Roster!$D$3:$D$148,0)),"") -> 8 | C33: =IF(A33="","",IF(ROW()-3<$F$1,"Group A",IF(ROW()-3<2*$F$1,"Group B","Group C"))) -> Group B | D33: Completed | E33: 546 | F33: Grade 5 | G33: =IF(F33="","",IF(B33-IF(F33="Grade K",0,VALUE(SUBSTITUTE(F33,"Grade ","")))<=0,"On/above grade",IF(B33-IF(F33="Grade K",0,VALUE(SUBSTITUTE(F33,"Grade ","")))=1,"1 grade below",IF(B33-IF(F33="Grade K",0,VALUE(SUBSTITUTE(F33,"Grade ","")))=2,"2 grades below","3+ grades below")))) -> 3+ grades below | H33: Completed | I33: 628 | J33: Grade 7 | K33: =IF(J33="","",IF(B33-IF(J33="Grade K",0,VALUE(SUBSTITUTE(J33,"Grade ","")))<=0,"On/above grade",IF(B33-IF(J33="Grade K",0,VALUE(SUBSTITUTE(J33,"Grade ","")))=1,"1 grade below",IF(B33-IF(J33="Grade K",0,VALUE(SUBSTITUTE(J33,"Grade ","")))=2,"2 grades below","3+ grades below")))) -> 1 grade below | L33: Present | M33: Present | N33: Present
A34: =IFERROR(INDEX(Roster!$A$3:$A$148,MATCH(32,Roster!$D$3:$D$148,0)),"") -> S-066 | B34: =IFERROR(INDEX(Roster!$B$3:$B$148,MATCH(32,Roster!$D$3:$D$148,0)),"") -> 5 | C34: =IF(A34="","",IF(ROW()-3<$F$1,"Group A",IF(ROW()-3<2*$F$1,"Group B","Group C"))) -> Group B | D34: Completed | E34: 540 | F34: Grade 5 | G34: =IF(F34="","",IF(B34-IF(F34="Grade K",0,VALUE(SUBSTITUTE(F34,"Grade ","")))<=0,"On/above grade",IF(B34-IF(F34="Grade K",0,VALUE(SUBSTITUTE(F34,"Grade ","")))=1,"1 grade below",IF(B34-IF(F34="Grade K",0,VALUE(SUBSTITUTE(F34,"Grade ","")))=2,"2 grades below","3+ grades below")))) -> On/above grade | H34: Completed | I34: 505 | J34: Grade 3 | K34: =IF(J34="","",IF(B34-IF(J34="Grade K",0,VALUE(SUBSTITUTE(J34,"Grade ","")))<=0,"On/above grade",IF(B34-IF(J34="Grade K",0,VALUE(SUBSTITUTE(J34,"Grade ","")))=1,"1 grade below",IF(B34-IF(J34="Grade K",0,VALUE(SUBSTITUTE(J34,"Grade ","")))=2,"2 grades below","3+ grades below")))) -> 2 grades below | L34: Absent | M34: Present | N34: Present
A35: =IFERROR(INDEX(Roster!$A$3:$A$148,MATCH(33,Roster!$D$3:$D$148,0)),"") -> S-067 | B35: =IFERROR(INDEX(Roster!$B$3:$B$148,MATCH(33,Roster!$D$3:$D$148,0)),"") -> 8 | C35: =IF(A35="","",IF(ROW()-3<$F$1,"Group A",IF(ROW()-3<2*$F$1,"Group B","Group C"))) -> Group B | D35: Completed | E35: 621 | F35: Grade 7 | G35: =IF(F35="","",IF(B35-IF(F35="Grade K",0,VALUE(SUBSTITUTE(F35,"Grade ","")))<=0,"On/above grade",IF(B35-IF(F35="Grade K",0,VALUE(SUBSTITUTE(F35,"Grade ","")))=1,"1 grade below",IF(B35-IF(F35="Grade K",0,VALUE(SUBSTITUTE(F35,"Grade ","")))=2,"2 grades below","3+ grades below")))) -> 1 grade below | H35: Completed | I35: 650 | J35: Grade 8 | K35: =IF(J35="","",IF(B35-IF(J35="Grade K",0,VALUE(SUBSTITUTE(J35,"Grade ","")))<=0,"On/above grade",IF(B35-IF(J35="Grade K",0,VALUE(SUBSTITUTE(J35,"Grade ","")))=1,"1 grade below",IF(B35-IF(J35="Grade K",0,VALUE(SUBSTITUTE(J35,"Grade ","")))=2,"2 grades below","3+ grades below")))) -> On/above grade | L35: Completed All | M35: Present | N35: Completed All
A36: =IFERROR(INDEX(Roster!$A$3:$A$148,MATCH(34,Roster!$D$3:$D$148,0)),"") -> S-068 | B36: =IFERROR(INDEX(Roster!$B$3:$B$148,MATCH(34,Roster!$D$3:$D$148,0)),"") -> 5 | C36: =IF(A36="","",IF(ROW()-3<$F$1,"Group A",IF(ROW()-3<2*$F$1,"Group B","Group C"))) -> Group B | D36: Started | G36: =IF(F36="","",IF(B36-IF(F36="Grade K",0,VALUE(SUBSTITUTE(F36,"Grade ","")))<=0,"On/above grade",IF(B36-IF(F36="Grade K",0,VALUE(SUBSTITUTE(F36,"Grade ","")))=1,"1 grade below",IF(B36-IF(F36="Grade K",0,VALUE(SUBSTITUTE(F36,"Grade ","")))=2,"2 grades below","3+ grades below")))) | H36: Completed | I36: 476 | J36: Grade 3 | K36: =IF(J36="","",IF(B36-IF(J36="Grade K",0,VALUE(SUBSTITUTE(J36,"Grade ","")))<=0,"On/above grade",IF(B36-IF(J36="Grade K",0,VALUE(SUBSTITUTE(J36,"Grade ","")))=1,"1 grade below",IF(B36-IF(J36="Grade K",0,VALUE(SUBSTITUTE(J36,"Grade ","")))=2,"2 grades below","3+ grades below")))) -> 2 grades below | L36: Present | M36: Completed All | N36: Present
A37: =IFERROR(INDEX(Roster!$A$3:$A$148,MATCH(35,Roster!$D$3:$D$148,0)),"") -> S-070 | B37: =IFERROR(INDEX(Roster!$B$3:$B$148,MATCH(35,Roster!$D$3:$D$148,0)),"") -> 8 | C37: =IF(A37="","",IF(ROW()-3<$F$1,"Group A",IF(ROW()-3<2*$F$1,"Group B","Group C"))) -> Group B | D37: Completed | E37: 605 | F37: Grade 7 | G37: =IF(F37="","",IF(B37-IF(F37="Grade K",0,VALUE(SUBSTITUTE(F37,"Grade ","")))<=0,"On/above grade",IF(B37-IF(F37="Grade K",0,VALUE(SUBSTITUTE(F37,"Grade ","")))=1,"1 grade below",IF(B37-IF(F37="Grade K",0,VALUE(SUBSTITUTE(F37,"Grade ","")))=2,"2 grades below","3+ grades below")))) -> 1 grade below | H37: Started | K37: =IF(J37="","",IF(B37-IF(J37="Grade K",0,VALUE(SUBSTITUTE(J37,"Grade ","")))<=0,"On/above grade",IF(B37-IF(J37="Grade K",0,VALUE(SUBSTITUTE(J37,"Grade ","")))=1,"1 grade below",IF(B37-IF(J37="Grade K",0,VALUE(SUBSTITUTE(J37,"Grade ","")))=2,"2 grades below","3+ grades below")))) | L37: Absent | M37: Absent | N37: Present
A38: =IFERROR(INDEX(Roster!$A$3:$A$148,MATCH(36,Roster!$D$3:$D$148,0)),"") -> S-071 | B38: =IFERROR(INDEX(Roster!$B$3:$B$148,MATCH(36,Roster!$D$3:$D$148,0)),"") -> 5 | C38: =IF(A38="","",IF(ROW()-3<$F$1,"Group A",IF(ROW()-3<2*$F$1,"Group B","Group C"))) -> Group B | D38: Completed | E38: 414 | F38: Grade 1 | G38: =IF(F38="","",IF(B38-IF(F38="Grade K",0,VALUE(SUBSTITUTE(F38,"Grade ","")))<=0,"On/above grade",IF(B38-IF(F38="Grade K",0,VALUE(SUBSTITUTE(F38,"Grade ","")))=1,"1 grade below",IF(B38-IF(F38="Grade K",0,VALUE(SUBSTITUTE(F38,"Grade ","")))=2,"2 grades below","3+ grades below")))) -> 3+ grades below | H38: Completed | I38: 501 | J38: Grade 3 | K38: =IF(J38="","",IF(B38-IF(J38="Grade K",0,VALUE(SUBSTITUTE(J38,"Grade ","")))<=0,"On/above grade",IF(B38-IF(J38="Grade K",0,VALUE(SUBSTITUTE(J38,"Grade ","")))=1,"1 grade below",IF(B38-IF(J38="Grade K",0,VALUE(SUBSTITUTE(J38,"Grade ","")))=2,"2 grades below","3+ grades below")))) -> 2 grades below | L38: Present | M38: Present | N38: Present
A39: =IFERROR(INDEX(Roster!$A$3:$A$148,MATCH(37,Roster!$D$3:$D$148,0)),"") -> S-072 | B39: =IFERROR(INDEX(Roster!$B$3:$B$148,MATCH(37,Roster!$D$3:$D$148,0)),"") -> 5 | C39: =IF(A39="","",IF(ROW()-3<$F$1,"Group A",IF(ROW()-3<2*$F$1,"Group B","Group C"))) -> Group B | D39: Completed | E39: 542 | F39: Grade 5 | G39: =IF(F39="","",IF(B39-IF(F39="Grade K",0,VALUE(SUBSTITUTE(F39,"Grade ","")))<=0,"On/above grade",IF(B39-IF(F39="Grade K",0,VALUE(SUBSTITUTE(F39,"Grade ","")))=1,"1 grade below",IF(B39-IF(F39="Grade K",0,VALUE(SUBSTITUTE(F39,"Grade ","")))=2,"2 grades below","3+ grades below")))) -> On/above grade | H39: Completed | I39: 396 | J39: Grade 1 | K39: =IF(J39="","",IF(B39-IF(J39="Grade K",0,VALUE(SUBSTITUTE(J39,"Grade ","")))<=0,"On/above grade",IF(B39-IF(J39="Grade K",0,VALUE(SUBSTITUTE(J39,"Grade ","")))=1,"1 grade below",IF(B39-IF(J39="Grade K",0,VALUE(SUBSTITUTE(J39,"Grade ","")))=2,"2 grades below","3+ grades below")))) -> 3+ grades below | L39: Present | M39: Present | N39: Present
A40: =IFERROR(INDEX(Roster!$A$3:$A$148,MATCH(38,Roster!$D$3:$D$148,0)),"") -> S-074 | B40: =IFERROR(INDEX(Roster!$B$3:$B$148,MATCH(38,Roster!$D$3:$D$148,0)),"") -> 5 | C40: =IF(A40="","",IF(ROW()-3<$F$1,"Group A",IF(ROW()-3<2*$F$1,"Group B","Group C"))) -> Group B | D40: Completed | E40: 512 | F40: Grade 4 | G40: =IF(F40="","",IF(B40-IF(F40="Grade K",0,VALUE(SUBSTITUTE(F40,"Grade ","")))<=0,"On/above grade",IF(B40-IF(F40="Grade K",0,VALUE(SUBSTITUTE(F40,"Grade ","")))=1,"1 grade below",IF(B40-IF(F40="Grade K",0,VALUE(SUBSTITUTE(F40,"Grade ","")))=2,"2 grades below","3+ grades below")))) -> 1 grade below | H40: Completed | I40: 551 | J40: Grade 5 | K40: =IF(J40="","",IF(B40-IF(J40="Grade K",0,VALUE(SUBSTITUTE(J40,"Grade ","")))<=0,"On/above grade",IF(B40-IF(J40="Grade K",0,VALUE(SUBSTITUTE(J40,"Grade ","")))=1,"1 grade below",IF(B40-IF(J40="Grade K",0,VALUE(SUBSTITUTE(J40,"Grade ","")))=2,"2 grades below","3+ grades below")))) -> On/above grade | L40: Present | M40: Absent | N40: Present
...

Sheet Week 2
A1: Week 2 | C1: Students: | D1: =COUNTIF(A3:A83,"S-*") -> 71 | E1: Per group: | F1: =ROUNDUP(D1/3,0) -> 24
A2: Student ID | B2: Grade | C2: Group | D2: ELA Status | E2: ELA Score | F2: ELA Placement | G2: ELA vs. Grade | H2: Math Status | I2: Math Score | J2: Math Placement | K2: Math vs. Grade | L2: Mon | M2: Tue | N2: Wed | O2: Notes
A3: =IFERROR(INDEX(Roster!$A$3:$A$148,MATCH(1,Roster!$E$3:$E$148,0)),"") -> S-004 | B3: =IFERROR(INDEX(Roster!$B$3:$B$148,MATCH(1,Roster!$E$3:$E$148,0)),"") -> 5 | C3: =IF(A3="","",IF(ROW()-3<$F$1,"Group A",IF(ROW()-3<2*$F$1,"Group B","Group C"))) -> Group A | D3: Completed | E3: 552 | F3: Grade 5 | G3: =IF(F3="","",IF(B3-IF(F3="Grade K",0,VALUE(SUBSTITUTE(F3,"Grade ","")))<=0,"On/above grade",IF(B3-IF(F3="Grade K",0,VALUE(SUBSTITUTE(F3,"Grade ","")))=1,"1 grade below",IF(B3-IF(F3="Grade K",0,VALUE(SUBSTITUTE(F3,"Grade ","")))=2,"2 grades below","3+ grades below")))) -> On/above grade | H3: Completed | I3: 530 | J3: Grade 4 | K3: =IF(J3="","",IF(B3-IF(J3="Grade K",0,VALUE(SUBSTITUTE(J3,"Grade ","")))<=0,"On/above grade",IF(B3-IF(J3="Grade K",0,VALUE(SUBSTITUTE(J3,"Grade ","")))=1,"1 grade below",IF(B3-IF(J3="Grade K",0,VALUE(SUBSTITUTE(J3,"Grade ","")))=2,"2 grades below","3+ grades below")))) -> 1 grade below | L3: Completed All | M3: Present | N3: Completed All
A4: =IFERROR(INDEX(Roster!$A$3:$A$148,MATCH(2,Roster!$E$3:$E$148,0)),"") -> S-005 | B4: =IFERROR(INDEX(Roster!$B$3:$B$148,MATCH(2,Roster!$E$3:$E$148,0)),"") -> 5 | C4: =IF(A4="","",IF(ROW()-3<$F$1,"Group A",IF(ROW()-3<2*$F$1,"Group B","Group C"))) -> Group A | D4: Completed | E4: 501 | F4: Grade 4 | G4: =IF(F4="","",IF(B4-IF(F4="Grade K",0,VALUE(SUBSTITUTE(F4,"Grade ","")))<=0,"On/above grade",IF(B4-IF(F4="Grade K",0,VALUE(SUBSTITUTE(F4,"Grade ","")))=1,"1 grade below",IF(B4-IF(F4="Grade K",0,VALUE(SUBSTITUTE(F4,"Grade ","")))=2,"2 grades below","3+ grades below")))) -> 1 grade below | H4: Completed | I4: 505 | J4: Grade 4 | K4: =IF(J4="","",IF(B4-IF(J4="Grade K",0,VALUE(SUBSTITUTE(J4,"Grade ","")))<=0,"On/above grade",IF(B4-IF(J4="Grade K",0,VALUE(SUBSTITUTE(J4,"Grade ","")))=1,"1 grade below",IF(B4-IF(J4="Grade K",0,VALUE(SUBSTITUTE(J4,"Grade ","")))=2,"2 grades below","3+ grades below")))) -> 1 grade below | L4: Completed All | M4: Present | N4: Present
A5: =IFERROR(INDEX(Roster!$A$3:$A$148,MATCH(3,Roster!$E$3:$E$148,0)),"") -> S-007 | B5: =IFERROR(INDEX(Roster!$B$3:$B$148,MATCH(3,Roster!$E$3:$E$148,0)),"") -> 5 | C5: =IF(A5="","",IF(ROW()-3<$F$1,"Group A",IF(ROW()-3<2*$F$1,"Group B","Group C"))) -> Group A | D5: Completed | E5: 519 | F5: Grade 4 | G5: =IF(F5="","",IF(B5-IF(F5="Grade K",0,VALUE(SUBSTITUTE(F5,"Grade ","")))<=0,"On/above grade",IF(B5-IF(F5="Grade K",0,VALUE(SUBSTITUTE(F5,"Grade ","")))=1,"1 grade below",IF(B5-IF(F5="Grade K",0,VALUE(SUBSTITUTE(F5,"Grade ","")))=2,"2 grades below","3+ grades below")))) -> 1 grade below | H5: Completed | I5: 535 | J5: Grade 4 | K5: =IF(J5="","",IF(B5-IF(J5="Grade K",0,VALUE(SUBSTITUTE(J5,"Grade ","")))<=0,"On/above grade",IF(B5-IF(J5="Grade K",0,VALUE(SUBSTITUTE(J5,"Grade ","")))=1,"1 grade below",IF(B5-IF(J5="Grade K",0,VALUE(SUBSTITUTE(J5,"Grade ","")))=2,"2 grades below","3+ grades below")))) -> 1 grade below | L5: Present | M5: Present | N5: Completed All
A6: =IFERROR(INDEX(Roster!$A$3:$A$148,MATCH(4,Roster!$E$3:$E$148,0)),"") -> S-008 | B6: =IFERROR(INDEX(Roster!$B$3:$B$148,MATCH(4,Roster!$E$3:$E$148,0)),"") -> 8 | C6: =IF(A6="","",IF(ROW()-3<$F$1,"Group A",IF(ROW()-3<2*$F$1,"Group B","Group C"))) -> Group A | D6: Completed | E6: 576 | F6: Grade 6 | G6: =IF(F6="","",IF(B6-IF(F6="Grade K",0,VALUE(SUBSTITUTE(F6,"Grade ","")))<=0,"On/above grade",IF(B6-IF(F6="Grade K",0,VALUE(SUBSTITUTE(F6,"Grade ","")))=1,"1 grade below",IF(B6-IF(F6="Grade K",0,VALUE(SUBSTITUTE(F6,"Grade ","")))=2,"2 grades below","3+ grades below")))) -> 2 grades below | H6: Completed | I6: 577 | J6: Grade 6 | K6: =IF(J6="","",IF(B6-IF(J6="Grade K",0,VALUE(SUBSTITUTE(J6,"Grade ","")))<=0,"On/above grade",IF(B6-IF(J6="Grade K",0,VALUE(SUBSTITUTE(J6,"Grade ","")))=1,"1 grade below",IF(B6-IF(J6="Grade K",0,VALUE(SUBSTITUTE(J6,"Grade ","")))=2,"2 grades below","3+ grades below")))) -> 2 grades below | L6: Completed All | M6: Present | N6: Present
A7: =IFERROR(INDEX(Roster!$A$3:$A$148,MATCH(5,Roster!$E$3:$E$148,0)),"") -> S-010 | B7: =IFERROR(INDEX(Roster!$B$3:$B$148,MATCH(5,Roster!$E$3:$E$148,0)),"") -> 5 | C7: =IF(A7="","",IF(ROW()-3<$F$1,"Group A",IF(ROW()-3<2*$F$1,"Group B","Group C"))) -> Group A | D7: Completed | E7: 571 | F7: Grade 5 | G7: =IF(F7="","",IF(B7-IF(F7="Grade K",0,VALUE(SUBSTITUTE(F7,"Grade ","")))<=0,"On/above grade",IF(B7-IF(F7="Grade K",0,VALUE(SUBSTITUTE(F7,"Grade ","")))=1,"1 grade below",IF(B7-IF(F7="Grade K",0,VALUE(SUBSTITUTE(F7,"Grade ","")))=2,"2 grades below","3+ grades below")))) -> On/above grade | H7: Completed | I7: 478 | J7: Grade 3 | K7: =IF(J7="","",IF(B7-IF(J7="Grade K",0,VALUE(SUBSTITUTE(J7,"Grade ","")))<=0,"On/above grade",IF(B7-IF(J7="Grade K",0,VALUE(SUBSTITUTE(J7,"Grade ","")))=1,"1 grade below",IF(B7-IF(J7="Grade K",0,VALUE(SUBSTITUTE(J7,"Grade ","")))=2,"2 grades below","3+ grades below")))) -> 2 grades below | L7: Absent | M7: Present | N7: Completed All
A8: =IFERROR(INDEX(Roster!$A$3:$A$148,MATCH(6,Roster!$E$3:$E$148,0)),"") -> S-012 | B8: =IFERROR(INDEX(Roster!$B$3:$B$148,MATCH(6,Roster!$E$3:$E$148,0)),"") -> 8 | C8: =IF(A8="","",IF(ROW()-3<$F$1,"Group A",IF(ROW()-3<2*$F$1,"Group B","Group C"))) -> Group A | D8: Absent | G8: =IF(F8="","",IF(B8-IF(F8="Grade K",0,VALUE(SUBSTITUTE(F8,"Grade ","")))<=0,"On/above grade",IF(B8-IF(F8="Grade K",0,VALUE(SUBSTITUTE(F8,"Grade ","")))=1,"1 grade below",IF(B8-IF(F8="Grade K",0,VALUE(SUBSTITUTE(F8,"Grade ","")))=2,"2 grades below","3+ grades below")))) | H8: Completed | I8: 525 | J8: Grade 4 | K8: =IF(J8="","",IF(B8-IF(J8="Grade K",0,VALUE(SUBSTITUTE(J8,"Grade ","")))<=0,"On/above grade",IF(B8-IF(J8="Grade K",0,VALUE(SUBSTITUTE(J8,"Grade ","")))=1,"1 grade below",IF(B8-IF(J8="Grade K",0,VALUE(SUBSTITUTE(J8,"Grade ","")))=2,"2 grades below","3+ grades below")))) -> 3+ grades below | L8: Present | M8: Present | N8: Present
A9: =IFERROR(INDEX(Roster!$A$3:$A$148,MATCH(7,Roster!$E$3:$E$148,0)),"") -> S-014 | B9: =IFERROR(INDEX(Roster!$B$3:$B$148,MATCH(7,Roster!$E$3:$E$148,0)),"") -> 8 | C9: =IF(A9="","",IF(ROW()-3<$F$1,"Group A",IF(ROW()-3<2*$F$1,"Group B","Group C"))) -> Group A | D9: Completed | E9: 659 | F9: Grade 8 | G9: =IF(F9="","",IF(B9-IF(F9="Grade K",0,VALUE(SUBSTITUTE(F9,"Grade ","")))<=0,"On/above grade",IF(B9-IF(F9="Grade K",0,VALUE(SUBSTITUTE(F9,"Grade ","")))=1,"1 grade below",IF(B9-IF(F9="Grade K",0,VALUE(SUBSTITUTE(F9,"Grade ","")))=2,"2 grades below","3+ grades below")))) -> On/above grade | H9: Absent | K9: =IF(J9="","",IF(B9-IF(J9="Grade K",0,VALUE(SUBSTITUTE(J9,"Grade ","")))<=0,"On/above grade",IF(B9-IF(J9="Grade K",0,VALUE(SUBSTITUTE(J9,"Grade ","")))=1,"1 grade below",IF(B9-IF(J9="Grade K",0,VALUE(SUBSTITUTE(J9,"Grade ","")))=2,"2 grades below","3+ grades below")))) | L9: Present | M9: Completed All | N9: Present
A10: =IFERROR(INDEX(Roster!$A$3:$A$148,MATCH(8,Roster!$E$3:$E$148,0)),"") -> S-015 | B10: =IFERROR(INDEX(Roster!$B$3:$B$148,MATCH(8,Roster!$E$3:$E$148,0)),"") -> 8 | C10: =IF(A10="","",IF(ROW()-3<$F$1,"Group A",IF(ROW()-3<2*$F$1,"Group B","Group C"))) -> Group A | D10: Completed | E10: 649 | F10: Grade 8 | G10: =IF(F10="","",IF(B10-IF(F10="Grade K",0,VALUE(SUBSTITUTE(F10,"Grade ","")))<=0,"On/above grade",IF(B10-IF(F10="Grade K",0,VALUE(SUBSTITUTE(F10,"Grade ","")))=1,"1 grade below",IF(B10-IF(F10="Grade K",0,VALUE(SUBSTITUTE(F10,"Grade ","")))=2,"2 grades below","3+ grades below")))) -> On/above grade | H10: Completed | I10: 680 | J10: Grade 8 | K10: =IF(J10="","",IF(B10-IF(J10="Grade K",0,VALUE(SUBSTITUTE(J10,"Grade ","")))<=0,"On/above grade",IF(B10-IF(J10="Grade K",0,VALUE(SUBSTITUTE(J10,"Grade ","")))=1,"1 grade below",IF(B10-IF(J10="Grade K",0,VALUE(SUBSTITUTE(J10,"Grade ","")))=2,"2 grades below","3+ grades below")))) -> On/above grade | L10: Completed All | M10: Present | N10: Present
A11: =IFERROR(INDEX(Roster!$A$3:$A$148,MATCH(9,Roster!$E$3:$E$148,0)),"") -> S-016 | B11: =IFERROR(INDEX(Roster!$B$3:$B$148,MATCH(9,Roster!$E$3:$E$148,0)),"") -> 8 | C11: =IF(A11="","",IF(ROW()-3<$F$1,"Group A",IF(ROW()-3<2*$F$1,"Group B","Group C"))) -> Group A | D11: Completed | E11: 575 | F11: Grade 6 | G11: =IF(F11="","",IF(B11-IF(F11="Grade K",0,VALUE(SUBSTITUTE(F11,"Grade ","")))<=0,"On/above grade",IF(B11-IF(F11="Grade K",0,VALUE(SUBSTITUTE(F11,"Grade ","")))=1,"1 grade below",IF(B11-IF(F11="Grade K",0,VALUE(SUBSTITUTE(F11,"Grade ","")))=2,"2 grades below","3+ grades below")))) -> 2 grades below | H11: Completed | I11: 647 | J11: Grade 8 | K11: =IF(J11="","",IF(B11-IF(J11="Grade K",0,VALUE(SUBSTITUTE(J11,"Grade ","")))<=0,"On/above grade",IF(B11-IF(J11="Grade K",0,VALUE(SUBSTITUTE(J11,"Grade ","")))=1,"1 grade below",IF(B11-IF(J11="Grade K",0,VALUE(SUBSTITUTE(J11,"Grade ","")))=2,"2 grades below","3+ grades below")))) -> On/above grade | L11: Present | M11: Completed All | N11: Present
A12: =IFERROR(INDEX(Roster!$A$3:$A$148,MATCH(10,Roster!$E$3:$E$148,0)),"") -> S-018 | B12: =IFERROR(INDEX(Roster!$B$3:$B$148,MATCH(10,Roster!$E$3:$E$148,0)),"") -> 8 | C12: =IF(A12="","",IF(ROW()-3<$F$1,"Group A",IF(ROW()-3<2*$F$1,"Group B","Group C"))) -> Group A | D12: Completed | E12: 543 | F12: Grade 5 | G12: =IF(F12="","",IF(B12-IF(F12="Grade K",0,VALUE(SUBSTITUTE(F12,"Grade ","")))<=0,"On/above grade",IF(B12-IF(F12="Grade K",0,VALUE(SUBSTITUTE(F12,"Grade ","")))=1,"1 grade below",IF(B12-IF(F12="Grade K",0,VALUE(SUBSTITUTE(F12,"Grade ","")))=2,"2 grades below","3+ grades below")))) -> 3+ grades below | H12: Completed | I12: 594 | J12: Grade 6 | K12: =IF(J12="","",IF(B12-IF(J12="Grade K",0,VALUE(SUBSTITUTE(J12,"Grade ","")))<=0,"On/above grade",IF(B12-IF(J12="Grade K",0,VALUE(SUBSTITUTE(J12,"Grade ","")))=1,"1 grade below",IF(B12-IF(J12="Grade K",0,VALUE(SUBSTITUTE(J12,"Grade ","")))=2,"2 grades below","3+ grades below")))) -> 2 grades below | L12: Present | M12: Absent | N12: Completed All
A13: =IFERROR(INDEX(Roster!$A$3:$A$148,MATCH(11,Roster!$E$3:$E$148,0)),"") -> S-019 | B13: =IFERROR(INDEX(Roster!$B$3:$B$148,MATCH(11,Roster!$E$3:$E$148,0)),"") -> 5 | C13: =IF(A13="","",IF(ROW()-3<$F$1,"Group A",IF(ROW()-3<2*$F$1,"Group B","Group C"))) -> Group A | D13: Completed | E13: 485 | F13: Grade 3 | G13: =IF(F13="","",IF(B13-IF(F13="Grade K",0,VALUE(SUBSTITUTE(F13,"Grade ","")))<=0,"On/above grade",IF(B13-IF(F13="Grade K",0,VALUE(SUBSTITUTE(F13,"Grade ","")))=1,"1 grade below",IF(B13-IF(F13="Grade K",0,VALUE(SUBSTITUTE(F13,"Grade ","")))=2,"2 grades below","3+ grades below")))) -> 2 grades below | H13: Absent | K13: =IF(J13="","",IF(B13-IF(J13="Grade K",0,VALUE(SUBSTITUTE(J13,"Grade ","")))<=0,"On/above grade",IF(B13-IF(J13="Grade K",0,VALUE(SUBSTITUTE(J13,"Grade ","")))=1,"1 grade below",IF(B13-IF(J13="Grade K",0,VALUE(SUBSTITUTE(J13,"Grade ","")))=2,"2 grades below","3+ grades below")))) | L13: Completed All | M13: Completed All | N13: Completed All
A14: =IFERROR(INDEX(Roster!$A$3:$A$148,MATCH(12,Roster!$E$3:$E$148,0)),"") -> S-020 | B14: =IFERROR(INDEX(Roster!$B$3:$B$148,MATCH(12,Roster!$E$3:$E$148,0)),"") -> 5 | C14: =IF(A14="","",IF(ROW()-3<$F$1,"Group A",IF(ROW()-3<2*$F$1,"Group B","Group C"))) -> Group A | D14: Completed | E14: 521 | F14: Grade 4 | G14: =IF(F14="","",IF(B14-IF(F14="Grade K",0,VALUE(SUBSTITUTE(F14,"Grade ","")))<=0,"On/above grade",IF(B14-IF(F14="Grade K",0,VALUE(SUBSTITUTE(F14,"Grade ","")))=1,"1 grade below",IF(B14-IF(F14="Grade K",0,VALUE(SUBSTITUTE(F14,"Grade ","")))=2,"2 grades below","3+ grades below")))) -> 1 grade below | H14: Completed | I14: 535 | J14: Grade 4 | K14: =IF(J14="","",IF(B14-IF(J14="Grade K",0,VALUE(SUBSTITUTE(J14,"Grade ","")))<=0,"On/above grade",IF(B14-IF(J14="Grade K",0,VALUE(SUBSTITUTE(J14,"Grade ","")))=1,"1 grade below",IF(B14-IF(J14="Grade K",0,VALUE(SUBSTITUTE(J14,"Grade ","")))=2,"2 grades below","3+ grades below")))) -> 1 grade below | L14: Present | M14: Present | N14: Completed All
A15: =IFERROR(INDEX(Roster!$A$3:$A$148,MATCH(13,Roster!$E$3:$E$148,0)),"") -> S-023 | B15: =IFERROR(INDEX(Roster!$B$3:$B$148,MATCH(13,Roster!$E$3:$E$148,0)),"") -> 8 | C15: =IF(A15="","",IF(ROW()-3<$F$1,"Group A",IF(ROW()-3<2*$F$1,"Group B","Group C"))) -> Group A | D15: Completed | E15: 580 | F15: Grade 6 | G15: =IF(F15="","",IF(B15-IF(F15="Grade K",0,VALUE(SUBSTITUTE(F15,"Grade ","")))<=0,"On/above grade",IF(B15-IF(F15="Grade K",0,VALUE(SUBSTITUTE(F15,"Grade ","")))=1,"1 grade below",IF(B15-IF(F15="Grade K",0,VALUE(SUBSTITUTE(F15,"Grade ","")))=2,"2 grades below","3+ grades below")))) -> 2 grades below | H15: Completed | I15: 624 | J15: Grade 7 | K15: =IF(J15="","",IF(B15-IF(J15="Grade K",0,VALUE(SUBSTITUTE(J15,"Grade ","")))<=0,"On/above grade",IF(B15-IF(J15="Grade K",0,VALUE(SUBSTITUTE(J15,"Grade ","")))=1,"1 grade below",IF(B15-IF(J15="Grade K",0,VALUE(SUBSTITUTE(J15,"Grade ","")))=2,"2 grades below","3+ grades below")))) -> 1 grade below | L15: Present | M15: Present | N15: Present
A16: =IFERROR(INDEX(Roster!$A$3:$A$148,MATCH(14,Roster!$E$3:$E$148,0)),"") -> S-025 | B16: =IFERROR(INDEX(Roster!$B$3:$B$148,MATCH(14,Roster!$E$3:$E$148,0)),"") -> 5 | C16: =IF(A16="","",IF(ROW()-3<$F$1,"Group A",IF(ROW()-3<2*$F$1,"Group B","Group C"))) -> Group A | D16: Completed | E16: 498 | F16: Grade 3 | G16: =IF(F16="","",IF(B16-IF(F16="Grade K",0,VALUE(SUBSTITUTE(F16,"Grade ","")))<=0,"On/above grade",IF(B16-IF(F16="Grade K",0,VALUE(SUBSTITUTE(F16,"Grade ","")))=1,"1 grade below",IF(B16-IF(F16="Grade K",0,VALUE(SUBSTITUTE(F16,"Grade ","")))=2,"2 grades below","3+ grades below")))) -> 2 grades below | H16: Absent | K16: =IF(J16="","",IF(B16-IF(J16="Grade K",0,VALUE(SUBSTITUTE(J16,"Grade ","")))<=0,"On/above grade",IF(B16-IF(J16="Grade K",0,VALUE(SUBSTITUTE(J16,"Grade ","")))=1,"1 grade below",IF(B16-IF(J16="Grade K",0,VALUE(SUBSTITUTE(J16,"Grade ","")))=2,"2 grades below","3+ grades below")))) | L16: Completed All | M16: Absent | N16: Present
A17: =IFERROR(INDEX(Roster!$A$3:$A$148,MATCH(15,Roster!$E$3:$E$148,0)),"") -> S-029 | B17: =IFERROR(INDEX(Roster!$B$3:$B$148,MATCH(15,Roster!$E$3:$E$148,0)),"") -> 8 | C17: =IF(A17="","",IF(ROW()-3<$F$1,"Group A",IF(ROW()-3<2*$F$1,"Group B","Group C"))) -> Group A | D17: Completed | E17: 575 | F17: Grade 6 | G17: =IF(F17="","",IF(B17-IF(F17="Grade K",0,VALUE(SUBSTITUTE(F17,"Grade ","")))<=0,"On/above grade",IF(B17-IF(F17="Grade K",0,VALUE(SUBSTITUTE(F17,"Grade ","")))=1,"1 grade below",IF(B17-IF(F17="Grade K",0,VALUE(SUBSTITUTE(F17,"Grade ","")))=2,"2 grades below","3+ grades below")))) -> 2 grades below | H17: Completed | I17: 631 | J17: Grade 7 | K17: =IF(J17="","",IF(B17-IF(J17="Grade K",0,VALUE(SUBSTITUTE(J17,"Grade ","")))<=0,"On/above grade",IF(B17-IF(J17="Grade K",0,VALUE(SUBSTITUTE(J17,"Grade ","")))=1,"1 grade below",IF(B17-IF(J17="Grade K",0,VALUE(SUBSTITUTE(J17,"Grade ","")))=2,"2 grades below","3+ grades below")))) -> 1 grade below | L17: Completed All | M17: Present | N17: Absent
A18: =IFERROR(INDEX(Roster!$A$3:$A$148,MATCH(16,Roster!$E$3:$E$148,0)),"") -> S-030 | B18: =IFERROR(INDEX(Roster!$B$3:$B$148,MATCH(16,Roster!$E$3:$E$148,0)),"") -> 8 | C18: =IF(A18="","",IF(ROW()-3<$F$1,"Group A",IF(ROW()-3<2*$F$1,"Group B","Group C"))) -> Group A | D18: Completed | E18: 612 | F18: Grade 7 | G18: =IF(F18="","",IF(B18-IF(F18="Grade K",0,VALUE(SUBSTITUTE(F18,"Grade ","")))<=0,"On/above grade",IF(B18-IF(F18="Grade K",0,VALUE(SUBSTITUTE(F18,"Grade ","")))=1,"1 grade below",IF(B18-IF(F18="Grade K",0,VALUE(SUBSTITUTE(F18,"Grade ","")))=2,"2 grades below","3+ grades below")))) -> 1 grade below | H18: Completed | I18: 585 | J18: Grade 6 | K18: =IF(J18="","",IF(B18-IF(J18="Grade K",0,VALUE(SUBSTITUTE(J18,"Grade ","")))<=0,"On/above grade",IF(B18-IF(J18="Grade K",0,VALUE(SUBSTITUTE(J18,"Grade ","")))=1,"1 grade below",IF(B18-IF(J18="Grade K",0,VALUE(SUBSTITUTE(J18,"Grade ","")))=2,"2 grades below","3+ grades below")))) -> 2 grades below | L18: Absent | M18: Present | N18: Present
